<<< PROJECT PART I -- process set (n=4) with 4 CPU-bound processes >>>
CPU-bound process A: arrival time 136ms; 17 CPU bursts
CPU-bound process B: arrival time 929ms; 12 CPU bursts
CPU-bound process C: arrival time 26ms; 60 CPU bursts
CPU-bound process D: arrival time 100ms; 37 CPU bursts

<<< PROJECT PART II -- t_cs=2ms; alpha=0.81; t_slice=128ms >>>
time 0ms: Simulator started for FCFS [Q <empty>]
time 26ms: Process C arrived; added to ready queue [Q C]
time 27ms: Process C started using the CPU for 2920ms burst [Q <empty>]
time 100ms: Process D arrived; added to ready queue [Q D]
time 136ms: Process A arrived; added to ready queue [Q D A]
time 929ms: Process B arrived; added to ready queue [Q D A B]
time 2947ms: Process C completed a CPU burst; 59 bursts to go [Q D A B]
time 2947ms: Process C switching out of CPU; blocking on I/O until time 3316ms [Q D A B]
time 2949ms: Process D started using the CPU for 6964ms burst [Q A B]
time 3316ms: Process C completed I/O; added to ready queue [Q A B C]
time 9913ms: Process D completed a CPU burst; 36 bursts to go [Q A B C]
time 9913ms: Process D switching out of CPU; blocking on I/O until time 10341ms [Q A B C]
time 9915ms: Process A started using the CPU for 5320ms burst [Q B C]
time 10341ms: Process D completed I/O; added to ready queue [Q B C D]
time 15235ms: Process A switching out of CPU; blocking on I/O until time 15953ms [Q B C D]
time 15237ms: Process B started using the CPU for 9752ms burst [Q C D]
time 15953ms: Process A completed I/O; added to ready queue [Q C D A]
time 24989ms: Process B switching out of CPU; blocking on I/O until time 25100ms [Q C D A]
time 24991ms: Process C started using the CPU for 2328ms burst [Q D A]
time 25100ms: Process B completed I/O; added to ready queue [Q D A B]
time 27319ms: Process C switching out of CPU; blocking on I/O until time 30432ms [Q D A B]
time 27321ms: Process D started using the CPU for 3260ms burst [Q A B]
time 30432ms: Process C completed I/O; added to ready queue [Q A B C]
time 30581ms: Process D switching out of CPU; blocking on I/O until time 32780ms [Q A B C]
time 30583ms: Process A started using the CPU for 2940ms burst [Q B C]
time 32780ms: Process D completed I/O; added to ready queue [Q B C D]
time 33523ms: Process A switching out of CPU; blocking on I/O until time 33606ms [Q B C D]
time 33525ms: Process B started using the CPU for 4692ms burst [Q C D]
time 33606ms: Process A completed I/O; added to ready queue [Q C D A]
time 38217ms: Process B switching out of CPU; blocking on I/O until time 38285ms [Q C D A]
time 38219ms: Process C started using the CPU for 1180ms burst [Q D A]
time 38285ms: Process B completed I/O; added to ready queue [Q D A B]
time 39399ms: Process C switching out of CPU; blocking on I/O until time 40720ms [Q D A B]
time 39401ms: Process D started using the CPU for 1428ms burst [Q A B]
time 40720ms: Process C completed I/O; added to ready queue [Q A B C]
time 40829ms: Process D switching out of CPU; blocking on I/O until time 41201ms [Q A B C]
time 40831ms: Process A started using the CPU for 96ms burst [Q B C]
time 40927ms: Process A switching out of CPU; blocking on I/O until time 40984ms [Q B C]
time 40929ms: Process B started using the CPU for 1968ms burst [Q C]
time 40984ms: Process A completed I/O; added to ready queue [Q C A]
time 41201ms: Process D completed I/O; added to ready queue [Q C A D]
time 42897ms: Process B switching out of CPU; blocking on I/O until time 44441ms [Q C A D]
time 42899ms: Process C started using the CPU for 11336ms burst [Q A D]
time 44441ms: Process B completed I/O; added to ready queue [Q A D B]
time 54235ms: Process C switching out of CPU; blocking on I/O until time 54912ms [Q A D B]
time 54237ms: Process A started using the CPU for 2732ms burst [Q D B]
time 54912ms: Process C completed I/O; added to ready queue [Q D B C]
time 56969ms: Process A switching out of CPU; blocking on I/O until time 57201ms [Q D B C]
time 56971ms: Process D started using the CPU for 5920ms burst [Q B C]
time 57201ms: Process A completed I/O; added to ready queue [Q B C A]
time 62891ms: Process D switching out of CPU; blocking on I/O until time 64934ms [Q B C A]
time 62893ms: Process B started using the CPU for 10680ms burst [Q C A]
time 64934ms: Process D completed I/O; added to ready queue [Q C A D]
time 73573ms: Process B switching out of CPU; blocking on I/O until time 74206ms [Q C A D]
time 73575ms: Process C started using the CPU for 5132ms burst [Q A D]
time 74206ms: Process B completed I/O; added to ready queue [Q A D B]
time 78707ms: Process C switching out of CPU; blocking on I/O until time 80555ms [Q A D B]
time 78709ms: Process A started using the CPU for 4400ms burst [Q D B]
time 80555ms: Process C completed I/O; added to ready queue [Q D B C]
time 83109ms: Process A switching out of CPU; blocking on I/O until time 84887ms [Q D B C]
time 83111ms: Process D started using the CPU for 2524ms burst [Q B C]
time 84887ms: Process A completed I/O; added to ready queue [Q B C A]
time 85635ms: Process D switching out of CPU; blocking on I/O until time 88523ms [Q B C A]
time 85637ms: Process B started using the CPU for 2440ms burst [Q C A]
time 88077ms: Process B switching out of CPU; blocking on I/O until time 91305ms [Q C A]
time 88079ms: Process C started using the CPU for 2896ms burst [Q A]
time 88523ms: Process D completed I/O; added to ready queue [Q A D]
time 90975ms: Process C switching out of CPU; blocking on I/O until time 94294ms [Q A D]
time 90977ms: Process A started using the CPU for 4000ms burst [Q D]
time 91305ms: Process B completed I/O; added to ready queue [Q D B]
time 94294ms: Process C completed I/O; added to ready queue [Q D B C]
time 94977ms: Process A switching out of CPU; blocking on I/O until time 95846ms [Q D B C]
time 94979ms: Process D started using the CPU for 3876ms burst [Q B C]
time 95846ms: Process A completed I/O; added to ready queue [Q B C A]
time 98855ms: Process D switching out of CPU; blocking on I/O until time 100126ms [Q B C A]
time 98857ms: Process B started using the CPU for 5808ms burst [Q C A]
time 100126ms: Process D completed I/O; added to ready queue [Q C A D]
time 104665ms: Process B switching out of CPU; blocking on I/O until time 105247ms [Q C A D]
time 104667ms: Process C started using the CPU for 160ms burst [Q A D]
time 104827ms: Process C switching out of CPU; blocking on I/O until time 106623ms [Q A D]
time 104829ms: Process A started using the CPU for 4664ms burst [Q D]
time 105247ms: Process B completed I/O; added to ready queue [Q D B]
time 106623ms: Process C completed I/O; added to ready queue [Q D B C]
time 109493ms: Process A switching out of CPU; blocking on I/O until time 110155ms [Q D B C]
time 109495ms: Process D started using the CPU for 2896ms burst [Q B C]
time 110155ms: Process A completed I/O; added to ready queue [Q B C A]
time 112391ms: Process D switching out of CPU; blocking on I/O until time 113849ms [Q B C A]
time 112393ms: Process B started using the CPU for 3512ms burst [Q C A]
time 113849ms: Process D completed I/O; added to ready queue [Q C A D]
time 115905ms: Process B switching out of CPU; blocking on I/O until time 117403ms [Q C A D]
time 115907ms: Process C started using the CPU for 2968ms burst [Q A D]
time 117403ms: Process B completed I/O; added to ready queue [Q A D B]
time 118875ms: Process C switching out of CPU; blocking on I/O until time 119919ms [Q A D B]
time 118877ms: Process A started using the CPU for 6244ms burst [Q D B]
time 119919ms: Process C completed I/O; added to ready queue [Q D B C]
time 125121ms: Process A switching out of CPU; blocking on I/O until time 125474ms [Q D B C]
time 125123ms: Process D started using the CPU for 6768ms burst [Q B C]
time 125474ms: Process A completed I/O; added to ready queue [Q B C A]
time 131891ms: Process D switching out of CPU; blocking on I/O until time 132603ms [Q B C A]
time 131893ms: Process B started using the CPU for 7996ms burst [Q C A]
time 132603ms: Process D completed I/O; added to ready queue [Q C A D]
time 139889ms: Process B switching out of CPU; blocking on I/O until time 140892ms [Q C A D]
time 139891ms: Process C started using the CPU for 4428ms burst [Q A D]
time 140892ms: Process B completed I/O; added to ready queue [Q A D B]
time 144319ms: Process C switching out of CPU; blocking on I/O until time 145597ms [Q A D B]
time 144321ms: Process A started using the CPU for 596ms burst [Q D B]
time 144917ms: Process A switching out of CPU; blocking on I/O until time 145008ms [Q D B]
time 144919ms: Process D started using the CPU for 6644ms burst [Q B]
time 145008ms: Process A completed I/O; added to ready queue [Q B A]
time 145597ms: Process C completed I/O; added to ready queue [Q B A C]
time 151563ms: Process D switching out of CPU; blocking on I/O until time 153617ms [Q B A C]
time 151565ms: Process B started using the CPU for 7880ms burst [Q A C]
time 153617ms: Process D completed I/O; added to ready queue [Q A C D]
time 159445ms: Process B switching out of CPU; blocking on I/O until time 161078ms [Q A C D]
time 159447ms: Process A started using the CPU for 1552ms burst [Q C D]
time 160999ms: Process A switching out of CPU; blocking on I/O until time 161921ms [Q C D]
time 161001ms: Process C started using the CPU for 7280ms burst [Q D]
time 161078ms: Process B completed I/O; added to ready queue [Q D B]
time 161921ms: Process A completed I/O; added to ready queue [Q D B A]
time 168281ms: Process C switching out of CPU; blocking on I/O until time 168899ms [Q D B A]
time 168283ms: Process D started using the CPU for 3160ms burst [Q B A]
time 168899ms: Process C completed I/O; added to ready queue [Q B A C]
time 171443ms: Process D switching out of CPU; blocking on I/O until time 174769ms [Q B A C]
time 171445ms: Process B started using the CPU for 1212ms burst [Q A C]
time 172657ms: Process B switching out of CPU; blocking on I/O until time 176344ms [Q A C]
time 172659ms: Process A started using the CPU for 136ms burst [Q C]
time 172795ms: Process A switching out of CPU; blocking on I/O until time 173988ms [Q C]
time 172797ms: Process C started using the CPU for 7180ms burst [Q <empty>]
time 173988ms: Process A completed I/O; added to ready queue [Q A]
time 174769ms: Process D completed I/O; added to ready queue [Q A D]
time 176344ms: Process B completed I/O; added to ready queue [Q A D B]
time 179977ms: Process C switching out of CPU; blocking on I/O until time 181524ms [Q A D B]
time 179979ms: Process A started using the CPU for 3816ms burst [Q D B]
time 181524ms: Process C completed I/O; added to ready queue [Q D B C]
time 183795ms: Process A switching out of CPU; blocking on I/O until time 185041ms [Q D B C]
time 183797ms: Process D started using the CPU for 4472ms burst [Q B C]
time 185041ms: Process A completed I/O; added to ready queue [Q B C A]
time 188269ms: Process D switching out of CPU; blocking on I/O until time 188718ms [Q B C A]
time 188271ms: Process B started using the CPU for 8980ms burst [Q C A]
time 188718ms: Process D completed I/O; added to ready queue [Q C A D]
time 197251ms: Process B switching out of CPU; blocking on I/O until time 200690ms [Q C A D]
time 197253ms: Process C started using the CPU for 8120ms burst [Q A D]
time 200690ms: Process B completed I/O; added to ready queue [Q A D B]
time 205373ms: Process C switching out of CPU; blocking on I/O until time 206932ms [Q A D B]
time 205375ms: Process A started using the CPU for 944ms burst [Q D B]
time 206319ms: Process A switching out of CPU; blocking on I/O until time 208446ms [Q D B]
time 206321ms: Process D started using the CPU for 6872ms burst [Q B]
time 206932ms: Process C completed I/O; added to ready queue [Q B C]
time 208446ms: Process A completed I/O; added to ready queue [Q B C A]
time 213193ms: Process D switching out of CPU; blocking on I/O until time 213740ms [Q B C A]
time 213195ms: Process B started using the CPU for 2460ms burst [Q C A]
time 213740ms: Process D completed I/O; added to ready queue [Q C A D]
time 215655ms: Process B terminated [Q C A D]
time 215657ms: Process C started using the CPU for 692ms burst [Q A D]
time 216349ms: Process C switching out of CPU; blocking on I/O until time 216945ms [Q A D]
time 216351ms: Process A started using the CPU for 2936ms burst [Q D]
time 216945ms: Process C completed I/O; added to ready queue [Q D C]
time 219287ms: Process A switching out of CPU; blocking on I/O until time 220019ms [Q D C]
time 219289ms: Process D started using the CPU for 6236ms burst [Q C]
time 220019ms: Process A completed I/O; added to ready queue [Q C A]
time 225525ms: Process D switching out of CPU; blocking on I/O until time 225606ms [Q C A]
time 225527ms: Process C started using the CPU for 3172ms burst [Q A]
time 225606ms: Process D completed I/O; added to ready queue [Q A D]
time 228699ms: Process C switching out of CPU; blocking on I/O until time 229146ms [Q A D]
time 228701ms: Process A started using the CPU for 4496ms burst [Q D]
time 229146ms: Process C completed I/O; added to ready queue [Q D C]
time 233197ms: Process A switching out of CPU; blocking on I/O until time 235653ms [Q D C]
time 233199ms: Process D started using the CPU for 2472ms burst [Q C]
time 235653ms: Process A completed I/O; added to ready queue [Q C A]
time 235671ms: Process D switching out of CPU; blocking on I/O until time 235805ms [Q C A]
time 235673ms: Process C started using the CPU for 7724ms burst [Q A]
time 235805ms: Process D completed I/O; added to ready queue [Q A D]
time 243397ms: Process C switching out of CPU; blocking on I/O until time 244213ms [Q A D]
time 243399ms: Process A started using the CPU for 248ms burst [Q D]
time 243647ms: Process A switching out of CPU; blocking on I/O until time 243941ms [Q D]
time 243649ms: Process D started using the CPU for 1952ms burst [Q <empty>]
time 243941ms: Process A completed I/O; added to ready queue [Q A]
time 244213ms: Process C completed I/O; added to ready queue [Q A C]
time 245601ms: Process D switching out of CPU; blocking on I/O until time 246454ms [Q A C]
time 245603ms: Process A started using the CPU for 2588ms burst [Q C]
time 246454ms: Process D completed I/O; added to ready queue [Q C D]
time 248191ms: Process A terminated [Q C D]
time 248193ms: Process C started using the CPU for 3628ms burst [Q D]
time 251821ms: Process C switching out of CPU; blocking on I/O until time 251880ms [Q D]
time 251823ms: Process D started using the CPU for 5708ms burst [Q <empty>]
time 251880ms: Process C completed I/O; added to ready queue [Q C]
time 257531ms: Process D switching out of CPU; blocking on I/O until time 259684ms [Q C]
time 257533ms: Process C started using the CPU for 2696ms burst [Q <empty>]
time 259684ms: Process D completed I/O; added to ready queue [Q D]
time 260229ms: Process C switching out of CPU; blocking on I/O until time 260261ms [Q D]
time 260231ms: Process D started using the CPU for 2108ms burst [Q <empty>]
time 260261ms: Process C completed I/O; added to ready queue [Q C]
time 262339ms: Process D switching out of CPU; blocking on I/O until time 262462ms [Q C]
time 262341ms: Process C started using the CPU for 9204ms burst [Q <empty>]
time 262462ms: Process D completed I/O; added to ready queue [Q D]
time 271545ms: Process C switching out of CPU; blocking on I/O until time 274933ms [Q D]
time 271547ms: Process D started using the CPU for 7608ms burst [Q <empty>]
time 274933ms: Process C completed I/O; added to ready queue [Q C]
time 279155ms: Process D switching out of CPU; blocking on I/O until time 280303ms [Q C]
time 279157ms: Process C started using the CPU for 7356ms burst [Q <empty>]
time 280303ms: Process D completed I/O; added to ready queue [Q D]
time 286513ms: Process C switching out of CPU; blocking on I/O until time 287324ms [Q D]
time 286515ms: Process D started using the CPU for 928ms burst [Q <empty>]
time 287324ms: Process C completed I/O; added to ready queue [Q C]
time 287443ms: Process D switching out of CPU; blocking on I/O until time 287469ms [Q C]
time 287445ms: Process C started using the CPU for 676ms burst [Q <empty>]
time 287469ms: Process D completed I/O; added to ready queue [Q D]
time 288121ms: Process C switching out of CPU; blocking on I/O until time 288467ms [Q D]
time 288123ms: Process D started using the CPU for 2848ms burst [Q <empty>]
time 288467ms: Process C completed I/O; added to ready queue [Q C]
time 290971ms: Process D switching out of CPU; blocking on I/O until time 291357ms [Q C]
time 290973ms: Process C started using the CPU for 4132ms burst [Q <empty>]
time 291357ms: Process D completed I/O; added to ready queue [Q D]
time 295105ms: Process C switching out of CPU; blocking on I/O until time 295558ms [Q D]
time 295107ms: Process D started using the CPU for 11844ms burst [Q <empty>]
time 295558ms: Process C completed I/O; added to ready queue [Q C]
time 306951ms: Process D switching out of CPU; blocking on I/O until time 307414ms [Q C]
time 306953ms: Process C started using the CPU for 3364ms burst [Q <empty>]
time 307414ms: Process D completed I/O; added to ready queue [Q D]
time 310317ms: Process C switching out of CPU; blocking on I/O until time 311991ms [Q D]
time 310319ms: Process D started using the CPU for 1572ms burst [Q <empty>]
time 311891ms: Process D switching out of CPU; blocking on I/O until time 312298ms [Q <empty>]
time 311991ms: Process C completed I/O; added to ready queue [Q C]
time 311992ms: Process C started using the CPU for 6900ms burst [Q <empty>]
time 312298ms: Process D completed I/O; added to ready queue [Q D]
time 318892ms: Process C switching out of CPU; blocking on I/O until time 321163ms [Q D]
time 318894ms: Process D started using the CPU for 3800ms burst [Q <empty>]
time 321163ms: Process C completed I/O; added to ready queue [Q C]
time 322694ms: Process D switching out of CPU; blocking on I/O until time 322973ms [Q C]
time 322696ms: Process C started using the CPU for 6916ms burst [Q <empty>]
time 322973ms: Process D completed I/O; added to ready queue [Q D]
time 329612ms: Process C switching out of CPU; blocking on I/O until time 330276ms [Q D]
time 329614ms: Process D started using the CPU for 5116ms burst [Q <empty>]
time 330276ms: Process C completed I/O; added to ready queue [Q C]
time 334730ms: Process D switching out of CPU; blocking on I/O until time 335178ms [Q C]
time 334732ms: Process C started using the CPU for 7244ms burst [Q <empty>]
time 335178ms: Process D completed I/O; added to ready queue [Q D]
time 341976ms: Process C switching out of CPU; blocking on I/O until time 342132ms [Q D]
time 341978ms: Process D started using the CPU for 4152ms burst [Q <empty>]
time 342132ms: Process C completed I/O; added to ready queue [Q C]
time 346130ms: Process D switching out of CPU; blocking on I/O until time 346672ms [Q C]
time 346132ms: Process C started using the CPU for 2396ms burst [Q <empty>]
time 346672ms: Process D completed I/O; added to ready queue [Q D]
time 348528ms: Process C switching out of CPU; blocking on I/O until time 349036ms [Q D]
time 348530ms: Process D started using the CPU for 3440ms burst [Q <empty>]
time 349036ms: Process C completed I/O; added to ready queue [Q C]
time 351970ms: Process D switching out of CPU; blocking on I/O until time 352536ms [Q C]
time 351972ms: Process C started using the CPU for 7736ms burst [Q <empty>]
time 352536ms: Process D completed I/O; added to ready queue [Q D]
time 359708ms: Process C switching out of CPU; blocking on I/O until time 361512ms [Q D]
time 359710ms: Process D started using the CPU for 56ms burst [Q <empty>]
time 359766ms: Process D switching out of CPU; blocking on I/O until time 360773ms [Q <empty>]
time 360773ms: Process D completed I/O; added to ready queue [Q D]
time 360774ms: Process D started using the CPU for 1732ms burst [Q <empty>]
time 361512ms: Process C completed I/O; added to ready queue [Q C]
time 362506ms: Process D switching out of CPU; blocking on I/O until time 364103ms [Q C]
time 362508ms: Process C started using the CPU for 4484ms burst [Q <empty>]
time 364103ms: Process D completed I/O; added to ready queue [Q D]
time 366992ms: Process C switching out of CPU; blocking on I/O until time 369221ms [Q D]
time 366994ms: Process D started using the CPU for 9912ms burst [Q <empty>]
time 369221ms: Process C completed I/O; added to ready queue [Q C]
time 376906ms: Process D switching out of CPU; blocking on I/O until time 378084ms [Q C]
time 376908ms: Process C started using the CPU for 7564ms burst [Q <empty>]
time 378084ms: Process D completed I/O; added to ready queue [Q D]
time 384472ms: Process C switching out of CPU; blocking on I/O until time 385695ms [Q D]
time 384474ms: Process D started using the CPU for 580ms burst [Q <empty>]
time 385054ms: Process D switching out of CPU; blocking on I/O until time 386986ms [Q <empty>]
time 385695ms: Process C completed I/O; added to ready queue [Q C]
time 385696ms: Process C started using the CPU for 3724ms burst [Q <empty>]
time 386986ms: Process D completed I/O; added to ready queue [Q D]
time 389420ms: Process C switching out of CPU; blocking on I/O until time 389542ms [Q D]
time 389422ms: Process D started using the CPU for 640ms burst [Q <empty>]
time 389542ms: Process C completed I/O; added to ready queue [Q C]
time 390062ms: Process D switching out of CPU; blocking on I/O until time 390098ms [Q C]
time 390064ms: Process C started using the CPU for 1608ms burst [Q <empty>]
time 390098ms: Process D completed I/O; added to ready queue [Q D]
time 391672ms: Process C switching out of CPU; blocking on I/O until time 392108ms [Q D]
time 391674ms: Process D started using the CPU for 316ms burst [Q <empty>]
time 391990ms: Process D switching out of CPU; blocking on I/O until time 393119ms [Q <empty>]
time 392108ms: Process C completed I/O; added to ready queue [Q C]
time 392109ms: Process C started using the CPU for 6880ms burst [Q <empty>]
time 393119ms: Process D completed I/O; added to ready queue [Q D]
time 398989ms: Process C switching out of CPU; blocking on I/O until time 400467ms [Q D]
time 398991ms: Process D started using the CPU for 3388ms burst [Q <empty>]
time 400467ms: Process C completed I/O; added to ready queue [Q C]
time 402379ms: Process D switching out of CPU; blocking on I/O until time 403160ms [Q C]
time 402381ms: Process C started using the CPU for 972ms burst [Q <empty>]
time 403160ms: Process D completed I/O; added to ready queue [Q D]
time 403353ms: Process C switching out of CPU; blocking on I/O until time 403671ms [Q D]
time 403355ms: Process D started using the CPU for 1976ms burst [Q <empty>]
time 403671ms: Process C completed I/O; added to ready queue [Q C]
time 405331ms: Process D switching out of CPU; blocking on I/O until time 406588ms [Q C]
time 405333ms: Process C started using the CPU for 176ms burst [Q <empty>]
time 405509ms: Process C switching out of CPU; blocking on I/O until time 407636ms [Q <empty>]
time 406588ms: Process D completed I/O; added to ready queue [Q D]
time 406589ms: Process D started using the CPU for 1688ms burst [Q <empty>]
time 407636ms: Process C completed I/O; added to ready queue [Q C]
time 408277ms: Process D switching out of CPU; blocking on I/O until time 409800ms [Q C]
time 408279ms: Process C started using the CPU for 412ms burst [Q <empty>]
time 408691ms: Process C switching out of CPU; blocking on I/O until time 409257ms [Q <empty>]
time 409257ms: Process C completed I/O; added to ready queue [Q C]
time 409258ms: Process C started using the CPU for 576ms burst [Q <empty>]
time 409800ms: Process D completed I/O; added to ready queue [Q D]
time 409834ms: Process C switching out of CPU; blocking on I/O until time 409906ms [Q D]
time 409836ms: Process D started using the CPU for 6672ms burst [Q <empty>]
time 409906ms: Process C completed I/O; added to ready queue [Q C]
time 416508ms: Process D switching out of CPU; blocking on I/O until time 417372ms [Q C]
time 416510ms: Process C started using the CPU for 4928ms burst [Q <empty>]
time 417372ms: Process D completed I/O; added to ready queue [Q D]
time 421438ms: Process C switching out of CPU; blocking on I/O until time 422141ms [Q D]
time 421440ms: Process D started using the CPU for 6364ms burst [Q <empty>]
time 422141ms: Process C completed I/O; added to ready queue [Q C]
time 427804ms: Process D terminated [Q C]
time 427806ms: Process C started using the CPU for 2804ms burst [Q <empty>]
time 430610ms: Process C switching out of CPU; blocking on I/O until time 431629ms [Q <empty>]
time 431629ms: Process C completed I/O; added to ready queue [Q C]
time 431630ms: Process C started using the CPU for 2120ms burst [Q <empty>]
time 433750ms: Process C switching out of CPU; blocking on I/O until time 435613ms [Q <empty>]
time 435613ms: Process C completed I/O; added to ready queue [Q C]
time 435614ms: Process C started using the CPU for 1944ms burst [Q <empty>]
time 437558ms: Process C switching out of CPU; blocking on I/O until time 437562ms [Q <empty>]
time 437562ms: Process C completed I/O; added to ready queue [Q C]
time 437563ms: Process C started using the CPU for 2472ms burst [Q <empty>]
time 440035ms: Process C switching out of CPU; blocking on I/O until time 440224ms [Q <empty>]
time 440224ms: Process C completed I/O; added to ready queue [Q C]
time 440225ms: Process C started using the CPU for 868ms burst [Q <empty>]
time 441093ms: Process C switching out of CPU; blocking on I/O until time 442117ms [Q <empty>]
time 442117ms: Process C completed I/O; added to ready queue [Q C]
time 442118ms: Process C started using the CPU for 3208ms burst [Q <empty>]
time 445326ms: Process C switching out of CPU; blocking on I/O until time 446430ms [Q <empty>]
time 446430ms: Process C completed I/O; added to ready queue [Q C]
time 446431ms: Process C started using the CPU for 1672ms burst [Q <empty>]
time 448103ms: Process C switching out of CPU; blocking on I/O until time 450681ms [Q <empty>]
time 450681ms: Process C completed I/O; added to ready queue [Q C]
time 450682ms: Process C started using the CPU for 3536ms burst [Q <empty>]
time 454218ms: Process C switching out of CPU; blocking on I/O until time 457756ms [Q <empty>]
time 457756ms: Process C completed I/O; added to ready queue [Q C]
time 457757ms: Process C started using the CPU for 2988ms burst [Q <empty>]
time 460745ms: Process C switching out of CPU; blocking on I/O until time 462822ms [Q <empty>]
time 462822ms: Process C completed I/O; added to ready queue [Q C]
time 462823ms: Process C started using the CPU for 7804ms burst [Q <empty>]
time 470627ms: Process C switching out of CPU; blocking on I/O until time 471895ms [Q <empty>]
time 471895ms: Process C completed I/O; added to ready queue [Q C]
time 471896ms: Process C started using the CPU for 5608ms burst [Q <empty>]
time 477504ms: Process C switching out of CPU; blocking on I/O until time 477802ms [Q <empty>]
time 477802ms: Process C completed I/O; added to ready queue [Q C]
time 477803ms: Process C started using the CPU for 1160ms burst [Q <empty>]
time 478963ms: Process C switching out of CPU; blocking on I/O until time 479605ms [Q <empty>]
time 479605ms: Process C completed I/O; added to ready queue [Q C]
time 479606ms: Process C started using the CPU for 3048ms burst [Q <empty>]
time 482654ms: Process C switching out of CPU; blocking on I/O until time 482666ms [Q <empty>]
time 482666ms: Process C completed I/O; added to ready queue [Q C]
time 482667ms: Process C started using the CPU for 1120ms burst [Q <empty>]
time 483787ms: Process C switching out of CPU; blocking on I/O until time 484535ms [Q <empty>]
time 484535ms: Process C completed I/O; added to ready queue [Q C]
time 484536ms: Process C started using the CPU for 8872ms burst [Q <empty>]
time 493408ms: Process C switching out of CPU; blocking on I/O until time 495852ms [Q <empty>]
time 495852ms: Process C completed I/O; added to ready queue [Q C]
time 495853ms: Process C started using the CPU for 3112ms burst [Q <empty>]
time 498965ms: Process C switching out of CPU; blocking on I/O until time 499634ms [Q <empty>]
time 499634ms: Process C completed I/O; added to ready queue [Q C]
time 499635ms: Process C started using the CPU for 1904ms burst [Q <empty>]
time 501539ms: Process C switching out of CPU; blocking on I/O until time 502257ms [Q <empty>]
time 502257ms: Process C completed I/O; added to ready queue [Q C]
time 502258ms: Process C started using the CPU for 5488ms burst [Q <empty>]
time 507746ms: Process C switching out of CPU; blocking on I/O until time 510422ms [Q <empty>]
time 510422ms: Process C completed I/O; added to ready queue [Q C]
time 510423ms: Process C started using the CPU for 3340ms burst [Q <empty>]
time 513763ms: Process C switching out of CPU; blocking on I/O until time 514206ms [Q <empty>]
time 514206ms: Process C completed I/O; added to ready queue [Q C]
time 514207ms: Process C started using the CPU for 7076ms burst [Q <empty>]
time 521283ms: Process C switching out of CPU; blocking on I/O until time 522071ms [Q <empty>]
time 522071ms: Process C completed I/O; added to ready queue [Q C]
time 522072ms: Process C started using the CPU for 9540ms burst [Q <empty>]
time 531612ms: Process C switching out of CPU; blocking on I/O until time 531654ms [Q <empty>]
time 531654ms: Process C completed I/O; added to ready queue [Q C]
time 531655ms: Process C started using the CPU for 1784ms burst [Q <empty>]
time 533439ms: Process C switching out of CPU; blocking on I/O until time 534066ms [Q <empty>]
time 534066ms: Process C completed I/O; added to ready queue [Q C]
time 534067ms: Process C started using the CPU for 1704ms burst [Q <empty>]
time 535771ms: Process C terminated [Q <empty>]
time 535772ms: Simulator ended for FCFS [Q <empty>]

time 0ms: Simulator started for SJF [Q <empty>]
time 26ms: Process C (tau 1000ms) arrived; added to ready queue [Q C]
time 27ms: Process C (tau 1000ms) started using the CPU for 2920ms burst [Q <empty>]
time 100ms: Process D (tau 1000ms) arrived; added to ready queue [Q D]
time 136ms: Process A (tau 1000ms) arrived; added to ready queue [Q A D]
time 929ms: Process B (tau 1000ms) arrived; added to ready queue [Q A B D]
time 2947ms: Process C (tau 1000ms) completed a CPU burst; 59 bursts to go [Q A B D]
time 2947ms: Recalculating tau for process C: old tau 1000ms ==> new tau 2556ms [Q A B D]
time 2947ms: Process C switching out of CPU; blocking on I/O until time 3316ms [Q A B D]
time 2949ms: Process A (tau 1000ms) started using the CPU for 5320ms burst [Q B D]
time 3316ms: Process C (tau 2556ms) completed I/O; added to ready queue [Q B D C]
time 8269ms: Process A (tau 1000ms) completed a CPU burst; 16 bursts to go [Q B D C]
time 8269ms: Recalculating tau for process A: old tau 1000ms ==> new tau 4500ms [Q B D C]
time 8269ms: Process A switching out of CPU; blocking on I/O until time 8987ms [Q B D C]
time 8271ms: Process B (tau 1000ms) started using the CPU for 9752ms burst [Q D C]
time 8987ms: Process A (tau 4500ms) completed I/O; added to ready queue [Q D C A]
time 18023ms: Process B (tau 1000ms) completed a CPU burst; 11 bursts to go [Q D C A]
time 18023ms: Recalculating tau for process B: old tau 1000ms ==> new tau 8090ms [Q D C A]
time 18023ms: Process B switching out of CPU; blocking on I/O until time 18134ms [Q D C A]
time 18025ms: Process D (tau 1000ms) started using the CPU for 6964ms burst [Q C A]
time 18134ms: Process B (tau 8090ms) completed I/O; added to ready queue [Q C A B]
time 24989ms: Process D (tau 1000ms) completed a CPU burst; 36 bursts to go [Q C A B]
time 24989ms: Recalculating tau for process D: old tau 1000ms ==> new tau 5831ms [Q C A B]
time 24989ms: Process D switching out of CPU; blocking on I/O until time 25417ms [Q C A B]
time 24991ms: Process C (tau 2556ms) started using the CPU for 2328ms burst [Q A B]
time 25417ms: Process D (tau 5831ms) completed I/O; added to ready queue [Q A D B]
time 27319ms: Process C (tau 2556ms) completed a CPU burst; 58 bursts to go [Q A D B]
time 27319ms: Recalculating tau for process C: old tau 2556ms ==> new tau 2372ms [Q A D B]
time 27319ms: Process C switching out of CPU; blocking on I/O until time 30432ms [Q A D B]
time 27321ms: Process A (tau 4500ms) started using the CPU for 2940ms burst [Q D B]
time 30261ms: Process A (tau 4500ms) completed a CPU burst; 15 bursts to go [Q D B]
time 30261ms: Recalculating tau for process A: old tau 4500ms ==> new tau 3237ms [Q D B]
time 30261ms: Process A switching out of CPU; blocking on I/O until time 30344ms [Q D B]
time 30263ms: Process D (tau 5831ms) started using the CPU for 3260ms burst [Q B]
time 30344ms: Process A (tau 3237ms) completed I/O; added to ready queue [Q A B]
time 30432ms: Process C (tau 2372ms) completed I/O; added to ready queue [Q C A B]
time 33523ms: Process D (tau 5831ms) completed a CPU burst; 35 bursts to go [Q C A B]
time 33523ms: Recalculating tau for process D: old tau 5831ms ==> new tau 3749ms [Q C A B]
time 33523ms: Process D switching out of CPU; blocking on I/O until time 35722ms [Q C A B]
time 33525ms: Process C (tau 2372ms) started using the CPU for 1180ms burst [Q A B]
time 34705ms: Process C (tau 2372ms) completed a CPU burst; 57 bursts to go [Q A B]
time 34705ms: Recalculating tau for process C: old tau 2372ms ==> new tau 1407ms [Q A B]
time 34705ms: Process C switching out of CPU; blocking on I/O until time 36026ms [Q A B]
time 34707ms: Process A (tau 3237ms) started using the CPU for 96ms burst [Q B]
time 34803ms: Process A (tau 3237ms) completed a CPU burst; 14 bursts to go [Q B]
time 34803ms: Recalculating tau for process A: old tau 3237ms ==> new tau 693ms [Q B]
time 34803ms: Process A switching out of CPU; blocking on I/O until time 34860ms [Q B]
time 34805ms: Process B (tau 8090ms) started using the CPU for 4692ms burst [Q <empty>]
time 34860ms: Process A (tau 693ms) completed I/O; added to ready queue [Q A]
time 35722ms: Process D (tau 3749ms) completed I/O; added to ready queue [Q A D]
time 36026ms: Process C (tau 1407ms) completed I/O; added to ready queue [Q A C D]
time 39497ms: Process B (tau 8090ms) completed a CPU burst; 10 bursts to go [Q A C D]
time 39497ms: Recalculating tau for process B: old tau 8090ms ==> new tau 5338ms [Q A C D]
time 39497ms: Process B switching out of CPU; blocking on I/O until time 39565ms [Q A C D]
time 39499ms: Process A (tau 693ms) started using the CPU for 2732ms burst [Q C D]
time 39565ms: Process B (tau 5338ms) completed I/O; added to ready queue [Q C D B]
time 42231ms: Process A (tau 693ms) completed a CPU burst; 13 bursts to go [Q C D B]
time 42231ms: Recalculating tau for process A: old tau 693ms ==> new tau 2345ms [Q C D B]
time 42231ms: Process A switching out of CPU; blocking on I/O until time 42463ms [Q C D B]
time 42233ms: Process C (tau 1407ms) started using the CPU for 11336ms burst [Q D B]
time 42463ms: Process A (tau 2345ms) completed I/O; added to ready queue [Q A D B]
time 53569ms: Process C (tau 1407ms) completed a CPU burst; 56 bursts to go [Q A D B]
time 53569ms: Recalculating tau for process C: old tau 1407ms ==> new tau 9450ms [Q A D B]
time 53569ms: Process C switching out of CPU; blocking on I/O until time 54246ms [Q A D B]
time 53571ms: Process A (tau 2345ms) started using the CPU for 4400ms burst [Q D B]
time 54246ms: Process C (tau 9450ms) completed I/O; added to ready queue [Q D B C]
time 57971ms: Process A (tau 2345ms) completed a CPU burst; 12 bursts to go [Q D B C]
time 57971ms: Recalculating tau for process A: old tau 2345ms ==> new tau 4010ms [Q D B C]
time 57971ms: Process A switching out of CPU; blocking on I/O until time 59749ms [Q D B C]
time 57973ms: Process D (tau 3749ms) started using the CPU for 1428ms burst [Q B C]
time 59401ms: Process D (tau 3749ms) completed a CPU burst; 34 bursts to go [Q B C]
time 59401ms: Recalculating tau for process D: old tau 3749ms ==> new tau 1869ms [Q B C]
time 59401ms: Process D switching out of CPU; blocking on I/O until time 59773ms [Q B C]
time 59403ms: Process B (tau 5338ms) started using the CPU for 1968ms burst [Q C]
time 59749ms: Process A (tau 4010ms) completed I/O; added to ready queue [Q A C]
time 59773ms: Process D (tau 1869ms) completed I/O; added to ready queue [Q D A C]
time 61371ms: Process B (tau 5338ms) completed a CPU burst; 9 bursts to go [Q D A C]
time 61371ms: Recalculating tau for process B: old tau 5338ms ==> new tau 2609ms [Q D A C]
time 61371ms: Process B switching out of CPU; blocking on I/O until time 62915ms [Q D A C]
time 61373ms: Process D (tau 1869ms) started using the CPU for 5920ms burst [Q A C]
time 62915ms: Process B (tau 2609ms) completed I/O; added to ready queue [Q B A C]
time 67293ms: Process D (tau 1869ms) completed a CPU burst; 33 bursts to go [Q B A C]
time 67293ms: Recalculating tau for process D: old tau 1869ms ==> new tau 5151ms [Q B A C]
time 67293ms: Process D switching out of CPU; blocking on I/O until time 69336ms [Q B A C]
time 67295ms: Process B (tau 2609ms) started using the CPU for 10680ms burst [Q A C]
time 69336ms: Process D (tau 5151ms) completed I/O; added to ready queue [Q A D C]
time 77975ms: Process B (tau 2609ms) completed a CPU burst; 8 bursts to go [Q A D C]
time 77975ms: Recalculating tau for process B: old tau 2609ms ==> new tau 9147ms [Q A D C]
time 77975ms: Process B switching out of CPU; blocking on I/O until time 78608ms [Q A D C]
time 77977ms: Process A (tau 4010ms) started using the CPU for 4000ms burst [Q D C]
time 78608ms: Process B (tau 9147ms) completed I/O; added to ready queue [Q D B C]
time 81977ms: Process A (tau 4010ms) completed a CPU burst; 11 bursts to go [Q D B C]
time 81977ms: Recalculating tau for process A: old tau 4010ms ==> new tau 4002ms [Q D B C]
time 81977ms: Process A switching out of CPU; blocking on I/O until time 82846ms [Q D B C]
time 81979ms: Process D (tau 5151ms) started using the CPU for 2524ms burst [Q B C]
time 82846ms: Process A (tau 4002ms) completed I/O; added to ready queue [Q A B C]
time 84503ms: Process D (tau 5151ms) completed a CPU burst; 32 bursts to go [Q A B C]
time 84503ms: Recalculating tau for process D: old tau 5151ms ==> new tau 3024ms [Q A B C]
time 84503ms: Process D switching out of CPU; blocking on I/O until time 87391ms [Q A B C]
time 84505ms: Process A (tau 4002ms) started using the CPU for 4664ms burst [Q B C]
time 87391ms: Process D (tau 3024ms) completed I/O; added to ready queue [Q D B C]
time 89169ms: Process A (tau 4002ms) completed a CPU burst; 10 bursts to go [Q D B C]
time 89169ms: Recalculating tau for process A: old tau 4002ms ==> new tau 4539ms [Q D B C]
time 89169ms: Process A switching out of CPU; blocking on I/O until time 89831ms [Q D B C]
time 89171ms: Process D (tau 3024ms) started using the CPU for 3876ms burst [Q B C]
time 89831ms: Process A (tau 4539ms) completed I/O; added to ready queue [Q A B C]
time 93047ms: Process D (tau 3024ms) completed a CPU burst; 31 bursts to go [Q A B C]
time 93047ms: Recalculating tau for process D: old tau 3024ms ==> new tau 3715ms [Q A B C]
time 93047ms: Process D switching out of CPU; blocking on I/O until time 94318ms [Q A B C]
time 93049ms: Process A (tau 4539ms) started using the CPU for 6244ms burst [Q B C]
time 94318ms: Process D (tau 3715ms) completed I/O; added to ready queue [Q D B C]
time 99293ms: Process A (tau 4539ms) completed a CPU burst; 9 bursts to go [Q D B C]
time 99293ms: Recalculating tau for process A: old tau 4539ms ==> new tau 5921ms [Q D B C]
time 99293ms: Process A switching out of CPU; blocking on I/O until time 99646ms [Q D B C]
time 99295ms: Process D (tau 3715ms) started using the CPU for 2896ms burst [Q B C]
time 99646ms: Process A (tau 5921ms) completed I/O; added to ready queue [Q A B C]
time 102191ms: Process D (tau 3715ms) completed a CPU burst; 30 bursts to go [Q A B C]
time 102191ms: Recalculating tau for process D: old tau 3715ms ==> new tau 3052ms [Q A B C]
time 102191ms: Process D switching out of CPU; blocking on I/O until time 103649ms [Q A B C]
time 102193ms: Process A (tau 5921ms) started using the CPU for 596ms burst [Q B C]
time 102789ms: Process A (tau 5921ms) completed a CPU burst; 8 bursts to go [Q B C]
time 102789ms: Recalculating tau for process A: old tau 5921ms ==> new tau 1608ms [Q B C]
time 102789ms: Process A switching out of CPU; blocking on I/O until time 102880ms [Q B C]
time 102791ms: Process B (tau 9147ms) started using the CPU for 2440ms burst [Q C]
time 102880ms: Process A (tau 1608ms) completed I/O; added to ready queue [Q A C]
time 103649ms: Process D (tau 3052ms) completed I/O; added to ready queue [Q A D C]
time 105231ms: Process B (tau 9147ms) completed a CPU burst; 7 bursts to go [Q A D C]
time 105231ms: Recalculating tau for process B: old tau 9147ms ==> new tau 3715ms [Q A D C]
time 105231ms: Process B switching out of CPU; blocking on I/O until time 108459ms [Q A D C]
time 105233ms: Process A (tau 1608ms) started using the CPU for 1552ms burst [Q D C]
time 106785ms: Process A (tau 1608ms) completed a CPU burst; 7 bursts to go [Q D C]
time 106785ms: Recalculating tau for process A: old tau 1608ms ==> new tau 1563ms [Q D C]
time 106785ms: Process A switching out of CPU; blocking on I/O until time 107707ms [Q D C]
time 106787ms: Process D (tau 3052ms) started using the CPU for 6768ms burst [Q C]
time 107707ms: Process A (tau 1563ms) completed I/O; added to ready queue [Q A C]
time 108459ms: Process B (tau 3715ms) completed I/O; added to ready queue [Q A B C]
time 113555ms: Process D (tau 3052ms) completed a CPU burst; 29 bursts to go [Q A B C]
time 113555ms: Recalculating tau for process D: old tau 3052ms ==> new tau 6062ms [Q A B C]
time 113555ms: Process D switching out of CPU; blocking on I/O until time 114267ms [Q A B C]
time 113557ms: Process A (tau 1563ms) started using the CPU for 136ms burst [Q B C]
time 113693ms: Process A (tau 1563ms) completed a CPU burst; 6 bursts to go [Q B C]
time 113693ms: Recalculating tau for process A: old tau 1563ms ==> new tau 408ms [Q B C]
time 113693ms: Process A switching out of CPU; blocking on I/O until time 114886ms [Q B C]
time 113695ms: Process B (tau 3715ms) started using the CPU for 5808ms burst [Q C]
time 114267ms: Process D (tau 6062ms) completed I/O; added to ready queue [Q D C]
time 114886ms: Process A (tau 408ms) completed I/O; added to ready queue [Q A D C]
time 119503ms: Process B (tau 3715ms) completed a CPU burst; 6 bursts to go [Q A D C]
time 119503ms: Recalculating tau for process B: old tau 3715ms ==> new tau 5411ms [Q A D C]
time 119503ms: Process B switching out of CPU; blocking on I/O until time 120085ms [Q A D C]
time 119505ms: Process A (tau 408ms) started using the CPU for 3816ms burst [Q D C]
time 120085ms: Process B (tau 5411ms) completed I/O; added to ready queue [Q B D C]
time 123321ms: Process A (tau 408ms) completed a CPU burst; 5 bursts to go [Q B D C]
time 123321ms: Recalculating tau for process A: old tau 408ms ==> new tau 3169ms [Q B D C]
time 123321ms: Process A switching out of CPU; blocking on I/O until time 124567ms [Q B D C]
time 123323ms: Process B (tau 5411ms) started using the CPU for 3512ms burst [Q D C]
time 124567ms: Process A (tau 3169ms) completed I/O; added to ready queue [Q A D C]
time 126835ms: Process B (tau 5411ms) completed a CPU burst; 5 bursts to go [Q A D C]
time 126835ms: Recalculating tau for process B: old tau 5411ms ==> new tau 3873ms [Q A D C]
time 126835ms: Process B switching out of CPU; blocking on I/O until time 128333ms [Q A D C]
time 126837ms: Process A (tau 3169ms) started using the CPU for 944ms burst [Q D C]
time 127781ms: Process A (tau 3169ms) completed a CPU burst; 4 bursts to go [Q D C]
time 127781ms: Recalculating tau for process A: old tau 3169ms ==> new tau 1367ms [Q D C]
time 127781ms: Process A switching out of CPU; blocking on I/O until time 129908ms [Q D C]
time 127783ms: Process D (tau 6062ms) started using the CPU for 6644ms burst [Q C]
time 128333ms: Process B (tau 3873ms) completed I/O; added to ready queue [Q B C]
time 129908ms: Process A (tau 1367ms) completed I/O; added to ready queue [Q A B C]
time 134427ms: Process D (tau 6062ms) completed a CPU burst; 28 bursts to go [Q A B C]
time 134427ms: Recalculating tau for process D: old tau 6062ms ==> new tau 6534ms [Q A B C]
time 134427ms: Process D switching out of CPU; blocking on I/O until time 136481ms [Q A B C]
time 134429ms: Process A (tau 1367ms) started using the CPU for 2936ms burst [Q B C]
time 136481ms: Process D (tau 6534ms) completed I/O; added to ready queue [Q B D C]
time 137365ms: Process A (tau 1367ms) completed a CPU burst; 3 bursts to go [Q B D C]
time 137365ms: Recalculating tau for process A: old tau 1367ms ==> new tau 2638ms [Q B D C]
time 137365ms: Process A switching out of CPU; blocking on I/O until time 138097ms [Q B D C]
time 137367ms: Process B (tau 3873ms) started using the CPU for 7996ms burst [Q D C]
time 138097ms: Process A (tau 2638ms) completed I/O; added to ready queue [Q A D C]
time 145363ms: Process B (tau 3873ms) completed a CPU burst; 4 bursts to go [Q A D C]
time 145363ms: Recalculating tau for process B: old tau 3873ms ==> new tau 7213ms [Q A D C]
time 145363ms: Process B switching out of CPU; blocking on I/O until time 146366ms [Q A D C]
time 145365ms: Process A (tau 2638ms) started using the CPU for 4496ms burst [Q D C]
time 146366ms: Process B (tau 7213ms) completed I/O; added to ready queue [Q D B C]
time 149861ms: Process A (tau 2638ms) completed a CPU burst; 2 bursts to go [Q D B C]
time 149861ms: Recalculating tau for process A: old tau 2638ms ==> new tau 4143ms [Q D B C]
time 149861ms: Process A switching out of CPU; blocking on I/O until time 152317ms [Q D B C]
time 149863ms: Process D (tau 6534ms) started using the CPU for 3160ms burst [Q B C]
time 152317ms: Process A (tau 4143ms) completed I/O; added to ready queue [Q A B C]
time 153023ms: Process D (tau 6534ms) completed a CPU burst; 27 bursts to go [Q A B C]
time 153023ms: Recalculating tau for process D: old tau 6534ms ==> new tau 3802ms [Q A B C]
time 153023ms: Process D switching out of CPU; blocking on I/O until time 156349ms [Q A B C]
time 153025ms: Process A (tau 4143ms) started using the CPU for 248ms burst [Q B C]
time 153273ms: Process A (tau 4143ms) completed a CPU burst; 1 burst to go [Q B C]
time 153273ms: Recalculating tau for process A: old tau 4143ms ==> new tau 989ms [Q B C]
time 153273ms: Process A switching out of CPU; blocking on I/O until time 153567ms [Q B C]
time 153275ms: Process B (tau 7213ms) started using the CPU for 7880ms burst [Q C]
time 153567ms: Process A (tau 989ms) completed I/O; added to ready queue [Q A C]
time 156349ms: Process D (tau 3802ms) completed I/O; added to ready queue [Q A D C]
time 161155ms: Process B (tau 7213ms) completed a CPU burst; 3 bursts to go [Q A D C]
time 161155ms: Recalculating tau for process B: old tau 7213ms ==> new tau 7754ms [Q A D C]
time 161155ms: Process B switching out of CPU; blocking on I/O until time 162788ms [Q A D C]
time 161157ms: Process A (tau 989ms) started using the CPU for 2588ms burst [Q D C]
time 162788ms: Process B (tau 7754ms) completed I/O; added to ready queue [Q D B C]
time 163745ms: Process A terminated [Q D B C]
time 163747ms: Process D (tau 3802ms) started using the CPU for 4472ms burst [Q B C]
time 168219ms: Process D (tau 3802ms) completed a CPU burst; 26 bursts to go [Q B C]
time 168219ms: Recalculating tau for process D: old tau 3802ms ==> new tau 4345ms [Q B C]
time 168219ms: Process D switching out of CPU; blocking on I/O until time 168668ms [Q B C]
time 168221ms: Process B (tau 7754ms) started using the CPU for 1212ms burst [Q C]
time 168668ms: Process D (tau 4345ms) completed I/O; added to ready queue [Q D C]
time 169433ms: Process B (tau 7754ms) completed a CPU burst; 2 bursts to go [Q D C]
time 169433ms: Recalculating tau for process B: old tau 7754ms ==> new tau 2455ms [Q D C]
time 169433ms: Process B switching out of CPU; blocking on I/O until time 173120ms [Q D C]
time 169435ms: Process D (tau 4345ms) started using the CPU for 6872ms burst [Q C]
time 173120ms: Process B (tau 2455ms) completed I/O; added to ready queue [Q B C]
time 176307ms: Process D (tau 4345ms) completed a CPU burst; 25 bursts to go [Q B C]
time 176307ms: Recalculating tau for process D: old tau 4345ms ==> new tau 6392ms [Q B C]
time 176307ms: Process D switching out of CPU; blocking on I/O until time 176854ms [Q B C]
time 176309ms: Process B (tau 2455ms) started using the CPU for 8980ms burst [Q C]
time 176854ms: Process D (tau 6392ms) completed I/O; added to ready queue [Q D C]
time 185289ms: Process B (tau 2455ms) completed a CPU burst; 1 burst to go [Q D C]
time 185289ms: Recalculating tau for process B: old tau 2455ms ==> new tau 7741ms [Q D C]
time 185289ms: Process B switching out of CPU; blocking on I/O until time 188728ms [Q D C]
time 185291ms: Process D (tau 6392ms) started using the CPU for 6236ms burst [Q C]
time 188728ms: Process B (tau 7741ms) completed I/O; added to ready queue [Q B C]
time 191527ms: Process D (tau 6392ms) completed a CPU burst; 24 bursts to go [Q B C]
time 191527ms: Recalculating tau for process D: old tau 6392ms ==> new tau 6266ms [Q B C]
time 191527ms: Process D switching out of CPU; blocking on I/O until time 191608ms [Q B C]
time 191529ms: Process B (tau 7741ms) started using the CPU for 2460ms burst [Q C]
time 191608ms: Process D (tau 6266ms) completed I/O; added to ready queue [Q D C]
time 193989ms: Process B terminated [Q D C]
time 193991ms: Process D (tau 6266ms) started using the CPU for 2472ms burst [Q C]
time 196463ms: Process D (tau 6266ms) completed a CPU burst; 23 bursts to go [Q C]
time 196463ms: Recalculating tau for process D: old tau 6266ms ==> new tau 3193ms [Q C]
time 196463ms: Process D switching out of CPU; blocking on I/O until time 196597ms [Q C]
time 196465ms: Process C (tau 9450ms) started using the CPU for 5132ms burst [Q <empty>]
time 196597ms: Process D (tau 3193ms) completed I/O; added to ready queue [Q D]
time 201597ms: Process C (tau 9450ms) completed a CPU burst; 55 bursts to go [Q D]
time 201597ms: Recalculating tau for process C: old tau 9450ms ==> new tau 5953ms [Q D]
time 201597ms: Process C switching out of CPU; blocking on I/O until time 203445ms [Q D]
time 201599ms: Process D (tau 3193ms) started using the CPU for 1952ms burst [Q <empty>]
time 203445ms: Process C (tau 5953ms) completed I/O; added to ready queue [Q C]
time 203551ms: Process D (tau 3193ms) completed a CPU burst; 22 bursts to go [Q C]
time 203551ms: Recalculating tau for process D: old tau 3193ms ==> new tau 2188ms [Q C]
time 203551ms: Process D switching out of CPU; blocking on I/O until time 204404ms [Q C]
time 203553ms: Process C (tau 5953ms) started using the CPU for 2896ms burst [Q <empty>]
time 204404ms: Process D (tau 2188ms) completed I/O; added to ready queue [Q D]
time 206449ms: Process C (tau 5953ms) completed a CPU burst; 54 bursts to go [Q D]
time 206449ms: Recalculating tau for process C: old tau 5953ms ==> new tau 3477ms [Q D]
time 206449ms: Process C switching out of CPU; blocking on I/O until time 209768ms [Q D]
time 206451ms: Process D (tau 2188ms) started using the CPU for 5708ms burst [Q <empty>]
time 209768ms: Process C (tau 3477ms) completed I/O; added to ready queue [Q C]
time 212159ms: Process D (tau 2188ms) completed a CPU burst; 21 bursts to go [Q C]
time 212159ms: Recalculating tau for process D: old tau 2188ms ==> new tau 5040ms [Q C]
time 212159ms: Process D switching out of CPU; blocking on I/O until time 214312ms [Q C]
time 212161ms: Process C (tau 3477ms) started using the CPU for 160ms burst [Q <empty>]
time 212321ms: Process C (tau 3477ms) completed a CPU burst; 53 bursts to go [Q <empty>]
time 212321ms: Recalculating tau for process C: old tau 3477ms ==> new tau 791ms [Q <empty>]
time 212321ms: Process C switching out of CPU; blocking on I/O until time 214117ms [Q <empty>]
time 214117ms: Process C (tau 791ms) completed I/O; added to ready queue [Q C]
time 214118ms: Process C (tau 791ms) started using the CPU for 2968ms burst [Q <empty>]
time 214312ms: Process D (tau 5040ms) completed I/O; added to ready queue [Q D]
time 217086ms: Process C (tau 791ms) completed a CPU burst; 52 bursts to go [Q D]
time 217086ms: Recalculating tau for process C: old tau 791ms ==> new tau 2555ms [Q D]
time 217086ms: Process C switching out of CPU; blocking on I/O until time 218130ms [Q D]
time 217088ms: Process D (tau 5040ms) started using the CPU for 2108ms burst [Q <empty>]
time 218130ms: Process C (tau 2555ms) completed I/O; added to ready queue [Q C]
time 219196ms: Process D (tau 5040ms) completed a CPU burst; 20 bursts to go [Q C]
time 219196ms: Recalculating tau for process D: old tau 5040ms ==> new tau 2666ms [Q C]
time 219196ms: Process D switching out of CPU; blocking on I/O until time 219319ms [Q C]
time 219198ms: Process C (tau 2555ms) started using the CPU for 4428ms burst [Q <empty>]
time 219319ms: Process D (tau 2666ms) completed I/O; added to ready queue [Q D]
time 223626ms: Process C (tau 2555ms) completed a CPU burst; 51 bursts to go [Q D]
time 223626ms: Recalculating tau for process C: old tau 2555ms ==> new tau 4073ms [Q D]
time 223626ms: Process C switching out of CPU; blocking on I/O until time 224904ms [Q D]
time 223628ms: Process D (tau 2666ms) started using the CPU for 7608ms burst [Q <empty>]
time 224904ms: Process C (tau 4073ms) completed I/O; added to ready queue [Q C]
time 231236ms: Process D (tau 2666ms) completed a CPU burst; 19 bursts to go [Q C]
time 231236ms: Recalculating tau for process D: old tau 2666ms ==> new tau 6670ms [Q C]
time 231236ms: Process D switching out of CPU; blocking on I/O until time 232384ms [Q C]
time 231238ms: Process C (tau 4073ms) started using the CPU for 7280ms burst [Q <empty>]
time 232384ms: Process D (tau 6670ms) completed I/O; added to ready queue [Q D]
time 238518ms: Process C (tau 4073ms) completed a CPU burst; 50 bursts to go [Q D]
time 238518ms: Recalculating tau for process C: old tau 4073ms ==> new tau 6671ms [Q D]
time 238518ms: Process C switching out of CPU; blocking on I/O until time 239136ms [Q D]
time 238520ms: Process D (tau 6670ms) started using the CPU for 928ms burst [Q <empty>]
time 239136ms: Process C (tau 6671ms) completed I/O; added to ready queue [Q C]
time 239448ms: Process D (tau 6670ms) completed a CPU burst; 18 bursts to go [Q C]
time 239448ms: Recalculating tau for process D: old tau 6670ms ==> new tau 2019ms [Q C]
time 239448ms: Process D switching out of CPU; blocking on I/O until time 239474ms [Q C]
time 239450ms: Process C (tau 6671ms) started using the CPU for 7180ms burst [Q <empty>]
time 239474ms: Process D (tau 2019ms) completed I/O; added to ready queue [Q D]
time 246630ms: Process C (tau 6671ms) completed a CPU burst; 49 bursts to go [Q D]
time 246630ms: Recalculating tau for process C: old tau 6671ms ==> new tau 7084ms [Q D]
time 246630ms: Process C switching out of CPU; blocking on I/O until time 248177ms [Q D]
time 246632ms: Process D (tau 2019ms) started using the CPU for 2848ms burst [Q <empty>]
time 248177ms: Process C (tau 7084ms) completed I/O; added to ready queue [Q C]
time 249480ms: Process D (tau 2019ms) completed a CPU burst; 17 bursts to go [Q C]
time 249480ms: Recalculating tau for process D: old tau 2019ms ==> new tau 2691ms [Q C]
time 249480ms: Process D switching out of CPU; blocking on I/O until time 249866ms [Q C]
time 249482ms: Process C (tau 7084ms) started using the CPU for 8120ms burst [Q <empty>]
time 249866ms: Process D (tau 2691ms) completed I/O; added to ready queue [Q D]
time 257602ms: Process C (tau 7084ms) completed a CPU burst; 48 bursts to go [Q D]
time 257602ms: Recalculating tau for process C: old tau 7084ms ==> new tau 7924ms [Q D]
time 257602ms: Process C switching out of CPU; blocking on I/O until time 259161ms [Q D]
time 257604ms: Process D (tau 2691ms) started using the CPU for 11844ms burst [Q <empty>]
time 259161ms: Process C (tau 7924ms) completed I/O; added to ready queue [Q C]
time 269448ms: Process D (tau 2691ms) completed a CPU burst; 16 bursts to go [Q C]
time 269448ms: Recalculating tau for process D: old tau 2691ms ==> new tau 10105ms [Q C]
time 269448ms: Process D switching out of CPU; blocking on I/O until time 269911ms [Q C]
time 269450ms: Process C (tau 7924ms) started using the CPU for 692ms burst [Q <empty>]
time 269911ms: Process D (tau 10105ms) completed I/O; added to ready queue [Q D]
time 270142ms: Process C (tau 7924ms) completed a CPU burst; 47 bursts to go [Q D]
time 270142ms: Recalculating tau for process C: old tau 7924ms ==> new tau 2067ms [Q D]
time 270142ms: Process C switching out of CPU; blocking on I/O until time 270738ms [Q D]
time 270144ms: Process D (tau 10105ms) started using the CPU for 1572ms burst [Q <empty>]
time 270738ms: Process C (tau 2067ms) completed I/O; added to ready queue [Q C]
time 271716ms: Process D (tau 10105ms) completed a CPU burst; 15 bursts to go [Q C]
time 271716ms: Recalculating tau for process D: old tau 10105ms ==> new tau 3194ms [Q C]
time 271716ms: Process D switching out of CPU; blocking on I/O until time 272123ms [Q C]
time 271718ms: Process C (tau 2067ms) started using the CPU for 3172ms burst [Q <empty>]
time 272123ms: Process D (tau 3194ms) completed I/O; added to ready queue [Q D]
time 274890ms: Process C (tau 2067ms) completed a CPU burst; 46 bursts to go [Q D]
time 274890ms: Recalculating tau for process C: old tau 2067ms ==> new tau 2963ms [Q D]
time 274890ms: Process C switching out of CPU; blocking on I/O until time 275337ms [Q D]
time 274892ms: Process D (tau 3194ms) started using the CPU for 3800ms burst [Q <empty>]
time 275337ms: Process C (tau 2963ms) completed I/O; added to ready queue [Q C]
time 278692ms: Process D (tau 3194ms) completed a CPU burst; 14 bursts to go [Q C]
time 278692ms: Recalculating tau for process D: old tau 3194ms ==> new tau 3685ms [Q C]
time 278692ms: Process D switching out of CPU; blocking on I/O until time 278971ms [Q C]
time 278694ms: Process C (tau 2963ms) started using the CPU for 7724ms burst [Q <empty>]
time 278971ms: Process D (tau 3685ms) completed I/O; added to ready queue [Q D]
time 286418ms: Process C (tau 2963ms) completed a CPU burst; 45 bursts to go [Q D]
time 286418ms: Recalculating tau for process C: old tau 2963ms ==> new tau 6820ms [Q D]
time 286418ms: Process C switching out of CPU; blocking on I/O until time 287234ms [Q D]
time 286420ms: Process D (tau 3685ms) started using the CPU for 5116ms burst [Q <empty>]
time 287234ms: Process C (tau 6820ms) completed I/O; added to ready queue [Q C]
time 291536ms: Process D (tau 3685ms) completed a CPU burst; 13 bursts to go [Q C]
time 291536ms: Recalculating tau for process D: old tau 3685ms ==> new tau 4845ms [Q C]
time 291536ms: Process D switching out of CPU; blocking on I/O until time 291984ms [Q C]
time 291538ms: Process C (tau 6820ms) started using the CPU for 3628ms burst [Q <empty>]
time 291984ms: Process D (tau 4845ms) completed I/O; added to ready queue [Q D]
time 295166ms: Process C (tau 6820ms) completed a CPU burst; 44 bursts to go [Q D]
time 295166ms: Recalculating tau for process C: old tau 6820ms ==> new tau 4235ms [Q D]
time 295166ms: Process C switching out of CPU; blocking on I/O until time 295225ms [Q D]
time 295168ms: Process D (tau 4845ms) started using the CPU for 4152ms burst [Q <empty>]
time 295225ms: Process C (tau 4235ms) completed I/O; added to ready queue [Q C]
time 299320ms: Process D (tau 4845ms) completed a CPU burst; 12 bursts to go [Q C]
time 299320ms: Recalculating tau for process D: old tau 4845ms ==> new tau 4284ms [Q C]
time 299320ms: Process D switching out of CPU; blocking on I/O until time 299862ms [Q C]
time 299322ms: Process C (tau 4235ms) started using the CPU for 2696ms burst [Q <empty>]
time 299862ms: Process D (tau 4284ms) completed I/O; added to ready queue [Q D]
time 302018ms: Process C (tau 4235ms) completed a CPU burst; 43 bursts to go [Q D]
time 302018ms: Recalculating tau for process C: old tau 4235ms ==> new tau 2989ms [Q D]
time 302018ms: Process C switching out of CPU; blocking on I/O until time 302050ms [Q D]
time 302020ms: Process D (tau 4284ms) started using the CPU for 3440ms burst [Q <empty>]
time 302050ms: Process C (tau 2989ms) completed I/O; added to ready queue [Q C]
time 305460ms: Process D (tau 4284ms) completed a CPU burst; 11 bursts to go [Q C]
time 305460ms: Recalculating tau for process D: old tau 4284ms ==> new tau 3601ms [Q C]
time 305460ms: Process D switching out of CPU; blocking on I/O until time 306026ms [Q C]
time 305462ms: Process C (tau 2989ms) started using the CPU for 9204ms burst [Q <empty>]
time 306026ms: Process D (tau 3601ms) completed I/O; added to ready queue [Q D]
time 314666ms: Process C (tau 2989ms) completed a CPU burst; 42 bursts to go [Q D]
time 314666ms: Recalculating tau for process C: old tau 2989ms ==> new tau 8024ms [Q D]
time 314666ms: Process C switching out of CPU; blocking on I/O until time 318054ms [Q D]
time 314668ms: Process D (tau 3601ms) started using the CPU for 56ms burst [Q <empty>]
time 314724ms: Process D (tau 3601ms) completed a CPU burst; 10 bursts to go [Q <empty>]
time 314724ms: Recalculating tau for process D: old tau 3601ms ==> new tau 730ms [Q <empty>]
time 314724ms: Process D switching out of CPU; blocking on I/O until time 315731ms [Q <empty>]
time 315731ms: Process D (tau 730ms) completed I/O; added to ready queue [Q D]
time 315732ms: Process D (tau 730ms) started using the CPU for 1732ms burst [Q <empty>]
time 317464ms: Process D (tau 730ms) completed a CPU burst; 9 bursts to go [Q <empty>]
time 317464ms: Recalculating tau for process D: old tau 730ms ==> new tau 1542ms [Q <empty>]
time 317464ms: Process D switching out of CPU; blocking on I/O until time 319061ms [Q <empty>]
time 318054ms: Process C (tau 8024ms) completed I/O; added to ready queue [Q C]
time 318055ms: Process C (tau 8024ms) started using the CPU for 7356ms burst [Q <empty>]
time 319061ms: Process D (tau 1542ms) completed I/O; added to ready queue [Q D]
time 325411ms: Process C (tau 8024ms) completed a CPU burst; 41 bursts to go [Q D]
time 325411ms: Recalculating tau for process C: old tau 8024ms ==> new tau 7483ms [Q D]
time 325411ms: Process C switching out of CPU; blocking on I/O until time 326222ms [Q D]
time 325413ms: Process D (tau 1542ms) started using the CPU for 9912ms burst [Q <empty>]
time 326222ms: Process C (tau 7483ms) completed I/O; added to ready queue [Q C]
time 335325ms: Process D (tau 1542ms) completed a CPU burst; 8 bursts to go [Q C]
time 335325ms: Recalculating tau for process D: old tau 1542ms ==> new tau 8322ms [Q C]
time 335325ms: Process D switching out of CPU; blocking on I/O until time 336503ms [Q C]
time 335327ms: Process C (tau 7483ms) started using the CPU for 676ms burst [Q <empty>]
time 336003ms: Process C (tau 7483ms) completed a CPU burst; 40 bursts to go [Q <empty>]
time 336003ms: Recalculating tau for process C: old tau 7483ms ==> new tau 1970ms [Q <empty>]
time 336003ms: Process C switching out of CPU; blocking on I/O until time 336349ms [Q <empty>]
time 336349ms: Process C (tau 1970ms) completed I/O; added to ready queue [Q C]
time 336350ms: Process C (tau 1970ms) started using the CPU for 4132ms burst [Q <empty>]
time 336503ms: Process D (tau 8322ms) completed I/O; added to ready queue [Q D]
time 340482ms: Process C (tau 1970ms) completed a CPU burst; 39 bursts to go [Q D]
time 340482ms: Recalculating tau for process C: old tau 1970ms ==> new tau 3722ms [Q D]
time 340482ms: Process C switching out of CPU; blocking on I/O until time 340935ms [Q D]
time 340484ms: Process D (tau 8322ms) started using the CPU for 580ms burst [Q <empty>]
time 340935ms: Process C (tau 3722ms) completed I/O; added to ready queue [Q C]
time 341064ms: Process D (tau 8322ms) completed a CPU burst; 7 bursts to go [Q C]
time 341064ms: Recalculating tau for process D: old tau 8322ms ==> new tau 2051ms [Q C]
time 341064ms: Process D switching out of CPU; blocking on I/O until time 342996ms [Q C]
time 341066ms: Process C (tau 3722ms) started using the CPU for 3364ms burst [Q <empty>]
time 342996ms: Process D (tau 2051ms) completed I/O; added to ready queue [Q D]
time 344430ms: Process C (tau 3722ms) completed a CPU burst; 38 bursts to go [Q D]
time 344430ms: Recalculating tau for process C: old tau 3722ms ==> new tau 3433ms [Q D]
time 344430ms: Process C switching out of CPU; blocking on I/O until time 346104ms [Q D]
time 344432ms: Process D (tau 2051ms) started using the CPU for 640ms burst [Q <empty>]
time 345072ms: Process D (tau 2051ms) completed a CPU burst; 6 bursts to go [Q <empty>]
time 345072ms: Recalculating tau for process D: old tau 2051ms ==> new tau 909ms [Q <empty>]
time 345072ms: Process D switching out of CPU; blocking on I/O until time 345108ms [Q <empty>]
time 345108ms: Process D (tau 909ms) completed I/O; added to ready queue [Q D]
time 345109ms: Process D (tau 909ms) started using the CPU for 316ms burst [Q <empty>]
time 345425ms: Process D (tau 909ms) completed a CPU burst; 5 bursts to go [Q <empty>]
time 345425ms: Recalculating tau for process D: old tau 909ms ==> new tau 429ms [Q <empty>]
time 345425ms: Process D switching out of CPU; blocking on I/O until time 346554ms [Q <empty>]
time 346104ms: Process C (tau 3433ms) completed I/O; added to ready queue [Q C]
time 346105ms: Process C (tau 3433ms) started using the CPU for 6900ms burst [Q <empty>]
time 346554ms: Process D (tau 429ms) completed I/O; added to ready queue [Q D]
time 353005ms: Process C (tau 3433ms) completed a CPU burst; 37 bursts to go [Q D]
time 353005ms: Recalculating tau for process C: old tau 3433ms ==> new tau 6242ms [Q D]
time 353005ms: Process C switching out of CPU; blocking on I/O until time 355276ms [Q D]
time 353007ms: Process D (tau 429ms) started using the CPU for 3388ms burst [Q <empty>]
time 355276ms: Process C (tau 6242ms) completed I/O; added to ready queue [Q C]
time 356395ms: Process D (tau 429ms) completed a CPU burst; 4 bursts to go [Q C]
time 356395ms: Recalculating tau for process D: old tau 429ms ==> new tau 2826ms [Q C]
time 356395ms: Process D switching out of CPU; blocking on I/O until time 357176ms [Q C]
time 356397ms: Process C (tau 6242ms) started using the CPU for 6916ms burst [Q <empty>]
time 357176ms: Process D (tau 2826ms) completed I/O; added to ready queue [Q D]
time 363313ms: Process C (tau 6242ms) completed a CPU burst; 36 bursts to go [Q D]
time 363313ms: Recalculating tau for process C: old tau 6242ms ==> new tau 6788ms [Q D]
time 363313ms: Process C switching out of CPU; blocking on I/O until time 363977ms [Q D]
time 363315ms: Process D (tau 2826ms) started using the CPU for 1976ms burst [Q <empty>]
time 363977ms: Process C (tau 6788ms) completed I/O; added to ready queue [Q C]
time 365291ms: Process D (tau 2826ms) completed a CPU burst; 3 bursts to go [Q C]
time 365291ms: Recalculating tau for process D: old tau 2826ms ==> new tau 2138ms [Q C]
time 365291ms: Process D switching out of CPU; blocking on I/O until time 366548ms [Q C]
time 365293ms: Process C (tau 6788ms) started using the CPU for 7244ms burst [Q <empty>]
time 366548ms: Process D (tau 2138ms) completed I/O; added to ready queue [Q D]
time 372537ms: Process C (tau 6788ms) completed a CPU burst; 35 bursts to go [Q D]
time 372537ms: Recalculating tau for process C: old tau 6788ms ==> new tau 7158ms [Q D]
time 372537ms: Process C switching out of CPU; blocking on I/O until time 372693ms [Q D]
time 372539ms: Process D (tau 2138ms) started using the CPU for 1688ms burst [Q <empty>]
time 372693ms: Process C (tau 7158ms) completed I/O; added to ready queue [Q C]
time 374227ms: Process D (tau 2138ms) completed a CPU burst; 2 bursts to go [Q C]
time 374227ms: Recalculating tau for process D: old tau 2138ms ==> new tau 1774ms [Q C]
time 374227ms: Process D switching out of CPU; blocking on I/O until time 375750ms [Q C]
time 374229ms: Process C (tau 7158ms) started using the CPU for 2396ms burst [Q <empty>]
time 375750ms: Process D (tau 1774ms) completed I/O; added to ready queue [Q D]
time 376625ms: Process C (tau 7158ms) completed a CPU burst; 34 bursts to go [Q D]
time 376625ms: Recalculating tau for process C: old tau 7158ms ==> new tau 3301ms [Q D]
time 376625ms: Process C switching out of CPU; blocking on I/O until time 377133ms [Q D]
time 376627ms: Process D (tau 1774ms) started using the CPU for 6672ms burst [Q <empty>]
time 377133ms: Process C (tau 3301ms) completed I/O; added to ready queue [Q C]
time 383299ms: Process D (tau 1774ms) completed a CPU burst; 1 burst to go [Q C]
time 383299ms: Recalculating tau for process D: old tau 1774ms ==> new tau 5742ms [Q C]
time 383299ms: Process D switching out of CPU; blocking on I/O until time 384163ms [Q C]
time 383301ms: Process C (tau 3301ms) started using the CPU for 7736ms burst [Q <empty>]
time 384163ms: Process D (tau 5742ms) completed I/O; added to ready queue [Q D]
time 391037ms: Process C (tau 3301ms) completed a CPU burst; 33 bursts to go [Q D]
time 391037ms: Recalculating tau for process C: old tau 3301ms ==> new tau 6894ms [Q D]
time 391037ms: Process C switching out of CPU; blocking on I/O until time 392841ms [Q D]
time 391039ms: Process D (tau 5742ms) started using the CPU for 6364ms burst [Q <empty>]
time 392841ms: Process C (tau 6894ms) completed I/O; added to ready queue [Q C]
time 397403ms: Process D terminated [Q C]
time 397405ms: Process C (tau 6894ms) started using the CPU for 4484ms burst [Q <empty>]
time 401889ms: Process C (tau 6894ms) completed a CPU burst; 32 bursts to go [Q <empty>]
time 401889ms: Recalculating tau for process C: old tau 6894ms ==> new tau 4942ms [Q <empty>]
time 401889ms: Process C switching out of CPU; blocking on I/O until time 404118ms [Q <empty>]
time 404118ms: Process C (tau 4942ms) completed I/O; added to ready queue [Q C]
time 404119ms: Process C (tau 4942ms) started using the CPU for 7564ms burst [Q <empty>]
time 411683ms: Process C (tau 4942ms) completed a CPU burst; 31 bursts to go [Q <empty>]
time 411683ms: Recalculating tau for process C: old tau 4942ms ==> new tau 7066ms [Q <empty>]
time 411683ms: Process C switching out of CPU; blocking on I/O until time 412906ms [Q <empty>]
time 412906ms: Process C (tau 7066ms) completed I/O; added to ready queue [Q C]
time 412907ms: Process C (tau 7066ms) started using the CPU for 3724ms burst [Q <empty>]
time 416631ms: Process C (tau 7066ms) completed a CPU burst; 30 bursts to go [Q <empty>]
time 416631ms: Recalculating tau for process C: old tau 7066ms ==> new tau 4359ms [Q <empty>]
time 416631ms: Process C switching out of CPU; blocking on I/O until time 416753ms [Q <empty>]
time 416753ms: Process C (tau 4359ms) completed I/O; added to ready queue [Q C]
time 416754ms: Process C (tau 4359ms) started using the CPU for 1608ms burst [Q <empty>]
time 418362ms: Process C (tau 4359ms) completed a CPU burst; 29 bursts to go [Q <empty>]
time 418362ms: Recalculating tau for process C: old tau 4359ms ==> new tau 2131ms [Q <empty>]
time 418362ms: Process C switching out of CPU; blocking on I/O until time 418798ms [Q <empty>]
time 418798ms: Process C (tau 2131ms) completed I/O; added to ready queue [Q C]
time 418799ms: Process C (tau 2131ms) started using the CPU for 6880ms burst [Q <empty>]
time 425679ms: Process C (tau 2131ms) completed a CPU burst; 28 bursts to go [Q <empty>]
time 425679ms: Recalculating tau for process C: old tau 2131ms ==> new tau 5978ms [Q <empty>]
time 425679ms: Process C switching out of CPU; blocking on I/O until time 427157ms [Q <empty>]
time 427157ms: Process C (tau 5978ms) completed I/O; added to ready queue [Q C]
time 427158ms: Process C (tau 5978ms) started using the CPU for 972ms burst [Q <empty>]
time 428130ms: Process C (tau 5978ms) completed a CPU burst; 27 bursts to go [Q <empty>]
time 428130ms: Recalculating tau for process C: old tau 5978ms ==> new tau 1924ms [Q <empty>]
time 428130ms: Process C switching out of CPU; blocking on I/O until time 428448ms [Q <empty>]
time 428448ms: Process C (tau 1924ms) completed I/O; added to ready queue [Q C]
time 428449ms: Process C (tau 1924ms) started using the CPU for 176ms burst [Q <empty>]
time 428625ms: Process C (tau 1924ms) completed a CPU burst; 26 bursts to go [Q <empty>]
time 428625ms: Recalculating tau for process C: old tau 1924ms ==> new tau 509ms [Q <empty>]
time 428625ms: Process C switching out of CPU; blocking on I/O until time 430752ms [Q <empty>]
time 430752ms: Process C (tau 509ms) completed I/O; added to ready queue [Q C]
time 430753ms: Process C (tau 509ms) started using the CPU for 412ms burst [Q <empty>]
time 431165ms: Process C (tau 509ms) completed a CPU burst; 25 bursts to go [Q <empty>]
time 431165ms: Recalculating tau for process C: old tau 509ms ==> new tau 431ms [Q <empty>]
time 431165ms: Process C switching out of CPU; blocking on I/O until time 431731ms [Q <empty>]
time 431731ms: Process C (tau 431ms) completed I/O; added to ready queue [Q C]
time 431732ms: Process C (tau 431ms) started using the CPU for 576ms burst [Q <empty>]
time 432308ms: Process C (tau 431ms) completed a CPU burst; 24 bursts to go [Q <empty>]
time 432308ms: Recalculating tau for process C: old tau 431ms ==> new tau 549ms [Q <empty>]
time 432308ms: Process C switching out of CPU; blocking on I/O until time 432380ms [Q <empty>]
time 432380ms: Process C (tau 549ms) completed I/O; added to ready queue [Q C]
time 432381ms: Process C (tau 549ms) started using the CPU for 4928ms burst [Q <empty>]
time 437309ms: Process C (tau 549ms) completed a CPU burst; 23 bursts to go [Q <empty>]
time 437309ms: Recalculating tau for process C: old tau 549ms ==> new tau 4096ms [Q <empty>]
time 437309ms: Process C switching out of CPU; blocking on I/O until time 438012ms [Q <empty>]
time 438012ms: Process C (tau 4096ms) completed I/O; added to ready queue [Q C]
time 438013ms: Process C (tau 4096ms) started using the CPU for 2804ms burst [Q <empty>]
time 440817ms: Process C (tau 4096ms) completed a CPU burst; 22 bursts to go [Q <empty>]
time 440817ms: Recalculating tau for process C: old tau 4096ms ==> new tau 3050ms [Q <empty>]
time 440817ms: Process C switching out of CPU; blocking on I/O until time 441836ms [Q <empty>]
time 441836ms: Process C (tau 3050ms) completed I/O; added to ready queue [Q C]
time 441837ms: Process C (tau 3050ms) started using the CPU for 2120ms burst [Q <empty>]
time 443957ms: Process C (tau 3050ms) completed a CPU burst; 21 bursts to go [Q <empty>]
time 443957ms: Recalculating tau for process C: old tau 3050ms ==> new tau 2297ms [Q <empty>]
time 443957ms: Process C switching out of CPU; blocking on I/O until time 445820ms [Q <empty>]
time 445820ms: Process C (tau 2297ms) completed I/O; added to ready queue [Q C]
time 445821ms: Process C (tau 2297ms) started using the CPU for 1944ms burst [Q <empty>]
time 447765ms: Process C (tau 2297ms) completed a CPU burst; 20 bursts to go [Q <empty>]
time 447765ms: Recalculating tau for process C: old tau 2297ms ==> new tau 2012ms [Q <empty>]
time 447765ms: Process C switching out of CPU; blocking on I/O until time 447769ms [Q <empty>]
time 447769ms: Process C (tau 2012ms) completed I/O; added to ready queue [Q C]
time 447770ms: Process C (tau 2012ms) started using the CPU for 2472ms burst [Q <empty>]
time 450242ms: Process C (tau 2012ms) completed a CPU burst; 19 bursts to go [Q <empty>]
time 450242ms: Recalculating tau for process C: old tau 2012ms ==> new tau 2385ms [Q <empty>]
time 450242ms: Process C switching out of CPU; blocking on I/O until time 450431ms [Q <empty>]
time 450431ms: Process C (tau 2385ms) completed I/O; added to ready queue [Q C]
time 450432ms: Process C (tau 2385ms) started using the CPU for 868ms burst [Q <empty>]
time 451300ms: Process C (tau 2385ms) completed a CPU burst; 18 bursts to go [Q <empty>]
time 451300ms: Recalculating tau for process C: old tau 2385ms ==> new tau 1157ms [Q <empty>]
time 451300ms: Process C switching out of CPU; blocking on I/O until time 452324ms [Q <empty>]
time 452324ms: Process C (tau 1157ms) completed I/O; added to ready queue [Q C]
time 452325ms: Process C (tau 1157ms) started using the CPU for 3208ms burst [Q <empty>]
time 455533ms: Process C (tau 1157ms) completed a CPU burst; 17 bursts to go [Q <empty>]
time 455533ms: Recalculating tau for process C: old tau 1157ms ==> new tau 2819ms [Q <empty>]
time 455533ms: Process C switching out of CPU; blocking on I/O until time 456637ms [Q <empty>]
time 456637ms: Process C (tau 2819ms) completed I/O; added to ready queue [Q C]
time 456638ms: Process C (tau 2819ms) started using the CPU for 1672ms burst [Q <empty>]
time 458310ms: Process C (tau 2819ms) completed a CPU burst; 16 bursts to go [Q <empty>]
time 458310ms: Recalculating tau for process C: old tau 2819ms ==> new tau 1890ms [Q <empty>]
time 458310ms: Process C switching out of CPU; blocking on I/O until time 460888ms [Q <empty>]
time 460888ms: Process C (tau 1890ms) completed I/O; added to ready queue [Q C]
time 460889ms: Process C (tau 1890ms) started using the CPU for 3536ms burst [Q <empty>]
time 464425ms: Process C (tau 1890ms) completed a CPU burst; 15 bursts to go [Q <empty>]
time 464425ms: Recalculating tau for process C: old tau 1890ms ==> new tau 3224ms [Q <empty>]
time 464425ms: Process C switching out of CPU; blocking on I/O until time 467963ms [Q <empty>]
time 467963ms: Process C (tau 3224ms) completed I/O; added to ready queue [Q C]
time 467964ms: Process C (tau 3224ms) started using the CPU for 2988ms burst [Q <empty>]
time 470952ms: Process C (tau 3224ms) completed a CPU burst; 14 bursts to go [Q <empty>]
time 470952ms: Recalculating tau for process C: old tau 3224ms ==> new tau 3033ms [Q <empty>]
time 470952ms: Process C switching out of CPU; blocking on I/O until time 473029ms [Q <empty>]
time 473029ms: Process C (tau 3033ms) completed I/O; added to ready queue [Q C]
time 473030ms: Process C (tau 3033ms) started using the CPU for 7804ms burst [Q <empty>]
time 480834ms: Process C (tau 3033ms) completed a CPU burst; 13 bursts to go [Q <empty>]
time 480834ms: Recalculating tau for process C: old tau 3033ms ==> new tau 6898ms [Q <empty>]
time 480834ms: Process C switching out of CPU; blocking on I/O until time 482102ms [Q <empty>]
time 482102ms: Process C (tau 6898ms) completed I/O; added to ready queue [Q C]
time 482103ms: Process C (tau 6898ms) started using the CPU for 5608ms burst [Q <empty>]
time 487711ms: Process C (tau 6898ms) completed a CPU burst; 12 bursts to go [Q <empty>]
time 487711ms: Recalculating tau for process C: old tau 6898ms ==> new tau 5854ms [Q <empty>]
time 487711ms: Process C switching out of CPU; blocking on I/O until time 488009ms [Q <empty>]
time 488009ms: Process C (tau 5854ms) completed I/O; added to ready queue [Q C]
time 488010ms: Process C (tau 5854ms) started using the CPU for 1160ms burst [Q <empty>]
time 489170ms: Process C (tau 5854ms) completed a CPU burst; 11 bursts to go [Q <empty>]
time 489170ms: Recalculating tau for process C: old tau 5854ms ==> new tau 2052ms [Q <empty>]
time 489170ms: Process C switching out of CPU; blocking on I/O until time 489812ms [Q <empty>]
time 489812ms: Process C (tau 2052ms) completed I/O; added to ready queue [Q C]
time 489813ms: Process C (tau 2052ms) started using the CPU for 3048ms burst [Q <empty>]
time 492861ms: Process C (tau 2052ms) completed a CPU burst; 10 bursts to go [Q <empty>]
time 492861ms: Recalculating tau for process C: old tau 2052ms ==> new tau 2859ms [Q <empty>]
time 492861ms: Process C switching out of CPU; blocking on I/O until time 492873ms [Q <empty>]
time 492873ms: Process C (tau 2859ms) completed I/O; added to ready queue [Q C]
time 492874ms: Process C (tau 2859ms) started using the CPU for 1120ms burst [Q <empty>]
time 493994ms: Process C (tau 2859ms) completed a CPU burst; 9 bursts to go [Q <empty>]
time 493994ms: Recalculating tau for process C: old tau 2859ms ==> new tau 1451ms [Q <empty>]
time 493994ms: Process C switching out of CPU; blocking on I/O until time 494742ms [Q <empty>]
time 494742ms: Process C (tau 1451ms) completed I/O; added to ready queue [Q C]
time 494743ms: Process C (tau 1451ms) started using the CPU for 8872ms burst [Q <empty>]
time 503615ms: Process C (tau 1451ms) completed a CPU burst; 8 bursts to go [Q <empty>]
time 503615ms: Recalculating tau for process C: old tau 1451ms ==> new tau 7463ms [Q <empty>]
time 503615ms: Process C switching out of CPU; blocking on I/O until time 506059ms [Q <empty>]
time 506059ms: Process C (tau 7463ms) completed I/O; added to ready queue [Q C]
time 506060ms: Process C (tau 7463ms) started using the CPU for 3112ms burst [Q <empty>]
time 509172ms: Process C (tau 7463ms) completed a CPU burst; 7 bursts to go [Q <empty>]
time 509172ms: Recalculating tau for process C: old tau 7463ms ==> new tau 3939ms [Q <empty>]
time 509172ms: Process C switching out of CPU; blocking on I/O until time 509841ms [Q <empty>]
time 509841ms: Process C (tau 3939ms) completed I/O; added to ready queue [Q C]
time 509842ms: Process C (tau 3939ms) started using the CPU for 1904ms burst [Q <empty>]
time 511746ms: Process C (tau 3939ms) completed a CPU burst; 6 bursts to go [Q <empty>]
time 511746ms: Recalculating tau for process C: old tau 3939ms ==> new tau 2291ms [Q <empty>]
time 511746ms: Process C switching out of CPU; blocking on I/O until time 512464ms [Q <empty>]
time 512464ms: Process C (tau 2291ms) completed I/O; added to ready queue [Q C]
time 512465ms: Process C (tau 2291ms) started using the CPU for 5488ms burst [Q <empty>]
time 517953ms: Process C (tau 2291ms) completed a CPU burst; 5 bursts to go [Q <empty>]
time 517953ms: Recalculating tau for process C: old tau 2291ms ==> new tau 4881ms [Q <empty>]
time 517953ms: Process C switching out of CPU; blocking on I/O until time 520629ms [Q <empty>]
time 520629ms: Process C (tau 4881ms) completed I/O; added to ready queue [Q C]
time 520630ms: Process C (tau 4881ms) started using the CPU for 3340ms burst [Q <empty>]
time 523970ms: Process C (tau 4881ms) completed a CPU burst; 4 bursts to go [Q <empty>]
time 523970ms: Recalculating tau for process C: old tau 4881ms ==> new tau 3633ms [Q <empty>]
time 523970ms: Process C switching out of CPU; blocking on I/O until time 524413ms [Q <empty>]
time 524413ms: Process C (tau 3633ms) completed I/O; added to ready queue [Q C]
time 524414ms: Process C (tau 3633ms) started using the CPU for 7076ms burst [Q <empty>]
time 531490ms: Process C (tau 3633ms) completed a CPU burst; 3 bursts to go [Q <empty>]
time 531490ms: Recalculating tau for process C: old tau 3633ms ==> new tau 6422ms [Q <empty>]
time 531490ms: Process C switching out of CPU; blocking on I/O until time 532278ms [Q <empty>]
time 532278ms: Process C (tau 6422ms) completed I/O; added to ready queue [Q C]
time 532279ms: Process C (tau 6422ms) started using the CPU for 9540ms burst [Q <empty>]
time 541819ms: Process C (tau 6422ms) completed a CPU burst; 2 bursts to go [Q <empty>]
time 541819ms: Recalculating tau for process C: old tau 6422ms ==> new tau 8948ms [Q <empty>]
time 541819ms: Process C switching out of CPU; blocking on I/O until time 541861ms [Q <empty>]
time 541861ms: Process C (tau 8948ms) completed I/O; added to ready queue [Q C]
time 541862ms: Process C (tau 8948ms) started using the CPU for 1784ms burst [Q <empty>]
time 543646ms: Process C (tau 8948ms) completed a CPU burst; 1 burst to go [Q <empty>]
time 543646ms: Recalculating tau for process C: old tau 8948ms ==> new tau 3146ms [Q <empty>]
time 543646ms: Process C switching out of CPU; blocking on I/O until time 544273ms [Q <empty>]
time 544273ms: Process C (tau 3146ms) completed I/O; added to ready queue [Q C]
time 544274ms: Process C (tau 3146ms) started using the CPU for 1704ms burst [Q <empty>]
time 545978ms: Process C terminated [Q <empty>]
time 545979ms: Simulator ended for SJF [Q <empty>]

time 0ms: Simulator started for SRT [Q <empty>]
time 26ms: Process C (tau 1000ms) arrived; added to ready queue [Q C]
time 27ms: Process C (tau 1000ms) started using the CPU for 2920ms burst [Q <empty>]
time 100ms: Process D (tau 1000ms) arrived; added to ready queue [Q D]
time 136ms: Process A (tau 1000ms) arrived; added to ready queue [Q A D]
time 929ms: Process B (tau 1000ms) arrived; added to ready queue [Q A B D]
time 2947ms: Process C (tau 1000ms) completed a CPU burst; 59 bursts to go [Q A B D]
time 2947ms: Recalculating tau for process C: old tau 1000ms ==> new tau 2556ms [Q A B D]
time 2947ms: Process C switching out of CPU; blocking on I/O until time 3316ms [Q A B D]
time 2949ms: Process A (tau 1000ms) started using the CPU for 5320ms burst [Q B D]
time 3316ms: Process C (tau 2556ms) completed I/O; added to ready queue [Q B D C]
time 8269ms: Process A (tau 1000ms) completed a CPU burst; 16 bursts to go [Q B D C]
time 8269ms: Recalculating tau for process A: old tau 1000ms ==> new tau 4500ms [Q B D C]
time 8269ms: Process A switching out of CPU; blocking on I/O until time 8987ms [Q B D C]
time 8271ms: Process B (tau 1000ms) started using the CPU for 9752ms burst [Q D C]
time 8987ms: Process A (tau 4500ms) completed I/O; added to ready queue [Q D C A]
time 18023ms: Process B (tau 1000ms) completed a CPU burst; 11 bursts to go [Q D C A]
time 18023ms: Recalculating tau for process B: old tau 1000ms ==> new tau 8090ms [Q D C A]
time 18023ms: Process B switching out of CPU; blocking on I/O until time 18134ms [Q D C A]
time 18025ms: Process D (tau 1000ms) started using the CPU for 6964ms burst [Q C A]
time 18134ms: Process B (tau 8090ms) completed I/O; added to ready queue [Q C A B]
time 24989ms: Process D (tau 1000ms) completed a CPU burst; 36 bursts to go [Q C A B]
time 24989ms: Recalculating tau for process D: old tau 1000ms ==> new tau 5831ms [Q C A B]
time 24989ms: Process D switching out of CPU; blocking on I/O until time 25417ms [Q C A B]
time 24991ms: Process C (tau 2556ms) started using the CPU for 2328ms burst [Q A B]
time 25417ms: Process D (tau 5831ms) completed I/O; added to ready queue [Q A D B]
time 27319ms: Process C (tau 2556ms) completed a CPU burst; 58 bursts to go [Q A D B]
time 27319ms: Recalculating tau for process C: old tau 2556ms ==> new tau 2372ms [Q A D B]
time 27319ms: Process C switching out of CPU; blocking on I/O until time 30432ms [Q A D B]
time 27321ms: Process A (tau 4500ms) started using the CPU for 2940ms burst [Q D B]
time 30261ms: Process A (tau 4500ms) completed a CPU burst; 15 bursts to go [Q D B]
time 30261ms: Recalculating tau for process A: old tau 4500ms ==> new tau 3237ms [Q D B]
time 30261ms: Process A switching out of CPU; blocking on I/O until time 30344ms [Q D B]
time 30263ms: Process D (tau 5831ms) started using the CPU for 3260ms burst [Q B]
time 30344ms: Process A (tau 3237ms) completed I/O; preempting D [Q A B]
time 30346ms: Process A (tau 3237ms) started using the CPU for 96ms burst [Q D B]
time 30432ms: Process C (tau 2372ms) completed I/O; preempting A [Q C D B]
time 30434ms: Process C (tau 2372ms) started using the CPU for 1180ms burst [Q A D B]
time 31614ms: Process C (tau 2372ms) completed a CPU burst; 57 bursts to go [Q A D B]
time 31614ms: Recalculating tau for process C: old tau 2372ms ==> new tau 1407ms [Q A D B]
time 31614ms: Process C switching out of CPU; blocking on I/O until time 32935ms [Q A D B]
time 31616ms: Process A (tau 3237ms) started using the CPU for remaining 10ms of 96ms burst [Q D B]
time 31626ms: Process A (tau 3237ms) completed a CPU burst; 14 bursts to go [Q D B]
time 31626ms: Recalculating tau for process A: old tau 3237ms ==> new tau 693ms [Q D B]
time 31626ms: Process A switching out of CPU; blocking on I/O until time 31683ms [Q D B]
time 31628ms: Process D (tau 5831ms) started using the CPU for remaining 3179ms of 3260ms burst [Q B]
time 31683ms: Process A (tau 693ms) completed I/O; preempting D [Q A B]
time 31685ms: Process A (tau 693ms) started using the CPU for 2732ms burst [Q D B]
time 32935ms: Process C (tau 1407ms) completed I/O; added to ready queue [Q C D B]
time 34417ms: Process A (tau 693ms) completed a CPU burst; 13 bursts to go [Q C D B]
time 34417ms: Recalculating tau for process A: old tau 693ms ==> new tau 2345ms [Q C D B]
time 34417ms: Process A switching out of CPU; blocking on I/O until time 34649ms [Q C D B]
time 34419ms: Process C (tau 1407ms) started using the CPU for 11336ms burst [Q D B]
time 34649ms: Process A (tau 2345ms) completed I/O; added to ready queue [Q A D B]
time 45755ms: Process C (tau 1407ms) completed a CPU burst; 56 bursts to go [Q A D B]
time 45755ms: Recalculating tau for process C: old tau 1407ms ==> new tau 9450ms [Q A D B]
time 45755ms: Process C switching out of CPU; blocking on I/O until time 46432ms [Q A D B]
time 45757ms: Process A (tau 2345ms) started using the CPU for 4400ms burst [Q D B]
time 46432ms: Process C (tau 9450ms) completed I/O; added to ready queue [Q D B C]
time 50157ms: Process A (tau 2345ms) completed a CPU burst; 12 bursts to go [Q D B C]
time 50157ms: Recalculating tau for process A: old tau 2345ms ==> new tau 4010ms [Q D B C]
time 50157ms: Process A switching out of CPU; blocking on I/O until time 51935ms [Q D B C]
time 50159ms: Process D (tau 5831ms) started using the CPU for remaining 3124ms of 3260ms burst [Q B C]
time 51935ms: Process A (tau 4010ms) completed I/O; added to ready queue [Q A B C]
time 53283ms: Process D (tau 5831ms) completed a CPU burst; 35 bursts to go [Q A B C]
time 53283ms: Recalculating tau for process D: old tau 5831ms ==> new tau 3749ms [Q A B C]
time 53283ms: Process D switching out of CPU; blocking on I/O until time 55482ms [Q A B C]
time 53285ms: Process A (tau 4010ms) started using the CPU for 4000ms burst [Q B C]
time 55482ms: Process D (tau 3749ms) completed I/O; added to ready queue [Q D B C]
time 57285ms: Process A (tau 4010ms) completed a CPU burst; 11 bursts to go [Q D B C]
time 57285ms: Recalculating tau for process A: old tau 4010ms ==> new tau 4002ms [Q D B C]
time 57285ms: Process A switching out of CPU; blocking on I/O until time 58154ms [Q D B C]
time 57287ms: Process D (tau 3749ms) started using the CPU for 1428ms burst [Q B C]
time 58154ms: Process A (tau 4002ms) completed I/O; added to ready queue [Q A B C]
time 58715ms: Process D (tau 3749ms) completed a CPU burst; 34 bursts to go [Q A B C]
time 58715ms: Recalculating tau for process D: old tau 3749ms ==> new tau 1869ms [Q A B C]
time 58715ms: Process D switching out of CPU; blocking on I/O until time 59087ms [Q A B C]
time 58717ms: Process A (tau 4002ms) started using the CPU for 4664ms burst [Q B C]
time 59087ms: Process D (tau 1869ms) completed I/O; preempting A [Q D B C]
time 59089ms: Process D (tau 1869ms) started using the CPU for 5920ms burst [Q A B C]
time 65009ms: Process D (tau 1869ms) completed a CPU burst; 33 bursts to go [Q A B C]
time 65009ms: Recalculating tau for process D: old tau 1869ms ==> new tau 5151ms [Q A B C]
time 65009ms: Process D switching out of CPU; blocking on I/O until time 67052ms [Q A B C]
time 65011ms: Process A (tau 4002ms) started using the CPU for remaining 4294ms of 4664ms burst [Q B C]
time 67052ms: Process D (tau 5151ms) completed I/O; added to ready queue [Q D B C]
time 69305ms: Process A (tau 4002ms) completed a CPU burst; 10 bursts to go [Q D B C]
time 69305ms: Recalculating tau for process A: old tau 4002ms ==> new tau 4539ms [Q D B C]
time 69305ms: Process A switching out of CPU; blocking on I/O until time 69967ms [Q D B C]
time 69307ms: Process D (tau 5151ms) started using the CPU for 2524ms burst [Q B C]
time 69967ms: Process A (tau 4539ms) completed I/O; added to ready queue [Q A B C]
time 71831ms: Process D (tau 5151ms) completed a CPU burst; 32 bursts to go [Q A B C]
time 71831ms: Recalculating tau for process D: old tau 5151ms ==> new tau 3024ms [Q A B C]
time 71831ms: Process D switching out of CPU; blocking on I/O until time 74719ms [Q A B C]
time 71833ms: Process A (tau 4539ms) started using the CPU for 6244ms burst [Q B C]
time 74719ms: Process D (tau 3024ms) completed I/O; added to ready queue [Q D B C]
time 78077ms: Process A (tau 4539ms) completed a CPU burst; 9 bursts to go [Q D B C]
time 78077ms: Recalculating tau for process A: old tau 4539ms ==> new tau 5921ms [Q D B C]
time 78077ms: Process A switching out of CPU; blocking on I/O until time 78430ms [Q D B C]
time 78079ms: Process D (tau 3024ms) started using the CPU for 3876ms burst [Q B C]
time 78430ms: Process A (tau 5921ms) completed I/O; added to ready queue [Q A B C]
time 81955ms: Process D (tau 3024ms) completed a CPU burst; 31 bursts to go [Q A B C]
time 81955ms: Recalculating tau for process D: old tau 3024ms ==> new tau 3715ms [Q A B C]
time 81955ms: Process D switching out of CPU; blocking on I/O until time 83226ms [Q A B C]
time 81957ms: Process A (tau 5921ms) started using the CPU for 596ms burst [Q B C]
time 82553ms: Process A (tau 5921ms) completed a CPU burst; 8 bursts to go [Q B C]
time 82553ms: Recalculating tau for process A: old tau 5921ms ==> new tau 1608ms [Q B C]
time 82553ms: Process A switching out of CPU; blocking on I/O until time 82644ms [Q B C]
time 82555ms: Process B (tau 8090ms) started using the CPU for 4692ms burst [Q C]
time 82644ms: Process A (tau 1608ms) completed I/O; preempting B [Q A C]
time 82646ms: Process A (tau 1608ms) started using the CPU for 1552ms burst [Q B C]
time 83226ms: Process D (tau 3715ms) completed I/O; added to ready queue [Q D B C]
time 84198ms: Process A (tau 1608ms) completed a CPU burst; 7 bursts to go [Q D B C]
time 84198ms: Recalculating tau for process A: old tau 1608ms ==> new tau 1563ms [Q D B C]
time 84198ms: Process A switching out of CPU; blocking on I/O until time 85120ms [Q D B C]
time 84200ms: Process D (tau 3715ms) started using the CPU for 2896ms burst [Q B C]
time 85120ms: Process A (tau 1563ms) completed I/O; preempting D [Q A B C]
time 85122ms: Process A (tau 1563ms) started using the CPU for 136ms burst [Q D B C]
time 85258ms: Process A (tau 1563ms) completed a CPU burst; 6 bursts to go [Q D B C]
time 85258ms: Recalculating tau for process A: old tau 1563ms ==> new tau 408ms [Q D B C]
time 85258ms: Process A switching out of CPU; blocking on I/O until time 86451ms [Q D B C]
time 85260ms: Process D (tau 3715ms) started using the CPU for remaining 1976ms of 2896ms burst [Q B C]
time 86451ms: Process A (tau 408ms) completed I/O; preempting D [Q A B C]
time 86453ms: Process A (tau 408ms) started using the CPU for 3816ms burst [Q D B C]
time 90269ms: Process A (tau 408ms) completed a CPU burst; 5 bursts to go [Q D B C]
time 90269ms: Recalculating tau for process A: old tau 408ms ==> new tau 3169ms [Q D B C]
time 90269ms: Process A switching out of CPU; blocking on I/O until time 91515ms [Q D B C]
time 90271ms: Process D (tau 3715ms) started using the CPU for remaining 785ms of 2896ms burst [Q B C]
time 91056ms: Process D (tau 3715ms) completed a CPU burst; 30 bursts to go [Q B C]
time 91056ms: Recalculating tau for process D: old tau 3715ms ==> new tau 3052ms [Q B C]
time 91056ms: Process D switching out of CPU; blocking on I/O until time 92514ms [Q B C]
time 91058ms: Process B (tau 8090ms) started using the CPU for remaining 4603ms of 4692ms burst [Q C]
time 91515ms: Process A (tau 3169ms) completed I/O; preempting B [Q A C]
time 91517ms: Process A (tau 3169ms) started using the CPU for 944ms burst [Q B C]
time 92461ms: Process A (tau 3169ms) completed a CPU burst; 4 bursts to go [Q B C]
time 92461ms: Recalculating tau for process A: old tau 3169ms ==> new tau 1367ms [Q B C]
time 92461ms: Process A switching out of CPU; blocking on I/O until time 94588ms [Q B C]
time 92463ms: Process B (tau 8090ms) started using the CPU for remaining 4146ms of 4692ms burst [Q C]
time 92514ms: Process D (tau 3052ms) completed I/O; preempting B [Q D C]
time 92516ms: Process D (tau 3052ms) started using the CPU for 6768ms burst [Q B C]
time 94588ms: Process A (tau 1367ms) completed I/O; added to ready queue [Q A B C]
time 99284ms: Process D (tau 3052ms) completed a CPU burst; 29 bursts to go [Q A B C]
time 99284ms: Recalculating tau for process D: old tau 3052ms ==> new tau 6062ms [Q A B C]
time 99284ms: Process D switching out of CPU; blocking on I/O until time 99996ms [Q A B C]
time 99286ms: Process A (tau 1367ms) started using the CPU for 2936ms burst [Q B C]
time 99996ms: Process D (tau 6062ms) completed I/O; added to ready queue [Q D B C]
time 102222ms: Process A (tau 1367ms) completed a CPU burst; 3 bursts to go [Q D B C]
time 102222ms: Recalculating tau for process A: old tau 1367ms ==> new tau 2638ms [Q D B C]
time 102222ms: Process A switching out of CPU; blocking on I/O until time 102954ms [Q D B C]
time 102224ms: Process D (tau 6062ms) started using the CPU for 6644ms burst [Q B C]
time 102954ms: Process A (tau 2638ms) completed I/O; preempting D [Q A B C]
time 102956ms: Process A (tau 2638ms) started using the CPU for 4496ms burst [Q D B C]
time 107452ms: Process A (tau 2638ms) completed a CPU burst; 2 bursts to go [Q D B C]
time 107452ms: Recalculating tau for process A: old tau 2638ms ==> new tau 4143ms [Q D B C]
time 107452ms: Process A switching out of CPU; blocking on I/O until time 109908ms [Q D B C]
time 107454ms: Process D (tau 6062ms) started using the CPU for remaining 5914ms of 6644ms burst [Q B C]
time 109908ms: Process A (tau 4143ms) completed I/O; added to ready queue [Q A B C]
time 113368ms: Process D (tau 6062ms) completed a CPU burst; 28 bursts to go [Q A B C]
time 113368ms: Recalculating tau for process D: old tau 6062ms ==> new tau 6534ms [Q A B C]
time 113368ms: Process D switching out of CPU; blocking on I/O until time 115422ms [Q A B C]
time 113370ms: Process A (tau 4143ms) started using the CPU for 248ms burst [Q B C]
time 113618ms: Process A (tau 4143ms) completed a CPU burst; 1 burst to go [Q B C]
time 113618ms: Recalculating tau for process A: old tau 4143ms ==> new tau 989ms [Q B C]
time 113618ms: Process A switching out of CPU; blocking on I/O until time 113912ms [Q B C]
time 113620ms: Process B (tau 8090ms) started using the CPU for remaining 4095ms of 4692ms burst [Q C]
time 113912ms: Process A (tau 989ms) completed I/O; preempting B [Q A C]
time 113914ms: Process A (tau 989ms) started using the CPU for 2588ms burst [Q B C]
time 115422ms: Process D (tau 6534ms) completed I/O; added to ready queue [Q D B C]
time 116502ms: Process A terminated [Q D B C]
time 116504ms: Process D (tau 6534ms) started using the CPU for 3160ms burst [Q B C]
time 119664ms: Process D (tau 6534ms) completed a CPU burst; 27 bursts to go [Q B C]
time 119664ms: Recalculating tau for process D: old tau 6534ms ==> new tau 3802ms [Q B C]
time 119664ms: Process D switching out of CPU; blocking on I/O until time 122990ms [Q B C]
time 119666ms: Process B (tau 8090ms) started using the CPU for remaining 3803ms of 4692ms burst [Q C]
time 122990ms: Process D (tau 3802ms) completed I/O; preempting B [Q D C]
time 122992ms: Process D (tau 3802ms) started using the CPU for 4472ms burst [Q B C]
time 127464ms: Process D (tau 3802ms) completed a CPU burst; 26 bursts to go [Q B C]
time 127464ms: Recalculating tau for process D: old tau 3802ms ==> new tau 4345ms [Q B C]
time 127464ms: Process D switching out of CPU; blocking on I/O until time 127913ms [Q B C]
time 127466ms: Process B (tau 8090ms) started using the CPU for remaining 479ms of 4692ms burst [Q C]
time 127913ms: Process D (tau 4345ms) completed I/O; added to ready queue [Q D C]
time 127945ms: Process B (tau 8090ms) completed a CPU burst; 10 bursts to go [Q D C]
time 127945ms: Recalculating tau for process B: old tau 8090ms ==> new tau 5338ms [Q D C]
time 127945ms: Process B switching out of CPU; blocking on I/O until time 128013ms [Q D C]
time 127947ms: Process D (tau 4345ms) started using the CPU for 6872ms burst [Q C]
time 128013ms: Process B (tau 5338ms) completed I/O; added to ready queue [Q B C]
time 134819ms: Process D (tau 4345ms) completed a CPU burst; 25 bursts to go [Q B C]
