<<< PROJECT PART I -- process set (n=26) with 3 CPU-bound processes >>>
I/O-bound process A: arrival time 13ms; 17 CPU bursts
I/O-bound process B: arrival time 326ms; 26 CPU bursts
I/O-bound process C: arrival time 17ms; 40 CPU bursts
I/O-bound process D: arrival time 77ms; 38 CPU bursts
I/O-bound process E: arrival time 127ms; 6 CPU bursts
I/O-bound process F: arrival time 42ms; 19 CPU bursts
I/O-bound process G: arrival time 29ms; 30 CPU bursts
I/O-bound process H: arrival time 9ms; 58 CPU bursts
I/O-bound process I: arrival time 48ms; 40 CPU bursts
I/O-bound process J: arrival time 197ms; 20 CPU bursts
I/O-bound process K: arrival time 62ms; 57 CPU bursts
I/O-bound process L: arrival time 166ms; 31 CPU bursts
I/O-bound process M: arrival time 406ms; 24 CPU bursts
I/O-bound process N: arrival time 6ms; 7 CPU bursts
I/O-bound process O: arrival time 222ms; 2 CPU bursts
I/O-bound process P: arrival time 2ms; 36 CPU bursts
I/O-bound process Q: arrival time 71ms; 41 CPU bursts
I/O-bound process R: arrival time 158ms; 4 CPU bursts
I/O-bound process S: arrival time 162ms; 56 CPU bursts
I/O-bound process T: arrival time 138ms; 47 CPU bursts
I/O-bound process U: arrival time 27ms; 34 CPU bursts
I/O-bound process V: arrival time 93ms; 58 CPU bursts
I/O-bound process W: arrival time 81ms; 46 CPU bursts
CPU-bound process X: arrival time 18ms; 59 CPU bursts
CPU-bound process Y: arrival time 169ms; 36 CPU bursts
CPU-bound process Z: arrival time 279ms; 40 CPU bursts

<<< PROJECT PART II -- t_cs=2ms; alpha=0.91; t_slice=32ms >>>
time 0ms: Simulator started for FCFS [Q <empty>]
time 2ms: Process P arrived; added to ready queue [Q P]
time 3ms: Process P started using the CPU for 153ms burst [Q <empty>]
time 6ms: Process N arrived; added to ready queue [Q N]
time 9ms: Process H arrived; added to ready queue [Q N H]
time 13ms: Process A arrived; added to ready queue [Q N H A]
time 17ms: Process C arrived; added to ready queue [Q N H A C]
time 18ms: Process X arrived; added to ready queue [Q N H A C X]
time 27ms: Process U arrived; added to ready queue [Q N H A C X U]
time 29ms: Process G arrived; added to ready queue [Q N H A C X U G]
time 42ms: Process F arrived; added to ready queue [Q N H A C X U G F]
time 48ms: Process I arrived; added to ready queue [Q N H A C X U G F I]
time 62ms: Process K arrived; added to ready queue [Q N H A C X U G F I K]
time 71ms: Process Q arrived; added to ready queue [Q N H A C X U G F I K Q]
time 77ms: Process D arrived; added to ready queue [Q N H A C X U G F I K Q D]
time 81ms: Process W arrived; added to ready queue [Q N H A C X U G F I K Q D W]
time 93ms: Process V arrived; added to ready queue [Q N H A C X U G F I K Q D W V]
time 127ms: Process E arrived; added to ready queue [Q N H A C X U G F I K Q D W V E]
time 138ms: Process T arrived; added to ready queue [Q N H A C X U G F I K Q D W V E T]
time 156ms: Process P completed a CPU burst; 35 bursts to go [Q N H A C X U G F I K Q D W V E T]
time 156ms: Process P switching out of CPU; blocking on I/O until time 487ms [Q N H A C X U G F I K Q D W V E T]
time 158ms: Process N started using the CPU for 55ms burst [Q H A C X U G F I K Q D W V E T]
time 158ms: Process R arrived; added to ready queue [Q H A C X U G F I K Q D W V E T R]
time 162ms: Process S arrived; added to ready queue [Q H A C X U G F I K Q D W V E T R S]
time 166ms: Process L arrived; added to ready queue [Q H A C X U G F I K Q D W V E T R S L]
time 169ms: Process Y arrived; added to ready queue [Q H A C X U G F I K Q D W V E T R S L Y]
time 197ms: Process J arrived; added to ready queue [Q H A C X U G F I K Q D W V E T R S L Y J]
time 213ms: Process N completed a CPU burst; 6 bursts to go [Q H A C X U G F I K Q D W V E T R S L Y J]
time 213ms: Process N switching out of CPU; blocking on I/O until time 1064ms [Q H A C X U G F I K Q D W V E T R S L Y J]
time 215ms: Process H started using the CPU for 17ms burst [Q A C X U G F I K Q D W V E T R S L Y J]
time 222ms: Process O arrived; added to ready queue [Q A C X U G F I K Q D W V E T R S L Y J O]
time 232ms: Process H completed a CPU burst; 57 bursts to go [Q A C X U G F I K Q D W V E T R S L Y J O]
time 232ms: Process H switching out of CPU; blocking on I/O until time 363ms [Q A C X U G F I K Q D W V E T R S L Y J O]
time 234ms: Process A started using the CPU for 133ms burst [Q C X U G F I K Q D W V E T R S L Y J O]
time 279ms: Process Z arrived; added to ready queue [Q C X U G F I K Q D W V E T R S L Y J O Z]
time 326ms: Process B arrived; added to ready queue [Q C X U G F I K Q D W V E T R S L Y J O Z B]
time 363ms: Process H completed I/O; added to ready queue [Q C X U G F I K Q D W V E T R S L Y J O Z B H]
time 367ms: Process A completed a CPU burst; 16 bursts to go [Q C X U G F I K Q D W V E T R S L Y J O Z B H]
time 367ms: Process A switching out of CPU; blocking on I/O until time 948ms [Q C X U G F I K Q D W V E T R S L Y J O Z B H]
time 369ms: Process C started using the CPU for 80ms burst [Q X U G F I K Q D W V E T R S L Y J O Z B H]
time 406ms: Process M arrived; added to ready queue [Q X U G F I K Q D W V E T R S L Y J O Z B H M]
time 449ms: Process C completed a CPU burst; 39 bursts to go [Q X U G F I K Q D W V E T R S L Y J O Z B H M]
time 449ms: Process C switching out of CPU; blocking on I/O until time 810ms [Q X U G F I K Q D W V E T R S L Y J O Z B H M]
time 451ms: Process X started using the CPU for 48ms burst [Q U G F I K Q D W V E T R S L Y J O Z B H M]
time 487ms: Process P completed I/O; added to ready queue [Q U G F I K Q D W V E T R S L Y J O Z B H M P]
time 499ms: Process X completed a CPU burst; 58 bursts to go [Q U G F I K Q D W V E T R S L Y J O Z B H M P]
time 499ms: Process X switching out of CPU; blocking on I/O until time 550ms [Q U G F I K Q D W V E T R S L Y J O Z B H M P]
time 501ms: Process U started using the CPU for 70ms burst [Q G F I K Q D W V E T R S L Y J O Z B H M P]
time 550ms: Process X completed I/O; added to ready queue [Q G F I K Q D W V E T R S L Y J O Z B H M P X]
time 571ms: Process U completed a CPU burst; 33 bursts to go [Q G F I K Q D W V E T R S L Y J O Z B H M P X]
time 571ms: Process U switching out of CPU; blocking on I/O until time 672ms [Q G F I K Q D W V E T R S L Y J O Z B H M P X]
time 573ms: Process G started using the CPU for 38ms burst [Q F I K Q D W V E T R S L Y J O Z B H M P X]
time 611ms: Process G completed a CPU burst; 29 bursts to go [Q F I K Q D W V E T R S L Y J O Z B H M P X]
time 611ms: Process G switching out of CPU; blocking on I/O until time 2782ms [Q F I K Q D W V E T R S L Y J O Z B H M P X]
time 613ms: Process F started using the CPU for 167ms burst [Q I K Q D W V E T R S L Y J O Z B H M P X]
time 672ms: Process U completed I/O; added to ready queue [Q I K Q D W V E T R S L Y J O Z B H M P X U]
time 780ms: Process F completed a CPU burst; 18 bursts to go [Q I K Q D W V E T R S L Y J O Z B H M P X U]
time 780ms: Process F switching out of CPU; blocking on I/O until time 1481ms [Q I K Q D W V E T R S L Y J O Z B H M P X U]
time 782ms: Process I started using the CPU for 19ms burst [Q K Q D W V E T R S L Y J O Z B H M P X U]
time 801ms: Process I completed a CPU burst; 39 bursts to go [Q K Q D W V E T R S L Y J O Z B H M P X U]
time 801ms: Process I switching out of CPU; blocking on I/O until time 3672ms [Q K Q D W V E T R S L Y J O Z B H M P X U]
time 803ms: Process K started using the CPU for 52ms burst [Q Q D W V E T R S L Y J O Z B H M P X U]
time 810ms: Process C completed I/O; added to ready queue [Q Q D W V E T R S L Y J O Z B H M P X U C]
time 855ms: Process K completed a CPU burst; 56 bursts to go [Q Q D W V E T R S L Y J O Z B H M P X U C]
time 855ms: Process K switching out of CPU; blocking on I/O until time 1446ms [Q Q D W V E T R S L Y J O Z B H M P X U C]
time 857ms: Process Q started using the CPU for 41ms burst [Q D W V E T R S L Y J O Z B H M P X U C]
time 898ms: Process Q completed a CPU burst; 40 bursts to go [Q D W V E T R S L Y J O Z B H M P X U C]
time 898ms: Process Q switching out of CPU; blocking on I/O until time 1829ms [Q D W V E T R S L Y J O Z B H M P X U C]
time 900ms: Process D started using the CPU for 48ms burst [Q W V E T R S L Y J O Z B H M P X U C]
time 948ms: Process D completed a CPU burst; 37 bursts to go [Q W V E T R S L Y J O Z B H M P X U C]
time 948ms: Process D switching out of CPU; blocking on I/O until time 1529ms [Q W V E T R S L Y J O Z B H M P X U C]
time 948ms: Process A completed I/O; added to ready queue [Q W V E T R S L Y J O Z B H M P X U C A]
time 950ms: Process W started using the CPU for 9ms burst [Q V E T R S L Y J O Z B H M P X U C A]
time 959ms: Process W completed a CPU burst; 45 bursts to go [Q V E T R S L Y J O Z B H M P X U C A]
time 959ms: Process W switching out of CPU; blocking on I/O until time 1570ms [Q V E T R S L Y J O Z B H M P X U C A]
time 961ms: Process V started using the CPU for 127ms burst [Q E T R S L Y J O Z B H M P X U C A]
time 1064ms: Process N completed I/O; added to ready queue [Q E T R S L Y J O Z B H M P X U C A N]
time 1088ms: Process V completed a CPU burst; 57 bursts to go [Q E T R S L Y J O Z B H M P X U C A N]
time 1088ms: Process V switching out of CPU; blocking on I/O until time 2749ms [Q E T R S L Y J O Z B H M P X U C A N]
time 1090ms: Process E started using the CPU for 95ms burst [Q T R S L Y J O Z B H M P X U C A N]
time 1185ms: Process E completed a CPU burst; 5 bursts to go [Q T R S L Y J O Z B H M P X U C A N]
time 1185ms: Process E switching out of CPU; blocking on I/O until time 1336ms [Q T R S L Y J O Z B H M P X U C A N]
time 1187ms: Process T started using the CPU for 66ms burst [Q R S L Y J O Z B H M P X U C A N]
time 1253ms: Process T completed a CPU burst; 46 bursts to go [Q R S L Y J O Z B H M P X U C A N]
time 1253ms: Process T switching out of CPU; blocking on I/O until time 1894ms [Q R S L Y J O Z B H M P X U C A N]
time 1255ms: Process R started using the CPU for 47ms burst [Q S L Y J O Z B H M P X U C A N]
time 1302ms: Process R completed a CPU burst; 3 bursts to go [Q S L Y J O Z B H M P X U C A N]
time 1302ms: Process R switching out of CPU; blocking on I/O until time 2683ms [Q S L Y J O Z B H M P X U C A N]
time 1304ms: Process S started using the CPU for 13ms burst [Q L Y J O Z B H M P X U C A N]
time 1317ms: Process S completed a CPU burst; 55 bursts to go [Q L Y J O Z B H M P X U C A N]
time 1317ms: Process S switching out of CPU; blocking on I/O until time 1328ms [Q L Y J O Z B H M P X U C A N]
time 1319ms: Process L started using the CPU for 206ms burst [Q Y J O Z B H M P X U C A N]
time 1328ms: Process S completed I/O; added to ready queue [Q Y J O Z B H M P X U C A N S]
time 1336ms: Process E completed I/O; added to ready queue [Q Y J O Z B H M P X U C A N S E]
time 1446ms: Process K completed I/O; added to ready queue [Q Y J O Z B H M P X U C A N S E K]
time 1481ms: Process F completed I/O; added to ready queue [Q Y J O Z B H M P X U C A N S E K F]
time 1525ms: Process L completed a CPU burst; 30 bursts to go [Q Y J O Z B H M P X U C A N S E K F]
time 1525ms: Process L switching out of CPU; blocking on I/O until time 2826ms [Q Y J O Z B H M P X U C A N S E K F]
time 1527ms: Process Y started using the CPU for 248ms burst [Q J O Z B H M P X U C A N S E K F]
time 1529ms: Process D completed I/O; added to ready queue [Q J O Z B H M P X U C A N S E K F D]
time 1570ms: Process W completed I/O; added to ready queue [Q J O Z B H M P X U C A N S E K F D W]
time 1775ms: Process Y completed a CPU burst; 35 bursts to go [Q J O Z B H M P X U C A N S E K F D W]
time 1775ms: Process Y switching out of CPU; blocking on I/O until time 1843ms [Q J O Z B H M P X U C A N S E K F D W]
time 1777ms: Process J started using the CPU for 131ms burst [Q O Z B H M P X U C A N S E K F D W]
time 1829ms: Process Q completed I/O; added to ready queue [Q O Z B H M P X U C A N S E K F D W Q]
time 1843ms: Process Y completed I/O; added to ready queue [Q O Z B H M P X U C A N S E K F D W Q Y]
time 1894ms: Process T completed I/O; added to ready queue [Q O Z B H M P X U C A N S E K F D W Q Y T]
time 1908ms: Process J completed a CPU burst; 19 bursts to go [Q O Z B H M P X U C A N S E K F D W Q Y T]
time 1908ms: Process J switching out of CPU; blocking on I/O until time 1949ms [Q O Z B H M P X U C A N S E K F D W Q Y T]
time 1910ms: Process O started using the CPU for 29ms burst [Q Z B H M P X U C A N S E K F D W Q Y T]
time 1939ms: Process O completed a CPU burst; 1 burst to go [Q Z B H M P X U C A N S E K F D W Q Y T]
time 1939ms: Process O switching out of CPU; blocking on I/O until time 2520ms [Q Z B H M P X U C A N S E K F D W Q Y T]
time 1941ms: Process Z started using the CPU for 328ms burst [Q B H M P X U C A N S E K F D W Q Y T]
time 1949ms: Process J completed I/O; added to ready queue [Q B H M P X U C A N S E K F D W Q Y T J]
time 2269ms: Process Z completed a CPU burst; 39 bursts to go [Q B H M P X U C A N S E K F D W Q Y T J]
time 2269ms: Process Z switching out of CPU; blocking on I/O until time 2517ms [Q B H M P X U C A N S E K F D W Q Y T J]
time 2271ms: Process B started using the CPU for 168ms burst [Q H M P X U C A N S E K F D W Q Y T J]
time 2439ms: Process B completed a CPU burst; 25 bursts to go [Q H M P X U C A N S E K F D W Q Y T J]
time 2439ms: Process B switching out of CPU; blocking on I/O until time 4880ms [Q H M P X U C A N S E K F D W Q Y T J]
time 2441ms: Process H started using the CPU for 33ms burst [Q M P X U C A N S E K F D W Q Y T J]
time 2474ms: Process H completed a CPU burst; 56 bursts to go [Q M P X U C A N S E K F D W Q Y T J]
time 2474ms: Process H switching out of CPU; blocking on I/O until time 3585ms [Q M P X U C A N S E K F D W Q Y T J]
time 2476ms: Process M started using the CPU for 181ms burst [Q P X U C A N S E K F D W Q Y T J]
time 2517ms: Process Z completed I/O; added to ready queue [Q P X U C A N S E K F D W Q Y T J Z]
time 2520ms: Process O completed I/O; added to ready queue [Q P X U C A N S E K F D W Q Y T J Z O]
time 2657ms: Process M completed a CPU burst; 23 bursts to go [Q P X U C A N S E K F D W Q Y T J Z O]
time 2657ms: Process M switching out of CPU; blocking on I/O until time 4658ms [Q P X U C A N S E K F D W Q Y T J Z O]
time 2659ms: Process P started using the CPU for 277ms burst [Q X U C A N S E K F D W Q Y T J Z O]
time 2683ms: Process R completed I/O; added to ready queue [Q X U C A N S E K F D W Q Y T J Z O R]
time 2749ms: Process V completed I/O; added to ready queue [Q X U C A N S E K F D W Q Y T J Z O R V]
time 2782ms: Process G completed I/O; added to ready queue [Q X U C A N S E K F D W Q Y T J Z O R V G]
time 2826ms: Process L completed I/O; added to ready queue [Q X U C A N S E K F D W Q Y T J Z O R V G L]
time 2936ms: Process P completed a CPU burst; 34 bursts to go [Q X U C A N S E K F D W Q Y T J Z O R V G L]
time 2936ms: Process P switching out of CPU; blocking on I/O until time 3027ms [Q X U C A N S E K F D W Q Y T J Z O R V G L]
time 2938ms: Process X started using the CPU for 620ms burst [Q U C A N S E K F D W Q Y T J Z O R V G L]
time 3027ms: Process P completed I/O; added to ready queue [Q U C A N S E K F D W Q Y T J Z O R V G L P]
time 3558ms: Process X completed a CPU burst; 57 bursts to go [Q U C A N S E K F D W Q Y T J Z O R V G L P]
time 3558ms: Process X switching out of CPU; blocking on I/O until time 3597ms [Q U C A N S E K F D W Q Y T J Z O R V G L P]
time 3560ms: Process U started using the CPU for 80ms burst [Q C A N S E K F D W Q Y T J Z O R V G L P]
time 3585ms: Process H completed I/O; added to ready queue [Q C A N S E K F D W Q Y T J Z O R V G L P H]
time 3597ms: Process X completed I/O; added to ready queue [Q C A N S E K F D W Q Y T J Z O R V G L P H X]
time 3640ms: Process U completed a CPU burst; 32 bursts to go [Q C A N S E K F D W Q Y T J Z O R V G L P H X]
time 3640ms: Process U switching out of CPU; blocking on I/O until time 4811ms [Q C A N S E K F D W Q Y T J Z O R V G L P H X]
time 3642ms: Process C started using the CPU for 194ms burst [Q A N S E K F D W Q Y T J Z O R V G L P H X]
time 3672ms: Process I completed I/O; added to ready queue [Q A N S E K F D W Q Y T J Z O R V G L P H X I]
time 3836ms: Process C completed a CPU burst; 38 bursts to go [Q A N S E K F D W Q Y T J Z O R V G L P H X I]
time 3836ms: Process C switching out of CPU; blocking on I/O until time 4497ms [Q A N S E K F D W Q Y T J Z O R V G L P H X I]
time 3838ms: Process A started using the CPU for 74ms burst [Q N S E K F D W Q Y T J Z O R V G L P H X I]
time 3912ms: Process A completed a CPU burst; 15 bursts to go [Q N S E K F D W Q Y T J Z O R V G L P H X I]
time 3912ms: Process A switching out of CPU; blocking on I/O until time 3983ms [Q N S E K F D W Q Y T J Z O R V G L P H X I]
time 3914ms: Process N started using the CPU for 192ms burst [Q S E K F D W Q Y T J Z O R V G L P H X I]
time 3983ms: Process A completed I/O; added to ready queue [Q S E K F D W Q Y T J Z O R V G L P H X I A]
time 4106ms: Process N completed a CPU burst; 5 bursts to go [Q S E K F D W Q Y T J Z O R V G L P H X I A]
time 4106ms: Process N switching out of CPU; blocking on I/O until time 4347ms [Q S E K F D W Q Y T J Z O R V G L P H X I A]
time 4108ms: Process S started using the CPU for 114ms burst [Q E K F D W Q Y T J Z O R V G L P H X I A]
time 4222ms: Process S completed a CPU burst; 54 bursts to go [Q E K F D W Q Y T J Z O R V G L P H X I A]
time 4222ms: Process S switching out of CPU; blocking on I/O until time 5103ms [Q E K F D W Q Y T J Z O R V G L P H X I A]
time 4224ms: Process E started using the CPU for 155ms burst [Q K F D W Q Y T J Z O R V G L P H X I A]
time 4347ms: Process N completed I/O; added to ready queue [Q K F D W Q Y T J Z O R V G L P H X I A N]
time 4379ms: Process E completed a CPU burst; 4 bursts to go [Q K F D W Q Y T J Z O R V G L P H X I A N]
time 4379ms: Process E switching out of CPU; blocking on I/O until time 4540ms [Q K F D W Q Y T J Z O R V G L P H X I A N]
time 4381ms: Process K started using the CPU for 27ms burst [Q F D W Q Y T J Z O R V G L P H X I A N]
time 4408ms: Process K completed a CPU burst; 55 bursts to go [Q F D W Q Y T J Z O R V G L P H X I A N]
time 4408ms: Process K switching out of CPU; blocking on I/O until time 4979ms [Q F D W Q Y T J Z O R V G L P H X I A N]
time 4410ms: Process F started using the CPU for 160ms burst [Q D W Q Y T J Z O R V G L P H X I A N]
time 4497ms: Process C completed I/O; added to ready queue [Q D W Q Y T J Z O R V G L P H X I A N C]
time 4540ms: Process E completed I/O; added to ready queue [Q D W Q Y T J Z O R V G L P H X I A N C E]
time 4570ms: Process F completed a CPU burst; 17 bursts to go [Q D W Q Y T J Z O R V G L P H X I A N C E]
time 4570ms: Process F switching out of CPU; blocking on I/O until time 5841ms [Q D W Q Y T J Z O R V G L P H X I A N C E]
time 4572ms: Process D started using the CPU for 138ms burst [Q W Q Y T J Z O R V G L P H X I A N C E]
time 4658ms: Process M completed I/O; added to ready queue [Q W Q Y T J Z O R V G L P H X I A N C E M]
time 4710ms: Process D completed a CPU burst; 36 bursts to go [Q W Q Y T J Z O R V G L P H X I A N C E M]
time 4710ms: Process D switching out of CPU; blocking on I/O until time 6851ms [Q W Q Y T J Z O R V G L P H X I A N C E M]
time 4712ms: Process W started using the CPU for 75ms burst [Q Q Y T J Z O R V G L P H X I A N C E M]
time 4787ms: Process W completed a CPU burst; 44 bursts to go [Q Q Y T J Z O R V G L P H X I A N C E M]
time 4787ms: Process W switching out of CPU; blocking on I/O until time 4948ms [Q Q Y T J Z O R V G L P H X I A N C E M]
time 4789ms: Process Q started using the CPU for 284ms burst [Q Y T J Z O R V G L P H X I A N C E M]
time 4811ms: Process U completed I/O; added to ready queue [Q Y T J Z O R V G L P H X I A N C E M U]
time 4880ms: Process B completed I/O; added to ready queue [Q Y T J Z O R V G L P H X I A N C E M U B]
time 4948ms: Process W completed I/O; added to ready queue [Q Y T J Z O R V G L P H X I A N C E M U B W]
time 4979ms: Process K completed I/O; added to ready queue [Q Y T J Z O R V G L P H X I A N C E M U B W K]
time 5073ms: Process Q completed a CPU burst; 39 bursts to go [Q Y T J Z O R V G L P H X I A N C E M U B W K]
time 5073ms: Process Q switching out of CPU; blocking on I/O until time 5464ms [Q Y T J Z O R V G L P H X I A N C E M U B W K]
time 5075ms: Process Y started using the CPU for 924ms burst [Q T J Z O R V G L P H X I A N C E M U B W K]
time 5103ms: Process S completed I/O; added to ready queue [Q T J Z O R V G L P H X I A N C E M U B W K S]
time 5464ms: Process Q completed I/O; added to ready queue [Q T J Z O R V G L P H X I A N C E M U B W K S Q]
time 5841ms: Process F completed I/O; added to ready queue [Q T J Z O R V G L P H X I A N C E M U B W K S Q F]
time 5999ms: Process Y completed a CPU burst; 34 bursts to go [Q T J Z O R V G L P H X I A N C E M U B W K S Q F]
time 5999ms: Process Y switching out of CPU; blocking on I/O until time 6060ms [Q T J Z O R V G L P H X I A N C E M U B W K S Q F]
time 6001ms: Process T started using the CPU for 248ms burst [Q J Z O R V G L P H X I A N C E M U B W K S Q F]
time 6060ms: Process Y completed I/O; added to ready queue [Q J Z O R V G L P H X I A N C E M U B W K S Q F Y]
time 6249ms: Process T completed a CPU burst; 45 bursts to go [Q J Z O R V G L P H X I A N C E M U B W K S Q F Y]
time 6249ms: Process T switching out of CPU; blocking on I/O until time 6410ms [Q J Z O R V G L P H X I A N C E M U B W K S Q F Y]
time 6251ms: Process J started using the CPU for 34ms burst [Q Z O R V G L P H X I A N C E M U B W K S Q F Y]
time 6285ms: Process J completed a CPU burst; 18 bursts to go [Q Z O R V G L P H X I A N C E M U B W K S Q F Y]
time 6285ms: Process J switching out of CPU; blocking on I/O until time 7066ms [Q Z O R V G L P H X I A N C E M U B W K S Q F Y]
time 6287ms: Process Z started using the CPU for 16ms burst [Q O R V G L P H X I A N C E M U B W K S Q F Y]
time 6303ms: Process Z completed a CPU burst; 38 bursts to go [Q O R V G L P H X I A N C E M U B W K S Q F Y]
time 6303ms: Process Z switching out of CPU; blocking on I/O until time 6767ms [Q O R V G L P H X I A N C E M U B W K S Q F Y]
time 6305ms: Process O started using the CPU for 132ms burst [Q R V G L P H X I A N C E M U B W K S Q F Y]
time 6410ms: Process T completed I/O; added to ready queue [Q R V G L P H X I A N C E M U B W K S Q F Y T]
time 6437ms: Process O completed a CPU burst; 0 burst to go [Q R V G L P H X I A N C E M U B W K S Q F Y T]
time 6437ms: Process O terminated [Q R V G L P H X I A N C E M U B W K S Q F Y T]
time 6439ms: Process R started using the CPU for 71ms burst [Q V G L P H X I A N C E M U B W K S Q F Y T]
time 6510ms: Process R completed a CPU burst; 2 bursts to go [Q V G L P H X I A N C E M U B W K S Q F Y T]
time 6510ms: Process R switching out of CPU; blocking on I/O until time 7941ms [Q V G L P H X I A N C E M U B W K S Q F Y T]
time 6512ms: Process V started using the CPU for 35ms burst [Q G L P H X I A N C E M U B W K S Q F Y T]
time 6547ms: Process V completed a CPU burst; 56 bursts to go [Q G L P H X I A N C E M U B W K S Q F Y T]
time 6547ms: Process V switching out of CPU; blocking on I/O until time 7748ms [Q G L P H X I A N C E M U B W K S Q F Y T]
time 6549ms: Process G started using the CPU for 34ms burst [Q L P H X I A N C E M U B W K S Q F Y T]
time 6583ms: Process G completed a CPU burst; 28 bursts to go [Q L P H X I A N C E M U B W K S Q F Y T]
time 6583ms: Process G switching out of CPU; blocking on I/O until time 6814ms [Q L P H X I A N C E M U B W K S Q F Y T]
time 6585ms: Process L started using the CPU for 10ms burst [Q P H X I A N C E M U B W K S Q F Y T]
time 6595ms: Process L completed a CPU burst; 29 bursts to go [Q P H X I A N C E M U B W K S Q F Y T]
time 6595ms: Process L switching out of CPU; blocking on I/O until time 7276ms [Q P H X I A N C E M U B W K S Q F Y T]
time 6597ms: Process P started using the CPU for 123ms burst [Q H X I A N C E M U B W K S Q F Y T]
time 6720ms: Process P completed a CPU burst; 33 bursts to go [Q H X I A N C E M U B W K S Q F Y T]
time 6720ms: Process P switching out of CPU; blocking on I/O until time 8521ms [Q H X I A N C E M U B W K S Q F Y T]
time 6722ms: Process H started using the CPU for 29ms burst [Q X I A N C E M U B W K S Q F Y T]
time 6751ms: Process H completed a CPU burst; 55 bursts to go [Q X I A N C E M U B W K S Q F Y T]
time 6751ms: Process H switching out of CPU; blocking on I/O until time 7952ms [Q X I A N C E M U B W K S Q F Y T]
time 6753ms: Process X started using the CPU for 1544ms burst [Q I A N C E M U B W K S Q F Y T]
time 6767ms: Process Z completed I/O; added to ready queue [Q I A N C E M U B W K S Q F Y T Z]
time 6814ms: Process G completed I/O; added to ready queue [Q I A N C E M U B W K S Q F Y T Z G]
time 6851ms: Process D completed I/O; added to ready queue [Q I A N C E M U B W K S Q F Y T Z G D]
time 7066ms: Process J completed I/O; added to ready queue [Q I A N C E M U B W K S Q F Y T Z G D J]
time 7276ms: Process L completed I/O; added to ready queue [Q I A N C E M U B W K S Q F Y T Z G D J L]
time 7748ms: Process V completed I/O; added to ready queue [Q I A N C E M U B W K S Q F Y T Z G D J L V]
time 7941ms: Process R completed I/O; added to ready queue [Q I A N C E M U B W K S Q F Y T Z G D J L V R]
time 7952ms: Process H completed I/O; added to ready queue [Q I A N C E M U B W K S Q F Y T Z G D J L V R H]
time 8297ms: Process X completed a CPU burst; 56 bursts to go [Q I A N C E M U B W K S Q F Y T Z G D J L V R H]
time 8297ms: Process X switching out of CPU; blocking on I/O until time 8319ms [Q I A N C E M U B W K S Q F Y T Z G D J L V R H]
time 8299ms: Process I started using the CPU for 9ms burst [Q A N C E M U B W K S Q F Y T Z G D J L V R H]
time 8308ms: Process I completed a CPU burst; 38 bursts to go [Q A N C E M U B W K S Q F Y T Z G D J L V R H]
time 8308ms: Process I switching out of CPU; blocking on I/O until time 8589ms [Q A N C E M U B W K S Q F Y T Z G D J L V R H]
time 8310ms: Process A started using the CPU for 3ms burst [Q N C E M U B W K S Q F Y T Z G D J L V R H]
time 8313ms: Process A completed a CPU burst; 14 bursts to go [Q N C E M U B W K S Q F Y T Z G D J L V R H]
time 8313ms: Process A switching out of CPU; blocking on I/O until time 8364ms [Q N C E M U B W K S Q F Y T Z G D J L V R H]
time 8315ms: Process N started using the CPU for 53ms burst [Q C E M U B W K S Q F Y T Z G D J L V R H]
time 8319ms: Process X completed I/O; added to ready queue [Q C E M U B W K S Q F Y T Z G D J L V R H X]
time 8364ms: Process A completed I/O; added to ready queue [Q C E M U B W K S Q F Y T Z G D J L V R H X A]
time 8368ms: Process N completed a CPU burst; 4 bursts to go [Q C E M U B W K S Q F Y T Z G D J L V R H X A]
time 8368ms: Process N switching out of CPU; blocking on I/O until time 8389ms [Q C E M U B W K S Q F Y T Z G D J L V R H X A]
time 8370ms: Process C started using the CPU for 91ms burst [Q E M U B W K S Q F Y T Z G D J L V R H X A]
time 8389ms: Process N completed I/O; added to ready queue [Q E M U B W K S Q F Y T Z G D J L V R H X A N]
time 8461ms: Process C completed a CPU burst; 37 bursts to go [Q E M U B W K S Q F Y T Z G D J L V R H X A N]
time 8461ms: Process C switching out of CPU; blocking on I/O until time 8512ms [Q E M U B W K S Q F Y T Z G D J L V R H X A N]
time 8463ms: Process E started using the CPU for 3ms burst [Q M U B W K S Q F Y T Z G D J L V R H X A N]
time 8466ms: Process E completed a CPU burst; 3 bursts to go [Q M U B W K S Q F Y T Z G D J L V R H X A N]
time 8466ms: Process E switching out of CPU; blocking on I/O until time 8547ms [Q M U B W K S Q F Y T Z G D J L V R H X A N]
time 8468ms: Process M started using the CPU for 55ms burst [Q U B W K S Q F Y T Z G D J L V R H X A N]
time 8512ms: Process C completed I/O; added to ready queue [Q U B W K S Q F Y T Z G D J L V R H X A N C]
time 8521ms: Process P completed I/O; added to ready queue [Q U B W K S Q F Y T Z G D J L V R H X A N C P]
time 8523ms: Process M completed a CPU burst; 22 bursts to go [Q U B W K S Q F Y T Z G D J L V R H X A N C P]
time 8523ms: Process M switching out of CPU; blocking on I/O until time 9284ms [Q U B W K S Q F Y T Z G D J L V R H X A N C P]
time 8525ms: Process U started using the CPU for 51ms burst [Q B W K S Q F Y T Z G D J L V R H X A N C P]
time 8547ms: Process E completed I/O; added to ready queue [Q B W K S Q F Y T Z G D J L V R H X A N C P E]
time 8576ms: Process U completed a CPU burst; 31 bursts to go [Q B W K S Q F Y T Z G D J L V R H X A N C P E]
time 8576ms: Process U switching out of CPU; blocking on I/O until time 8647ms [Q B W K S Q F Y T Z G D J L V R H X A N C P E]
time 8578ms: Process B started using the CPU for 9ms burst [Q W K S Q F Y T Z G D J L V R H X A N C P E]
time 8587ms: Process B completed a CPU burst; 24 bursts to go [Q W K S Q F Y T Z G D J L V R H X A N C P E]
time 8587ms: Process B switching out of CPU; blocking on I/O until time 9768ms [Q W K S Q F Y T Z G D J L V R H X A N C P E]
time 8589ms: Process W started using the CPU for 55ms burst [Q K S Q F Y T Z G D J L V R H X A N C P E]
time 8589ms: Process I completed I/O; added to ready queue [Q K S Q F Y T Z G D J L V R H X A N C P E I]
time 8644ms: Process W completed a CPU burst; 43 bursts to go [Q K S Q F Y T Z G D J L V R H X A N C P E I]
time 8644ms: Process W switching out of CPU; blocking on I/O until time 9045ms [Q K S Q F Y T Z G D J L V R H X A N C P E I]
time 8646ms: Process K started using the CPU for 29ms burst [Q S Q F Y T Z G D J L V R H X A N C P E I]
time 8647ms: Process U completed I/O; added to ready queue [Q S Q F Y T Z G D J L V R H X A N C P E I U]
time 8675ms: Process K completed a CPU burst; 54 bursts to go [Q S Q F Y T Z G D J L V R H X A N C P E I U]
time 8675ms: Process K switching out of CPU; blocking on I/O until time 9416ms [Q S Q F Y T Z G D J L V R H X A N C P E I U]
time 8677ms: Process S started using the CPU for 157ms burst [Q Q F Y T Z G D J L V R H X A N C P E I U]
time 8834ms: Process S completed a CPU burst; 53 bursts to go [Q Q F Y T Z G D J L V R H X A N C P E I U]
time 8834ms: Process S switching out of CPU; blocking on I/O until time 9645ms [Q Q F Y T Z G D J L V R H X A N C P E I U]
time 8836ms: Process Q started using the CPU for 595ms burst [Q F Y T Z G D J L V R H X A N C P E I U]
time 9045ms: Process W completed I/O; added to ready queue [Q F Y T Z G D J L V R H X A N C P E I U W]
time 9284ms: Process M completed I/O; added to ready queue [Q F Y T Z G D J L V R H X A N C P E I U W M]
time 9416ms: Process K completed I/O; added to ready queue [Q F Y T Z G D J L V R H X A N C P E I U W M K]
time 9431ms: Process Q completed a CPU burst; 38 bursts to go [Q F Y T Z G D J L V R H X A N C P E I U W M K]
time 9431ms: Process Q switching out of CPU; blocking on I/O until time 10592ms [Q F Y T Z G D J L V R H X A N C P E I U W M K]
time 9433ms: Process F started using the CPU for 87ms burst [Q Y T Z G D J L V R H X A N C P E I U W M K]
time 9520ms: Process F completed a CPU burst; 16 bursts to go [Q Y T Z G D J L V R H X A N C P E I U W M K]
time 9520ms: Process F switching out of CPU; blocking on I/O until time 11771ms [Q Y T Z G D J L V R H X A N C P E I U W M K]
time 9522ms: Process Y started using the CPU for 680ms burst [Q T Z G D J L V R H X A N C P E I U W M K]
time 9645ms: Process S completed I/O; added to ready queue [Q T Z G D J L V R H X A N C P E I U W M K S]
time 9768ms: Process B completed I/O; added to ready queue [Q T Z G D J L V R H X A N C P E I U W M K S B]
time 10202ms: Process Y switching out of CPU; blocking on I/O until time 10664ms [Q T Z G D J L V R H X A N C P E I U W M K S B]
time 10204ms: Process T started using the CPU for 240ms burst [Q Z G D J L V R H X A N C P E I U W M K S B]
time 10444ms: Process T switching out of CPU; blocking on I/O until time 14225ms [Q Z G D J L V R H X A N C P E I U W M K S B]
time 10446ms: Process Z started using the CPU for 448ms burst [Q G D J L V R H X A N C P E I U W M K S B]
time 10592ms: Process Q completed I/O; added to ready queue [Q G D J L V R H X A N C P E I U W M K S B Q]
time 10664ms: Process Y completed I/O; added to ready queue [Q G D J L V R H X A N C P E I U W M K S B Q Y]
time 10894ms: Process Z switching out of CPU; blocking on I/O until time 11017ms [Q G D J L V R H X A N C P E I U W M K S B Q Y]
time 10896ms: Process G started using the CPU for 29ms burst [Q D J L V R H X A N C P E I U W M K S B Q Y]
time 10925ms: Process G switching out of CPU; blocking on I/O until time 11406ms [Q D J L V R H X A N C P E I U W M K S B Q Y]
time 10927ms: Process D started using the CPU for 84ms burst [Q J L V R H X A N C P E I U W M K S B Q Y]
time 11011ms: Process D switching out of CPU; blocking on I/O until time 11372ms [Q J L V R H X A N C P E I U W M K S B Q Y]
time 11013ms: Process J started using the CPU for 75ms burst [Q L V R H X A N C P E I U W M K S B Q Y]
time 11017ms: Process Z completed I/O; added to ready queue [Q L V R H X A N C P E I U W M K S B Q Y Z]
time 11088ms: Process J switching out of CPU; blocking on I/O until time 13219ms [Q L V R H X A N C P E I U W M K S B Q Y Z]
time 11090ms: Process L started using the CPU for 37ms burst [Q V R H X A N C P E I U W M K S B Q Y Z]
time 11127ms: Process L switching out of CPU; blocking on I/O until time 11698ms [Q V R H X A N C P E I U W M K S B Q Y Z]
time 11129ms: Process V started using the CPU for 18ms burst [Q R H X A N C P E I U W M K S B Q Y Z]
time 11147ms: Process V switching out of CPU; blocking on I/O until time 12178ms [Q R H X A N C P E I U W M K S B Q Y Z]
time 11149ms: Process R started using the CPU for 225ms burst [Q H X A N C P E I U W M K S B Q Y Z]
time 11372ms: Process D completed I/O; added to ready queue [Q H X A N C P E I U W M K S B Q Y Z D]
time 11374ms: Process R switching out of CPU; blocking on I/O until time 12335ms [Q H X A N C P E I U W M K S B Q Y Z D]
time 11376ms: Process H started using the CPU for 7ms burst [Q X A N C P E I U W M K S B Q Y Z D]
time 11383ms: Process H switching out of CPU; blocking on I/O until time 13724ms [Q X A N C P E I U W M K S B Q Y Z D]
time 11385ms: Process X started using the CPU for 108ms burst [Q A N C P E I U W M K S B Q Y Z D]
time 11406ms: Process G completed I/O; added to ready queue [Q A N C P E I U W M K S B Q Y Z D G]
time 11493ms: Process X switching out of CPU; blocking on I/O until time 11867ms [Q A N C P E I U W M K S B Q Y Z D G]
time 11495ms: Process A started using the CPU for 69ms burst [Q N C P E I U W M K S B Q Y Z D G]
time 11564ms: Process A switching out of CPU; blocking on I/O until time 11755ms [Q N C P E I U W M K S B Q Y Z D G]
time 11566ms: Process N started using the CPU for 16ms burst [Q C P E I U W M K S B Q Y Z D G]
time 11582ms: Process N switching out of CPU; blocking on I/O until time 11693ms [Q C P E I U W M K S B Q Y Z D G]
time 11584ms: Process C started using the CPU for 68ms burst [Q P E I U W M K S B Q Y Z D G]
time 11652ms: Process C switching out of CPU; blocking on I/O until time 11683ms [Q P E I U W M K S B Q Y Z D G]
time 11654ms: Process P started using the CPU for 276ms burst [Q E I U W M K S B Q Y Z D G]
time 11683ms: Process C completed I/O; added to ready queue [Q E I U W M K S B Q Y Z D G C]
time 11693ms: Process N completed I/O; added to ready queue [Q E I U W M K S B Q Y Z D G C N]
time 11698ms: Process L completed I/O; added to ready queue [Q E I U W M K S B Q Y Z D G C N L]
time 11755ms: Process A completed I/O; added to ready queue [Q E I U W M K S B Q Y Z D G C N L A]
time 11771ms: Process F completed I/O; added to ready queue [Q E I U W M K S B Q Y Z D G C N L A F]
time 11867ms: Process X completed I/O; added to ready queue [Q E I U W M K S B Q Y Z D G C N L A F X]
time 11930ms: Process P switching out of CPU; blocking on I/O until time 12331ms [Q E I U W M K S B Q Y Z D G C N L A F X]
time 11932ms: Process E started using the CPU for 91ms burst [Q I U W M K S B Q Y Z D G C N L A F X]
time 12023ms: Process E switching out of CPU; blocking on I/O until time 12874ms [Q I U W M K S B Q Y Z D G C N L A F X]
time 12025ms: Process I started using the CPU for 105ms burst [Q U W M K S B Q Y Z D G C N L A F X]
time 12130ms: Process I switching out of CPU; blocking on I/O until time 12501ms [Q U W M K S B Q Y Z D G C N L A F X]
time 12132ms: Process U started using the CPU for 157ms burst [Q W M K S B Q Y Z D G C N L A F X]
time 12178ms: Process V completed I/O; added to ready queue [Q W M K S B Q Y Z D G C N L A F X V]
time 12289ms: Process U switching out of CPU; blocking on I/O until time 12880ms [Q W M K S B Q Y Z D G C N L A F X V]
time 12291ms: Process W started using the CPU for 5ms burst [Q M K S B Q Y Z D G C N L A F X V]
time 12296ms: Process W switching out of CPU; blocking on I/O until time 13147ms [Q M K S B Q Y Z D G C N L A F X V]
time 12298ms: Process M started using the CPU for 60ms burst [Q K S B Q Y Z D G C N L A F X V]
time 12331ms: Process P completed I/O; added to ready queue [Q K S B Q Y Z D G C N L A F X V P]
time 12335ms: Process R completed I/O; added to ready queue [Q K S B Q Y Z D G C N L A F X V P R]
time 12358ms: Process M switching out of CPU; blocking on I/O until time 13629ms [Q K S B Q Y Z D G C N L A F X V P R]
time 12360ms: Process K started using the CPU for 67ms burst [Q S B Q Y Z D G C N L A F X V P R]
time 12427ms: Process K switching out of CPU; blocking on I/O until time 12458ms [Q S B Q Y Z D G C N L A F X V P R]
time 12429ms: Process S started using the CPU for 168ms burst [Q B Q Y Z D G C N L A F X V P R]
time 12458ms: Process K completed I/O; added to ready queue [Q B Q Y Z D G C N L A F X V P R K]
time 12501ms: Process I completed I/O; added to ready queue [Q B Q Y Z D G C N L A F X V P R K I]
time 12597ms: Process S switching out of CPU; blocking on I/O until time 13518ms [Q B Q Y Z D G C N L A F X V P R K I]
time 12599ms: Process B started using the CPU for 6ms burst [Q Q Y Z D G C N L A F X V P R K I]
time 12605ms: Process B switching out of CPU; blocking on I/O until time 13106ms [Q Q Y Z D G C N L A F X V P R K I]
time 12607ms: Process Q started using the CPU for 57ms burst [Q Y Z D G C N L A F X V P R K I]
time 12664ms: Process Q switching out of CPU; blocking on I/O until time 14295ms [Q Y Z D G C N L A F X V P R K I]
time 12666ms: Process Y started using the CPU for 168ms burst [Q Z D G C N L A F X V P R K I]
time 12834ms: Process Y switching out of CPU; blocking on I/O until time 12870ms [Q Z D G C N L A F X V P R K I]
time 12836ms: Process Z started using the CPU for 300ms burst [Q D G C N L A F X V P R K I]
time 12870ms: Process Y completed I/O; added to ready queue [Q D G C N L A F X V P R K I Y]
time 12874ms: Process E completed I/O; added to ready queue [Q D G C N L A F X V P R K I Y E]
time 12880ms: Process U completed I/O; added to ready queue [Q D G C N L A F X V P R K I Y E U]
time 13106ms: Process B completed I/O; added to ready queue [Q D G C N L A F X V P R K I Y E U B]
time 13136ms: Process Z switching out of CPU; blocking on I/O until time 13208ms [Q D G C N L A F X V P R K I Y E U B]
time 13138ms: Process D started using the CPU for 177ms burst [Q G C N L A F X V P R K I Y E U B]
time 13147ms: Process W completed I/O; added to ready queue [Q G C N L A F X V P R K I Y E U B W]
time 13208ms: Process Z completed I/O; added to ready queue [Q G C N L A F X V P R K I Y E U B W Z]
time 13219ms: Process J completed I/O; added to ready queue [Q G C N L A F X V P R K I Y E U B W Z J]
time 13315ms: Process D switching out of CPU; blocking on I/O until time 13946ms [Q G C N L A F X V P R K I Y E U B W Z J]
time 13317ms: Process G started using the CPU for 60ms burst [Q C N L A F X V P R K I Y E U B W Z J]
time 13377ms: Process G switching out of CPU; blocking on I/O until time 14018ms [Q C N L A F X V P R K I Y E U B W Z J]
time 13379ms: Process C started using the CPU for 231ms burst [Q N L A F X V P R K I Y E U B W Z J]
time 13518ms: Process S completed I/O; added to ready queue [Q N L A F X V P R K I Y E U B W Z J S]
time 13610ms: Process C switching out of CPU; blocking on I/O until time 16321ms [Q N L A F X V P R K I Y E U B W Z J S]
time 13612ms: Process N started using the CPU for 277ms burst [Q L A F X V P R K I Y E U B W Z J S]
time 13629ms: Process M completed I/O; added to ready queue [Q L A F X V P R K I Y E U B W Z J S M]
time 13724ms: Process H completed I/O; added to ready queue [Q L A F X V P R K I Y E U B W Z J S M H]
time 13889ms: Process N switching out of CPU; blocking on I/O until time 15100ms [Q L A F X V P R K I Y E U B W Z J S M H]
time 13891ms: Process L started using the CPU for 110ms burst [Q A F X V P R K I Y E U B W Z J S M H]
time 13946ms: Process D completed I/O; added to ready queue [Q A F X V P R K I Y E U B W Z J S M H D]
time 14001ms: Process L switching out of CPU; blocking on I/O until time 14552ms [Q A F X V P R K I Y E U B W Z J S M H D]
time 14003ms: Process A started using the CPU for 110ms burst [Q F X V P R K I Y E U B W Z J S M H D]
time 14018ms: Process G completed I/O; added to ready queue [Q F X V P R K I Y E U B W Z J S M H D G]
time 14113ms: Process A switching out of CPU; blocking on I/O until time 15544ms [Q F X V P R K I Y E U B W Z J S M H D G]
time 14115ms: Process F started using the CPU for 51ms burst [Q X V P R K I Y E U B W Z J S M H D G]
time 14166ms: Process F switching out of CPU; blocking on I/O until time 16357ms [Q X V P R K I Y E U B W Z J S M H D G]
time 14168ms: Process X started using the CPU for 16ms burst [Q V P R K I Y E U B W Z J S M H D G]
time 14184ms: Process X switching out of CPU; blocking on I/O until time 14263ms [Q V P R K I Y E U B W Z J S M H D G]
time 14186ms: Process V started using the CPU for 52ms burst [Q P R K I Y E U B W Z J S M H D G]
time 14225ms: Process T completed I/O; added to ready queue [Q P R K I Y E U B W Z J S M H D G T]
time 14238ms: Process V switching out of CPU; blocking on I/O until time 14429ms [Q P R K I Y E U B W Z J S M H D G T]
time 14240ms: Process P started using the CPU for 68ms burst [Q R K I Y E U B W Z J S M H D G T]
time 14263ms: Process X completed I/O; added to ready queue [Q R K I Y E U B W Z J S M H D G T X]
time 14295ms: Process Q completed I/O; added to ready queue [Q R K I Y E U B W Z J S M H D G T X Q]
time 14308ms: Process P switching out of CPU; blocking on I/O until time 15129ms [Q R K I Y E U B W Z J S M H D G T X Q]
time 14310ms: Process R started using the CPU for 39ms burst [Q K I Y E U B W Z J S M H D G T X Q]
time 14349ms: Process R terminated [Q K I Y E U B W Z J S M H D G T X Q]
time 14351ms: Process K started using the CPU for 13ms burst [Q I Y E U B W Z J S M H D G T X Q]
time 14364ms: Process K switching out of CPU; blocking on I/O until time 15075ms [Q I Y E U B W Z J S M H D G T X Q]
time 14366ms: Process I started using the CPU for 30ms burst [Q Y E U B W Z J S M H D G T X Q]
time 14396ms: Process I switching out of CPU; blocking on I/O until time 14567ms [Q Y E U B W Z J S M H D G T X Q]
time 14398ms: Process Y started using the CPU for 884ms burst [Q E U B W Z J S M H D G T X Q]
time 14429ms: Process V completed I/O; added to ready queue [Q E U B W Z J S M H D G T X Q V]
time 14552ms: Process L completed I/O; added to ready queue [Q E U B W Z J S M H D G T X Q V L]
time 14567ms: Process I completed I/O; added to ready queue [Q E U B W Z J S M H D G T X Q V L I]
time 15075ms: Process K completed I/O; added to ready queue [Q E U B W Z J S M H D G T X Q V L I K]
time 15100ms: Process N completed I/O; added to ready queue [Q E U B W Z J S M H D G T X Q V L I K N]
time 15129ms: Process P completed I/O; added to ready queue [Q E U B W Z J S M H D G T X Q V L I K N P]
time 15282ms: Process Y switching out of CPU; blocking on I/O until time 15414ms [Q E U B W Z J S M H D G T X Q V L I K N P]
time 15284ms: Process E started using the CPU for 63ms burst [Q U B W Z J S M H D G T X Q V L I K N P]
time 15347ms: Process E switching out of CPU; blocking on I/O until time 15848ms [Q U B W Z J S M H D G T X Q V L I K N P]
time 15349ms: Process U started using the CPU for 13ms burst [Q B W Z J S M H D G T X Q V L I K N P]
time 15362ms: Process U switching out of CPU; blocking on I/O until time 15573ms [Q B W Z J S M H D G T X Q V L I K N P]
time 15364ms: Process B started using the CPU for 124ms burst [Q W Z J S M H D G T X Q V L I K N P]
time 15414ms: Process Y completed I/O; added to ready queue [Q W Z J S M H D G T X Q V L I K N P Y]
time 15488ms: Process B switching out of CPU; blocking on I/O until time 18159ms [Q W Z J S M H D G T X Q V L I K N P Y]
time 15490ms: Process W started using the CPU for 20ms burst [Q Z J S M H D G T X Q V L I K N P Y]
time 15510ms: Process W switching out of CPU; blocking on I/O until time 15921ms [Q Z J S M H D G T X Q V L I K N P Y]
time 15512ms: Process Z started using the CPU for 1656ms burst [Q J S M H D G T X Q V L I K N P Y]
time 15544ms: Process A completed I/O; added to ready queue [Q J S M H D G T X Q V L I K N P Y A]
time 15573ms: Process U completed I/O; added to ready queue [Q J S M H D G T X Q V L I K N P Y A U]
time 15848ms: Process E completed I/O; added to ready queue [Q J S M H D G T X Q V L I K N P Y A U E]
time 15921ms: Process W completed I/O; added to ready queue [Q J S M H D G T X Q V L I K N P Y A U E W]
time 16321ms: Process C completed I/O; added to ready queue [Q J S M H D G T X Q V L I K N P Y A U E W C]
time 16357ms: Process F completed I/O; added to ready queue [Q J S M H D G T X Q V L I K N P Y A U E W C F]
time 17168ms: Process Z switching out of CPU; blocking on I/O until time 17212ms [Q J S M H D G T X Q V L I K N P Y A U E W C F]
time 17170ms: Process J started using the CPU for 46ms burst [Q S M H D G T X Q V L I K N P Y A U E W C F]
time 17212ms: Process Z completed I/O; added to ready queue [Q S M H D G T X Q V L I K N P Y A U E W C F Z]
time 17216ms: Process J switching out of CPU; blocking on I/O until time 18447ms [Q S M H D G T X Q V L I K N P Y A U E W C F Z]
time 17218ms: Process S started using the CPU for 180ms burst [Q M H D G T X Q V L I K N P Y A U E W C F Z]
time 17398ms: Process S switching out of CPU; blocking on I/O until time 19119ms [Q M H D G T X Q V L I K N P Y A U E W C F Z]
time 17400ms: Process M started using the CPU for 315ms burst [Q H D G T X Q V L I K N P Y A U E W C F Z]
time 17715ms: Process M switching out of CPU; blocking on I/O until time 19536ms [Q H D G T X Q V L I K N P Y A U E W C F Z]
time 17717ms: Process H started using the CPU for 37ms burst [Q D G T X Q V L I K N P Y A U E W C F Z]
time 17754ms: Process H switching out of CPU; blocking on I/O until time 18265ms [Q D G T X Q V L I K N P Y A U E W C F Z]
time 17756ms: Process D started using the CPU for 239ms burst [Q G T X Q V L I K N P Y A U E W C F Z]
time 17995ms: Process D switching out of CPU; blocking on I/O until time 18036ms [Q G T X Q V L I K N P Y A U E W C F Z]
time 17997ms: Process G started using the CPU for 66ms burst [Q T X Q V L I K N P Y A U E W C F Z]
time 18036ms: Process D completed I/O; added to ready queue [Q T X Q V L I K N P Y A U E W C F Z D]
time 18063ms: Process G switching out of CPU; blocking on I/O until time 18304ms [Q T X Q V L I K N P Y A U E W C F Z D]
time 18065ms: Process T started using the CPU for 45ms burst [Q X Q V L I K N P Y A U E W C F Z D]
time 18110ms: Process T switching out of CPU; blocking on I/O until time 19971ms [Q X Q V L I K N P Y A U E W C F Z D]
time 18112ms: Process X started using the CPU for 748ms burst [Q Q V L I K N P Y A U E W C F Z D]
time 18159ms: Process B completed I/O; added to ready queue [Q Q V L I K N P Y A U E W C F Z D B]
time 18265ms: Process H completed I/O; added to ready queue [Q Q V L I K N P Y A U E W C F Z D B H]
time 18304ms: Process G completed I/O; added to ready queue [Q Q V L I K N P Y A U E W C F Z D B H G]
time 18447ms: Process J completed I/O; added to ready queue [Q Q V L I K N P Y A U E W C F Z D B H G J]
time 18860ms: Process X switching out of CPU; blocking on I/O until time 18969ms [Q Q V L I K N P Y A U E W C F Z D B H G J]
time 18862ms: Process Q started using the CPU for 2ms burst [Q V L I K N P Y A U E W C F Z D B H G J]
time 18864ms: Process Q switching out of CPU; blocking on I/O until time 19415ms [Q V L I K N P Y A U E W C F Z D B H G J]
time 18866ms: Process V started using the CPU for 46ms burst [Q L I K N P Y A U E W C F Z D B H G J]
time 18912ms: Process V switching out of CPU; blocking on I/O until time 25373ms [Q L I K N P Y A U E W C F Z D B H G J]
time 18914ms: Process L started using the CPU for 8ms burst [Q I K N P Y A U E W C F Z D B H G J]
time 18922ms: Process L switching out of CPU; blocking on I/O until time 18963ms [Q I K N P Y A U E W C F Z D B H G J]
time 18924ms: Process I started using the CPU for 80ms burst [Q K N P Y A U E W C F Z D B H G J]
time 18963ms: Process L completed I/O; added to ready queue [Q K N P Y A U E W C F Z D B H G J L]
time 18969ms: Process X completed I/O; added to ready queue [Q K N P Y A U E W C F Z D B H G J L X]
time 19004ms: Process I switching out of CPU; blocking on I/O until time 19425ms [Q K N P Y A U E W C F Z D B H G J L X]
time 19006ms: Process K started using the CPU for 67ms burst [Q N P Y A U E W C F Z D B H G J L X]
time 19073ms: Process K switching out of CPU; blocking on I/O until time 20704ms [Q N P Y A U E W C F Z D B H G J L X]
time 19075ms: Process N started using the CPU for 47ms burst [Q P Y A U E W C F Z D B H G J L X]
time 19119ms: Process S completed I/O; added to ready queue [Q P Y A U E W C F Z D B H G J L X S]
time 19122ms: Process N switching out of CPU; blocking on I/O until time 20493ms [Q P Y A U E W C F Z D B H G J L X S]
time 19124ms: Process P started using the CPU for 40ms burst [Q Y A U E W C F Z D B H G J L X S]
time 19164ms: Process P switching out of CPU; blocking on I/O until time 21735ms [Q Y A U E W C F Z D B H G J L X S]
time 19166ms: Process Y started using the CPU for 592ms burst [Q A U E W C F Z D B H G J L X S]
time 19415ms: Process Q completed I/O; added to ready queue [Q A U E W C F Z D B H G J L X S Q]
time 19425ms: Process I completed I/O; added to ready queue [Q A U E W C F Z D B H G J L X S Q I]
time 19536ms: Process M completed I/O; added to ready queue [Q A U E W C F Z D B H G J L X S Q I M]
time 19758ms: Process Y switching out of CPU; blocking on I/O until time 20051ms [Q A U E W C F Z D B H G J L X S Q I M]
time 19760ms: Process A started using the CPU for 100ms burst [Q U E W C F Z D B H G J L X S Q I M]
time 19860ms: Process A switching out of CPU; blocking on I/O until time 20561ms [Q U E W C F Z D B H G J L X S Q I M]
time 19862ms: Process U started using the CPU for 85ms burst [Q E W C F Z D B H G J L X S Q I M]
time 19947ms: Process U switching out of CPU; blocking on I/O until time 20518ms [Q E W C F Z D B H G J L X S Q I M]
time 19949ms: Process E started using the CPU for 101ms burst [Q W C F Z D B H G J L X S Q I M]
time 19971ms: Process T completed I/O; added to ready queue [Q W C F Z D B H G J L X S Q I M T]
time 20050ms: Process E terminated [Q W C F Z D B H G J L X S Q I M T]
time 20051ms: Process Y completed I/O; added to ready queue [Q W C F Z D B H G J L X S Q I M T Y]
time 20052ms: Process W started using the CPU for 211ms burst [Q C F Z D B H G J L X S Q I M T Y]
time 20263ms: Process W switching out of CPU; blocking on I/O until time 20434ms [Q C F Z D B H G J L X S Q I M T Y]
time 20265ms: Process C started using the CPU for 184ms burst [Q F Z D B H G J L X S Q I M T Y]
time 20434ms: Process W completed I/O; added to ready queue [Q F Z D B H G J L X S Q I M T Y W]
time 20449ms: Process C switching out of CPU; blocking on I/O until time 21100ms [Q F Z D B H G J L X S Q I M T Y W]
time 20451ms: Process F started using the CPU for 54ms burst [Q Z D B H G J L X S Q I M T Y W]
time 20493ms: Process N completed I/O; added to ready queue [Q Z D B H G J L X S Q I M T Y W N]
time 20505ms: Process F switching out of CPU; blocking on I/O until time 24236ms [Q Z D B H G J L X S Q I M T Y W N]
time 20507ms: Process Z started using the CPU for 1592ms burst [Q D B H G J L X S Q I M T Y W N]
time 20518ms: Process U completed I/O; added to ready queue [Q D B H G J L X S Q I M T Y W N U]
time 20561ms: Process A completed I/O; added to ready queue [Q D B H G J L X S Q I M T Y W N U A]
time 20704ms: Process K completed I/O; added to ready queue [Q D B H G J L X S Q I M T Y W N U A K]
time 21100ms: Process C completed I/O; added to ready queue [Q D B H G J L X S Q I M T Y W N U A K C]
time 21735ms: Process P completed I/O; added to ready queue [Q D B H G J L X S Q I M T Y W N U A K C P]
time 22099ms: Process Z switching out of CPU; blocking on I/O until time 22191ms [Q D B H G J L X S Q I M T Y W N U A K C P]
time 22101ms: Process D started using the CPU for 45ms burst [Q B H G J L X S Q I M T Y W N U A K C P]
time 22146ms: Process D switching out of CPU; blocking on I/O until time 22657ms [Q B H G J L X S Q I M T Y W N U A K C P]
time 22148ms: Process B started using the CPU for 51ms burst [Q H G J L X S Q I M T Y W N U A K C P]
time 22191ms: Process Z completed I/O; added to ready queue [Q H G J L X S Q I M T Y W N U A K C P Z]
time 22199ms: Process B switching out of CPU; blocking on I/O until time 22810ms [Q H G J L X S Q I M T Y W N U A K C P Z]
time 22201ms: Process H started using the CPU for 21ms burst [Q G J L X S Q I M T Y W N U A K C P Z]
time 22222ms: Process H switching out of CPU; blocking on I/O until time 23193ms [Q G J L X S Q I M T Y W N U A K C P Z]
time 22224ms: Process G started using the CPU for 79ms burst [Q J L X S Q I M T Y W N U A K C P Z]
time 22303ms: Process G switching out of CPU; blocking on I/O until time 24944ms [Q J L X S Q I M T Y W N U A K C P Z]
time 22305ms: Process J started using the CPU for 11ms burst [Q L X S Q I M T Y W N U A K C P Z]
time 22316ms: Process J switching out of CPU; blocking on I/O until time 24037ms [Q L X S Q I M T Y W N U A K C P Z]
time 22318ms: Process L started using the CPU for 75ms burst [Q X S Q I M T Y W N U A K C P Z]
time 22393ms: Process L switching out of CPU; blocking on I/O until time 22464ms [Q X S Q I M T Y W N U A K C P Z]
time 22395ms: Process X started using the CPU for 36ms burst [Q S Q I M T Y W N U A K C P Z]
time 22431ms: Process X switching out of CPU; blocking on I/O until time 22477ms [Q S Q I M T Y W N U A K C P Z]
time 22433ms: Process S started using the CPU for 13ms burst [Q Q I M T Y W N U A K C P Z]
time 22446ms: Process S switching out of CPU; blocking on I/O until time 22647ms [Q Q I M T Y W N U A K C P Z]
time 22448ms: Process Q started using the CPU for 88ms burst [Q I M T Y W N U A K C P Z]
time 22464ms: Process L completed I/O; added to ready queue [Q I M T Y W N U A K C P Z L]
time 22477ms: Process X completed I/O; added to ready queue [Q I M T Y W N U A K C P Z L X]
time 22536ms: Process Q switching out of CPU; blocking on I/O until time 23207ms [Q I M T Y W N U A K C P Z L X]
time 22538ms: Process I started using the CPU for 13ms burst [Q M T Y W N U A K C P Z L X]
time 22551ms: Process I switching out of CPU; blocking on I/O until time 25542ms [Q M T Y W N U A K C P Z L X]
time 22553ms: Process M started using the CPU for 28ms burst [Q T Y W N U A K C P Z L X]
time 22581ms: Process M switching out of CPU; blocking on I/O until time 23802ms [Q T Y W N U A K C P Z L X]
time 22583ms: Process T started using the CPU for 82ms burst [Q Y W N U A K C P Z L X]
time 22647ms: Process S completed I/O; added to ready queue [Q Y W N U A K C P Z L X S]
time 22657ms: Process D completed I/O; added to ready queue [Q Y W N U A K C P Z L X S D]
time 22665ms: Process T switching out of CPU; blocking on I/O until time 23066ms [Q Y W N U A K C P Z L X S D]
time 22667ms: Process Y started using the CPU for 1412ms burst [Q W N U A K C P Z L X S D]
time 22810ms: Process B completed I/O; added to ready queue [Q W N U A K C P Z L X S D B]
time 23066ms: Process T completed I/O; added to ready queue [Q W N U A K C P Z L X S D B T]
time 23193ms: Process H completed I/O; added to ready queue [Q W N U A K C P Z L X S D B T H]
time 23207ms: Process Q completed I/O; added to ready queue [Q W N U A K C P Z L X S D B T H Q]
time 23802ms: Process M completed I/O; added to ready queue [Q W N U A K C P Z L X S D B T H Q M]
time 24037ms: Process J completed I/O; added to ready queue [Q W N U A K C P Z L X S D B T H Q M J]
time 24079ms: Process Y switching out of CPU; blocking on I/O until time 24105ms [Q W N U A K C P Z L X S D B T H Q M J]
time 24081ms: Process W started using the CPU for 2ms burst [Q N U A K C P Z L X S D B T H Q M J]
time 24083ms: Process W switching out of CPU; blocking on I/O until time 26284ms [Q N U A K C P Z L X S D B T H Q M J]
time 24085ms: Process N started using the CPU for 83ms burst [Q U A K C P Z L X S D B T H Q M J]
time 24105ms: Process Y completed I/O; added to ready queue [Q U A K C P Z L X S D B T H Q M J Y]
time 24168ms: Process N terminated [Q U A K C P Z L X S D B T H Q M J Y]
time 24170ms: Process U started using the CPU for 301ms burst [Q A K C P Z L X S D B T H Q M J Y]
time 24236ms: Process F completed I/O; added to ready queue [Q A K C P Z L X S D B T H Q M J Y F]
time 24471ms: Process U switching out of CPU; blocking on I/O until time 25472ms [Q A K C P Z L X S D B T H Q M J Y F]
time 24473ms: Process A started using the CPU for 117ms burst [Q K C P Z L X S D B T H Q M J Y F]
time 24590ms: Process A switching out of CPU; blocking on I/O until time 25121ms [Q K C P Z L X S D B T H Q M J Y F]
time 24592ms: Process K started using the CPU for 181ms burst [Q C P Z L X S D B T H Q M J Y F]
time 24773ms: Process K switching out of CPU; blocking on I/O until time 25054ms [Q C P Z L X S D B T H Q M J Y F]
time 24775ms: Process C started using the CPU for 17ms burst [Q P Z L X S D B T H Q M J Y F]
time 24792ms: Process C switching out of CPU; blocking on I/O until time 25073ms [Q P Z L X S D B T H Q M J Y F]
time 24794ms: Process P started using the CPU for 87ms burst [Q Z L X S D B T H Q M J Y F]
time 24881ms: Process P switching out of CPU; blocking on I/O until time 26382ms [Q Z L X S D B T H Q M J Y F]
time 24883ms: Process Z started using the CPU for 188ms burst [Q L X S D B T H Q M J Y F]
time 24944ms: Process G completed I/O; added to ready queue [Q L X S D B T H Q M J Y F G]
time 25054ms: Process K completed I/O; added to ready queue [Q L X S D B T H Q M J Y F G K]
time 25071ms: Process Z switching out of CPU; blocking on I/O until time 25592ms [Q L X S D B T H Q M J Y F G K]
time 25073ms: Process L started using the CPU for 34ms burst [Q X S D B T H Q M J Y F G K]
time 25073ms: Process C completed I/O; added to ready queue [Q X S D B T H Q M J Y F G K C]
time 25107ms: Process L switching out of CPU; blocking on I/O until time 25868ms [Q X S D B T H Q M J Y F G K C]
time 25109ms: Process X started using the CPU for 284ms burst [Q S D B T H Q M J Y F G K C]
time 25121ms: Process A completed I/O; added to ready queue [Q S D B T H Q M J Y F G K C A]
time 25373ms: Process V completed I/O; added to ready queue [Q S D B T H Q M J Y F G K C A V]
time 25393ms: Process X switching out of CPU; blocking on I/O until time 25692ms [Q S D B T H Q M J Y F G K C A V]
time 25395ms: Process S started using the CPU for 112ms burst [Q D B T H Q M J Y F G K C A V]
time 25472ms: Process U completed I/O; added to ready queue [Q D B T H Q M J Y F G K C A V U]
time 25507ms: Process S switching out of CPU; blocking on I/O until time 26488ms [Q D B T H Q M J Y F G K C A V U]
time 25509ms: Process D started using the CPU for 43ms burst [Q B T H Q M J Y F G K C A V U]
time 25542ms: Process I completed I/O; added to ready queue [Q B T H Q M J Y F G K C A V U I]
time 25552ms: Process D switching out of CPU; blocking on I/O until time 25663ms [Q B T H Q M J Y F G K C A V U I]
time 25554ms: Process B started using the CPU for 474ms burst [Q T H Q M J Y F G K C A V U I]
time 25592ms: Process Z completed I/O; added to ready queue [Q T H Q M J Y F G K C A V U I Z]
time 25663ms: Process D completed I/O; added to ready queue [Q T H Q M J Y F G K C A V U I Z D]
time 25692ms: Process X completed I/O; added to ready queue [Q T H Q M J Y F G K C A V U I Z D X]
time 25868ms: Process L completed I/O; added to ready queue [Q T H Q M J Y F G K C A V U I Z D X L]
time 26028ms: Process B switching out of CPU; blocking on I/O until time 28619ms [Q T H Q M J Y F G K C A V U I Z D X L]
time 26030ms: Process T started using the CPU for 87ms burst [Q H Q M J Y F G K C A V U I Z D X L]
time 26117ms: Process T switching out of CPU; blocking on I/O until time 26868ms [Q H Q M J Y F G K C A V U I Z D X L]
time 26119ms: Process H started using the CPU for 36ms burst [Q Q M J Y F G K C A V U I Z D X L]
time 26155ms: Process H switching out of CPU; blocking on I/O until time 27776ms [Q Q M J Y F G K C A V U I Z D X L]
time 26157ms: Process Q started using the CPU for 66ms burst [Q M J Y F G K C A V U I Z D X L]
time 26223ms: Process Q switching out of CPU; blocking on I/O until time 26384ms [Q M J Y F G K C A V U I Z D X L]
time 26225ms: Process M started using the CPU for 49ms burst [Q J Y F G K C A V U I Z D X L]
time 26274ms: Process M switching out of CPU; blocking on I/O until time 29195ms [Q J Y F G K C A V U I Z D X L]
time 26276ms: Process J started using the CPU for 81ms burst [Q Y F G K C A V U I Z D X L]
time 26284ms: Process W completed I/O; added to ready queue [Q Y F G K C A V U I Z D X L W]
time 26357ms: Process J switching out of CPU; blocking on I/O until time 27078ms [Q Y F G K C A V U I Z D X L W]
time 26359ms: Process Y started using the CPU for 292ms burst [Q F G K C A V U I Z D X L W]
time 26382ms: Process P completed I/O; added to ready queue [Q F G K C A V U I Z D X L W P]
time 26384ms: Process Q completed I/O; added to ready queue [Q F G K C A V U I Z D X L W P Q]
time 26488ms: Process S completed I/O; added to ready queue [Q F G K C A V U I Z D X L W P Q S]
time 26651ms: Process Y switching out of CPU; blocking on I/O until time 26697ms [Q F G K C A V U I Z D X L W P Q S]
time 26653ms: Process F started using the CPU for 26ms burst [Q G K C A V U I Z D X L W P Q S]
time 26679ms: Process F switching out of CPU; blocking on I/O until time 27080ms [Q G K C A V U I Z D X L W P Q S]
time 26681ms: Process G started using the CPU for 117ms burst [Q K C A V U I Z D X L W P Q S]
time 26697ms: Process Y completed I/O; added to ready queue [Q K C A V U I Z D X L W P Q S Y]
time 26798ms: Process G switching out of CPU; blocking on I/O until time 27069ms [Q K C A V U I Z D X L W P Q S Y]
time 26800ms: Process K started using the CPU for 2ms burst [Q C A V U I Z D X L W P Q S Y]
time 26802ms: Process K switching out of CPU; blocking on I/O until time 26993ms [Q C A V U I Z D X L W P Q S Y]
time 26804ms: Process C started using the CPU for 104ms burst [Q A V U I Z D X L W P Q S Y]
time 26868ms: Process T completed I/O; added to ready queue [Q A V U I Z D X L W P Q S Y T]
time 26908ms: Process C switching out of CPU; blocking on I/O until time 27279ms [Q A V U I Z D X L W P Q S Y T]
time 26910ms: Process A started using the CPU for 157ms burst [Q V U I Z D X L W P Q S Y T]
time 26993ms: Process K completed I/O; added to ready queue [Q V U I Z D X L W P Q S Y T K]
time 27067ms: Process A switching out of CPU; blocking on I/O until time 27358ms [Q V U I Z D X L W P Q S Y T K]
time 27069ms: Process V started using the CPU for 16ms burst [Q U I Z D X L W P Q S Y T K]
time 27069ms: Process G completed I/O; added to ready queue [Q U I Z D X L W P Q S Y T K G]
time 27078ms: Process J completed I/O; added to ready queue [Q U I Z D X L W P Q S Y T K G J]
time 27080ms: Process F completed I/O; added to ready queue [Q U I Z D X L W P Q S Y T K G J F]
time 27085ms: Process V switching out of CPU; blocking on I/O until time 27786ms [Q U I Z D X L W P Q S Y T K G J F]
time 27087ms: Process U started using the CPU for 37ms burst [Q I Z D X L W P Q S Y T K G J F]
time 27124ms: Process U switching out of CPU; blocking on I/O until time 27745ms [Q I Z D X L W P Q S Y T K G J F]
time 27126ms: Process I started using the CPU for 295ms burst [Q Z D X L W P Q S Y T K G J F]
time 27279ms: Process C completed I/O; added to ready queue [Q Z D X L W P Q S Y T K G J F C]
time 27358ms: Process A completed I/O; added to ready queue [Q Z D X L W P Q S Y T K G J F C A]
time 27421ms: Process I switching out of CPU; blocking on I/O until time 28802ms [Q Z D X L W P Q S Y T K G J F C A]
time 27423ms: Process Z started using the CPU for 368ms burst [Q D X L W P Q S Y T K G J F C A]
time 27745ms: Process U completed I/O; added to ready queue [Q D X L W P Q S Y T K G J F C A U]
time 27776ms: Process H completed I/O; added to ready queue [Q D X L W P Q S Y T K G J F C A U H]
time 27786ms: Process V completed I/O; added to ready queue [Q D X L W P Q S Y T K G J F C A U H V]
time 27791ms: Process Z switching out of CPU; blocking on I/O until time 27799ms [Q D X L W P Q S Y T K G J F C A U H V]
time 27793ms: Process D started using the CPU for 58ms burst [Q X L W P Q S Y T K G J F C A U H V]
time 27799ms: Process Z completed I/O; added to ready queue [Q X L W P Q S Y T K G J F C A U H V Z]
time 27851ms: Process D switching out of CPU; blocking on I/O until time 29602ms [Q X L W P Q S Y T K G J F C A U H V Z]
time 27853ms: Process X started using the CPU for 536ms burst [Q L W P Q S Y T K G J F C A U H V Z]
time 28389ms: Process X switching out of CPU; blocking on I/O until time 28402ms [Q L W P Q S Y T K G J F C A U H V Z]
time 28391ms: Process L started using the CPU for 143ms burst [Q W P Q S Y T K G J F C A U H V Z]
time 28402ms: Process X completed I/O; added to ready queue [Q W P Q S Y T K G J F C A U H V Z X]
time 28534ms: Process L switching out of CPU; blocking on I/O until time 28925ms [Q W P Q S Y T K G J F C A U H V Z X]
time 28536ms: Process W started using the CPU for 44ms burst [Q P Q S Y T K G J F C A U H V Z X]
time 28580ms: Process W switching out of CPU; blocking on I/O until time 29841ms [Q P Q S Y T K G J F C A U H V Z X]
time 28582ms: Process P started using the CPU for 50ms burst [Q Q S Y T K G J F C A U H V Z X]
time 28619ms: Process B completed I/O; added to ready queue [Q Q S Y T K G J F C A U H V Z X B]
time 28632ms: Process P switching out of CPU; blocking on I/O until time 29033ms [Q Q S Y T K G J F C A U H V Z X B]
time 28634ms: Process Q started using the CPU for 74ms burst [Q S Y T K G J F C A U H V Z X B]
time 28708ms: Process Q switching out of CPU; blocking on I/O until time 29969ms [Q S Y T K G J F C A U H V Z X B]
time 28710ms: Process S started using the CPU for 73ms burst [Q Y T K G J F C A U H V Z X B]
time 28783ms: Process S switching out of CPU; blocking on I/O until time 29184ms [Q Y T K G J F C A U H V Z X B]
time 28785ms: Process Y started using the CPU for 352ms burst [Q T K G J F C A U H V Z X B]
time 28802ms: Process I completed I/O; added to ready queue [Q T K G J F C A U H V Z X B I]
time 28925ms: Process L completed I/O; added to ready queue [Q T K G J F C A U H V Z X B I L]
time 29033ms: Process P completed I/O; added to ready queue [Q T K G J F C A U H V Z X B I L P]
time 29137ms: Process Y switching out of CPU; blocking on I/O until time 29179ms [Q T K G J F C A U H V Z X B I L P]
time 29139ms: Process T started using the CPU for 131ms burst [Q K G J F C A U H V Z X B I L P]
time 29179ms: Process Y completed I/O; added to ready queue [Q K G J F C A U H V Z X B I L P Y]
time 29184ms: Process S completed I/O; added to ready queue [Q K G J F C A U H V Z X B I L P Y S]
time 29195ms: Process M completed I/O; added to ready queue [Q K G J F C A U H V Z X B I L P Y S M]
time 29270ms: Process T switching out of CPU; blocking on I/O until time 30481ms [Q K G J F C A U H V Z X B I L P Y S M]
time 29272ms: Process K started using the CPU for 22ms burst [Q G J F C A U H V Z X B I L P Y S M]
time 29294ms: Process K switching out of CPU; blocking on I/O until time 30455ms [Q G J F C A U H V Z X B I L P Y S M]
time 29296ms: Process G started using the CPU for 53ms burst [Q J F C A U H V Z X B I L P Y S M]
time 29349ms: Process G switching out of CPU; blocking on I/O until time 29640ms [Q J F C A U H V Z X B I L P Y S M]
time 29351ms: Process J started using the CPU for 87ms burst [Q F C A U H V Z X B I L P Y S M]
time 29438ms: Process J switching out of CPU; blocking on I/O until time 30199ms [Q F C A U H V Z X B I L P Y S M]
time 29440ms: Process F started using the CPU for 2ms burst [Q C A U H V Z X B I L P Y S M]
time 29442ms: Process F switching out of CPU; blocking on I/O until time 29563ms [Q C A U H V Z X B I L P Y S M]
time 29444ms: Process C started using the CPU for 85ms burst [Q A U H V Z X B I L P Y S M]
time 29529ms: Process C switching out of CPU; blocking on I/O until time 30870ms [Q A U H V Z X B I L P Y S M]
time 29531ms: Process A started using the CPU for 15ms burst [Q U H V Z X B I L P Y S M]
time 29546ms: Process A switching out of CPU; blocking on I/O until time 29627ms [Q U H V Z X B I L P Y S M]
time 29548ms: Process U started using the CPU for 87ms burst [Q H V Z X B I L P Y S M]
time 29563ms: Process F completed I/O; added to ready queue [Q H V Z X B I L P Y S M F]
time 29602ms: Process D completed I/O; added to ready queue [Q H V Z X B I L P Y S M F D]
time 29627ms: Process A completed I/O; added to ready queue [Q H V Z X B I L P Y S M F D A]
time 29635ms: Process U switching out of CPU; blocking on I/O until time 29876ms [Q H V Z X B I L P Y S M F D A]
time 29637ms: Process H started using the CPU for 43ms burst [Q V Z X B I L P Y S M F D A]
time 29640ms: Process G completed I/O; added to ready queue [Q V Z X B I L P Y S M F D A G]
time 29680ms: Process H switching out of CPU; blocking on I/O until time 31371ms [Q V Z X B I L P Y S M F D A G]
time 29682ms: Process V started using the CPU for 72ms burst [Q Z X B I L P Y S M F D A G]
time 29754ms: Process V switching out of CPU; blocking on I/O until time 29835ms [Q Z X B I L P Y S M F D A G]
time 29756ms: Process Z started using the CPU for 76ms burst [Q X B I L P Y S M F D A G]
time 29832ms: Process Z switching out of CPU; blocking on I/O until time 29893ms [Q X B I L P Y S M F D A G]
time 29834ms: Process X started using the CPU for 140ms burst [Q B I L P Y S M F D A G]
time 29835ms: Process V completed I/O; added to ready queue [Q B I L P Y S M F D A G V]
time 29841ms: Process W completed I/O; added to ready queue [Q B I L P Y S M F D A G V W]
time 29876ms: Process U completed I/O; added to ready queue [Q B I L P Y S M F D A G V W U]
time 29893ms: Process Z completed I/O; added to ready queue [Q B I L P Y S M F D A G V W U Z]
time 29969ms: Process Q completed I/O; added to ready queue [Q B I L P Y S M F D A G V W U Z Q]
time 29974ms: Process X switching out of CPU; blocking on I/O until time 30288ms [Q B I L P Y S M F D A G V W U Z Q]
time 29976ms: Process B started using the CPU for 146ms burst [Q I L P Y S M F D A G V W U Z Q]
time 30122ms: Process B switching out of CPU; blocking on I/O until time 30593ms [Q I L P Y S M F D A G V W U Z Q]
time 30124ms: Process I started using the CPU for 167ms burst [Q L P Y S M F D A G V W U Z Q]
time 30199ms: Process J completed I/O; added to ready queue [Q L P Y S M F D A G V W U Z Q J]
time 30288ms: Process X completed I/O; added to ready queue [Q L P Y S M F D A G V W U Z Q J X]
time 30291ms: Process I switching out of CPU; blocking on I/O until time 30502ms [Q L P Y S M F D A G V W U Z Q J X]
time 30293ms: Process L started using the CPU for 89ms burst [Q P Y S M F D A G V W U Z Q J X]
time 30382ms: Process L switching out of CPU; blocking on I/O until time 30643ms [Q P Y S M F D A G V W U Z Q J X]
time 30384ms: Process P started using the CPU for 123ms burst [Q Y S M F D A G V W U Z Q J X]
time 30455ms: Process K completed I/O; added to ready queue [Q Y S M F D A G V W U Z Q J X K]
time 30481ms: Process T completed I/O; added to ready queue [Q Y S M F D A G V W U Z Q J X K T]
time 30502ms: Process I completed I/O; added to ready queue [Q Y S M F D A G V W U Z Q J X K T I]
time 30507ms: Process P switching out of CPU; blocking on I/O until time 31758ms [Q Y S M F D A G V W U Z Q J X K T I]
time 30509ms: Process Y started using the CPU for 800ms burst [Q S M F D A G V W U Z Q J X K T I]
time 30593ms: Process B completed I/O; added to ready queue [Q S M F D A G V W U Z Q J X K T I B]
time 30643ms: Process L completed I/O; added to ready queue [Q S M F D A G V W U Z Q J X K T I B L]
time 30870ms: Process C completed I/O; added to ready queue [Q S M F D A G V W U Z Q J X K T I B L C]
time 31309ms: Process Y switching out of CPU; blocking on I/O until time 31448ms [Q S M F D A G V W U Z Q J X K T I B L C]
time 31311ms: Process S started using the CPU for 45ms burst [Q M F D A G V W U Z Q J X K T I B L C]
time 31356ms: Process S switching out of CPU; blocking on I/O until time 33087ms [Q M F D A G V W U Z Q J X K T I B L C]
time 31358ms: Process M started using the CPU for 12ms burst [Q F D A G V W U Z Q J X K T I B L C]
time 31370ms: Process M switching out of CPU; blocking on I/O until time 31741ms [Q F D A G V W U Z Q J X K T I B L C]
time 31371ms: Process H completed I/O; added to ready queue [Q F D A G V W U Z Q J X K T I B L C H]
time 31372ms: Process F started using the CPU for 9ms burst [Q D A G V W U Z Q J X K T I B L C H]
time 31381ms: Process F switching out of CPU; blocking on I/O until time 32712ms [Q D A G V W U Z Q J X K T I B L C H]
time 31383ms: Process D started using the CPU for 35ms burst [Q A G V W U Z Q J X K T I B L C H]
time 31418ms: Process D switching out of CPU; blocking on I/O until time 32239ms [Q A G V W U Z Q J X K T I B L C H]
time 31420ms: Process A started using the CPU for 39ms burst [Q G V W U Z Q J X K T I B L C H]
time 31448ms: Process Y completed I/O; added to ready queue [Q G V W U Z Q J X K T I B L C H Y]
time 31459ms: Process A switching out of CPU; blocking on I/O until time 32200ms [Q G V W U Z Q J X K T I B L C H Y]
time 31461ms: Process G started using the CPU for 96ms burst [Q V W U Z Q J X K T I B L C H Y]
time 31557ms: Process G switching out of CPU; blocking on I/O until time 31778ms [Q V W U Z Q J X K T I B L C H Y]
time 31559ms: Process V started using the CPU for 123ms burst [Q W U Z Q J X K T I B L C H Y]
time 31682ms: Process V switching out of CPU; blocking on I/O until time 34363ms [Q W U Z Q J X K T I B L C H Y]
time 31684ms: Process W started using the CPU for 125ms burst [Q U Z Q J X K T I B L C H Y]
time 31741ms: Process M completed I/O; added to ready queue [Q U Z Q J X K T I B L C H Y M]
time 31758ms: Process P completed I/O; added to ready queue [Q U Z Q J X K T I B L C H Y M P]
time 31778ms: Process G completed I/O; added to ready queue [Q U Z Q J X K T I B L C H Y M P G]
time 31809ms: Process W switching out of CPU; blocking on I/O until time 32210ms [Q U Z Q J X K T I B L C H Y M P G]
time 31811ms: Process U started using the CPU for 14ms burst [Q Z Q J X K T I B L C H Y M P G]
time 31825ms: Process U switching out of CPU; blocking on I/O until time 33076ms [Q Z Q J X K T I B L C H Y M P G]
time 31827ms: Process Z started using the CPU for 168ms burst [Q Q J X K T I B L C H Y M P G]
time 31995ms: Process Z switching out of CPU; blocking on I/O until time 32122ms [Q Q J X K T I B L C H Y M P G]
time 31997ms: Process Q started using the CPU for 11ms burst [Q J X K T I B L C H Y M P G]
time 32008ms: Process Q switching out of CPU; blocking on I/O until time 32479ms [Q J X K T I B L C H Y M P G]
time 32010ms: Process J started using the CPU for 55ms burst [Q X K T I B L C H Y M P G]
time 32065ms: Process J switching out of CPU; blocking on I/O until time 33866ms [Q X K T I B L C H Y M P G]
time 32067ms: Process X started using the CPU for 232ms burst [Q K T I B L C H Y M P G]
time 32122ms: Process Z completed I/O; added to ready queue [Q K T I B L C H Y M P G Z]
time 32200ms: Process A completed I/O; added to ready queue [Q K T I B L C H Y M P G Z A]
time 32210ms: Process W completed I/O; added to ready queue [Q K T I B L C H Y M P G Z A W]
time 32239ms: Process D completed I/O; added to ready queue [Q K T I B L C H Y M P G Z A W D]
time 32299ms: Process X switching out of CPU; blocking on I/O until time 32368ms [Q K T I B L C H Y M P G Z A W D]
time 32301ms: Process K started using the CPU for 355ms burst [Q T I B L C H Y M P G Z A W D]
time 32368ms: Process X completed I/O; added to ready queue [Q T I B L C H Y M P G Z A W D X]
time 32479ms: Process Q completed I/O; added to ready queue [Q T I B L C H Y M P G Z A W D X Q]
time 32656ms: Process K switching out of CPU; blocking on I/O until time 33927ms [Q T I B L C H Y M P G Z A W D X Q]
time 32658ms: Process T started using the CPU for 78ms burst [Q I B L C H Y M P G Z A W D X Q]
time 32712ms: Process F completed I/O; added to ready queue [Q I B L C H Y M P G Z A W D X Q F]
time 32736ms: Process T switching out of CPU; blocking on I/O until time 32747ms [Q I B L C H Y M P G Z A W D X Q F]
time 32738ms: Process I started using the CPU for 183ms burst [Q B L C H Y M P G Z A W D X Q F]
time 32747ms: Process T completed I/O; added to ready queue [Q B L C H Y M P G Z A W D X Q F T]
time 32921ms: Process I switching out of CPU; blocking on I/O until time 33452ms [Q B L C H Y M P G Z A W D X Q F T]
time 32923ms: Process B started using the CPU for 88ms burst [Q L C H Y M P G Z A W D X Q F T]
time 33011ms: Process B switching out of CPU; blocking on I/O until time 34212ms [Q L C H Y M P G Z A W D X Q F T]
time 33013ms: Process L started using the CPU for 5ms burst [Q C H Y M P G Z A W D X Q F T]
time 33018ms: Process L switching out of CPU; blocking on I/O until time 33519ms [Q C H Y M P G Z A W D X Q F T]
time 33020ms: Process C started using the CPU for 173ms burst [Q H Y M P G Z A W D X Q F T]
time 33076ms: Process U completed I/O; added to ready queue [Q H Y M P G Z A W D X Q F T U]
time 33087ms: Process S completed I/O; added to ready queue [Q H Y M P G Z A W D X Q F T U S]
time 33193ms: Process C switching out of CPU; blocking on I/O until time 35014ms [Q H Y M P G Z A W D X Q F T U S]
time 33195ms: Process H started using the CPU for 81ms burst [Q Y M P G Z A W D X Q F T U S]
time 33276ms: Process H switching out of CPU; blocking on I/O until time 33847ms [Q Y M P G Z A W D X Q F T U S]
time 33278ms: Process Y started using the CPU for 1216ms burst [Q M P G Z A W D X Q F T U S]
time 33452ms: Process I completed I/O; added to ready queue [Q M P G Z A W D X Q F T U S I]
time 33519ms: Process L completed I/O; added to ready queue [Q M P G Z A W D X Q F T U S I L]
time 33847ms: Process H completed I/O; added to ready queue [Q M P G Z A W D X Q F T U S I L H]
time 33866ms: Process J completed I/O; added to ready queue [Q M P G Z A W D X Q F T U S I L H J]
time 33927ms: Process K completed I/O; added to ready queue [Q M P G Z A W D X Q F T U S I L H J K]
time 34212ms: Process B completed I/O; added to ready queue [Q M P G Z A W D X Q F T U S I L H J K B]
time 34363ms: Process V completed I/O; added to ready queue [Q M P G Z A W D X Q F T U S I L H J K B V]
time 34494ms: Process Y switching out of CPU; blocking on I/O until time 34595ms [Q M P G Z A W D X Q F T U S I L H J K B V]
time 34496ms: Process M started using the CPU for 11ms burst [Q P G Z A W D X Q F T U S I L H J K B V]
time 34507ms: Process M switching out of CPU; blocking on I/O until time 34918ms [Q P G Z A W D X Q F T U S I L H J K B V]
time 34509ms: Process P started using the CPU for 10ms burst [Q G Z A W D X Q F T U S I L H J K B V]
time 34519ms: Process P switching out of CPU; blocking on I/O until time 37070ms [Q G Z A W D X Q F T U S I L H J K B V]
time 34521ms: Process G started using the CPU for 85ms burst [Q Z A W D X Q F T U S I L H J K B V]
time 34595ms: Process Y completed I/O; added to ready queue [Q Z A W D X Q F T U S I L H J K B V Y]
time 34606ms: Process G switching out of CPU; blocking on I/O until time 35457ms [Q Z A W D X Q F T U S I L H J K B V Y]
time 34608ms: Process Z started using the CPU for 544ms burst [Q A W D X Q F T U S I L H J K B V Y]
time 34918ms: Process M completed I/O; added to ready queue [Q A W D X Q F T U S I L H J K B V Y M]
time 35014ms: Process C completed I/O; added to ready queue [Q A W D X Q F T U S I L H J K B V Y M C]
time 35152ms: Process Z switching out of CPU; blocking on I/O until time 35376ms [Q A W D X Q F T U S I L H J K B V Y M C]
time 35154ms: Process A started using the CPU for 4ms burst [Q W D X Q F T U S I L H J K B V Y M C]
time 35158ms: Process A switching out of CPU; blocking on I/O until time 36119ms [Q W D X Q F T U S I L H J K B V Y M C]
time 35160ms: Process W started using the CPU for 32ms burst [Q D X Q F T U S I L H J K B V Y M C]
time 35192ms: Process W switching out of CPU; blocking on I/O until time 37323ms [Q D X Q F T U S I L H J K B V Y M C]
time 35194ms: Process D started using the CPU for 176ms burst [Q X Q F T U S I L H J K B V Y M C]
time 35370ms: Process D switching out of CPU; blocking on I/O until time 35731ms [Q X Q F T U S I L H J K B V Y M C]
time 35372ms: Process X started using the CPU for 952ms burst [Q Q F T U S I L H J K B V Y M C]
time 35376ms: Process Z completed I/O; added to ready queue [Q Q F T U S I L H J K B V Y M C Z]
time 35457ms: Process G completed I/O; added to ready queue [Q Q F T U S I L H J K B V Y M C Z G]
time 35731ms: Process D completed I/O; added to ready queue [Q Q F T U S I L H J K B V Y M C Z G D]
time 36119ms: Process A completed I/O; added to ready queue [Q Q F T U S I L H J K B V Y M C Z G D A]
time 36324ms: Process X switching out of CPU; blocking on I/O until time 36502ms [Q Q F T U S I L H J K B V Y M C Z G D A]
time 36326ms: Process Q started using the CPU for 133ms burst [Q F T U S I L H J K B V Y M C Z G D A]
time 36459ms: Process Q switching out of CPU; blocking on I/O until time 38270ms [Q F T U S I L H J K B V Y M C Z G D A]
time 36461ms: Process F started using the CPU for 31ms burst [Q T U S I L H J K B V Y M C Z G D A]
time 36492ms: Process F switching out of CPU; blocking on I/O until time 38553ms [Q T U S I L H J K B V Y M C Z G D A]
time 36494ms: Process T started using the CPU for 5ms burst [Q U S I L H J K B V Y M C Z G D A]
time 36499ms: Process T switching out of CPU; blocking on I/O until time 39120ms [Q U S I L H J K B V Y M C Z G D A]
time 36501ms: Process U started using the CPU for 480ms burst [Q S I L H J K B V Y M C Z G D A]
time 36502ms: Process X completed I/O; added to ready queue [Q S I L H J K B V Y M C Z G D A X]
time 36981ms: Process U switching out of CPU; blocking on I/O until time 37362ms [Q S I L H J K B V Y M C Z G D A X]
time 36983ms: Process S started using the CPU for 30ms burst [Q I L H J K B V Y M C Z G D A X]
time 37013ms: Process S switching out of CPU; blocking on I/O until time 37784ms [Q I L H J K B V Y M C Z G D A X]
time 37015ms: Process I started using the CPU for 192ms burst [Q L H J K B V Y M C Z G D A X]
time 37070ms: Process P completed I/O; added to ready queue [Q L H J K B V Y M C Z G D A X P]
time 37207ms: Process I switching out of CPU; blocking on I/O until time 37328ms [Q L H J K B V Y M C Z G D A X P]
time 37209ms: Process L started using the CPU for 180ms burst [Q H J K B V Y M C Z G D A X P]
time 37323ms: Process W completed I/O; added to ready queue [Q H J K B V Y M C Z G D A X P W]
time 37328ms: Process I completed I/O; added to ready queue [Q H J K B V Y M C Z G D A X P W I]
time 37362ms: Process U completed I/O; added to ready queue [Q H J K B V Y M C Z G D A X P W I U]
time 37389ms: Process L switching out of CPU; blocking on I/O until time 40160ms [Q H J K B V Y M C Z G D A X P W I U]
time 37391ms: Process H started using the CPU for 36ms burst [Q J K B V Y M C Z G D A X P W I U]
time 37427ms: Process H switching out of CPU; blocking on I/O until time 38128ms [Q J K B V Y M C Z G D A X P W I U]
time 37429ms: Process J started using the CPU for 150ms burst [Q K B V Y M C Z G D A X P W I U]
time 37579ms: Process J switching out of CPU; blocking on I/O until time 37910ms [Q K B V Y M C Z G D A X P W I U]
time 37581ms: Process K started using the CPU for 21ms burst [Q B V Y M C Z G D A X P W I U]
time 37602ms: Process K switching out of CPU; blocking on I/O until time 37673ms [Q B V Y M C Z G D A X P W I U]
time 37604ms: Process B started using the CPU for 200ms burst [Q V Y M C Z G D A X P W I U]
time 37673ms: Process K completed I/O; added to ready queue [Q V Y M C Z G D A X P W I U K]
time 37784ms: Process S completed I/O; added to ready queue [Q V Y M C Z G D A X P W I U K S]
time 37804ms: Process B switching out of CPU; blocking on I/O until time 38615ms [Q V Y M C Z G D A X P W I U K S]
time 37806ms: Process V started using the CPU for 147ms burst [Q Y M C Z G D A X P W I U K S]
time 37910ms: Process J completed I/O; added to ready queue [Q Y M C Z G D A X P W I U K S J]
time 37953ms: Process V switching out of CPU; blocking on I/O until time 40984ms [Q Y M C Z G D A X P W I U K S J]
time 37955ms: Process Y started using the CPU for 244ms burst [Q M C Z G D A X P W I U K S J]
time 38128ms: Process H completed I/O; added to ready queue [Q M C Z G D A X P W I U K S J H]
time 38199ms: Process Y switching out of CPU; blocking on I/O until time 38257ms [Q M C Z G D A X P W I U K S J H]
time 38201ms: Process M started using the CPU for 39ms burst [Q C Z G D A X P W I U K S J H]
time 38240ms: Process M switching out of CPU; blocking on I/O until time 38761ms [Q C Z G D A X P W I U K S J H]
time 38242ms: Process C started using the CPU for 173ms burst [Q Z G D A X P W I U K S J H]
time 38257ms: Process Y completed I/O; added to ready queue [Q Z G D A X P W I U K S J H Y]
time 38270ms: Process Q completed I/O; added to ready queue [Q Z G D A X P W I U K S J H Y Q]
time 38415ms: Process C switching out of CPU; blocking on I/O until time 38956ms [Q Z G D A X P W I U K S J H Y Q]
time 38417ms: Process Z started using the CPU for 996ms burst [Q G D A X P W I U K S J H Y Q]
time 38553ms: Process F completed I/O; added to ready queue [Q G D A X P W I U K S J H Y Q F]
time 38615ms: Process B completed I/O; added to ready queue [Q G D A X P W I U K S J H Y Q F B]
time 38761ms: Process M completed I/O; added to ready queue [Q G D A X P W I U K S J H Y Q F B M]
time 38956ms: Process C completed I/O; added to ready queue [Q G D A X P W I U K S J H Y Q F B M C]
time 39120ms: Process T completed I/O; added to ready queue [Q G D A X P W I U K S J H Y Q F B M C T]
time 39413ms: Process Z switching out of CPU; blocking on I/O until time 39560ms [Q G D A X P W I U K S J H Y Q F B M C T]
time 39415ms: Process G started using the CPU for 248ms burst [Q D A X P W I U K S J H Y Q F B M C T]
time 39560ms: Process Z completed I/O; added to ready queue [Q D A X P W I U K S J H Y Q F B M C T Z]
time 39663ms: Process G switching out of CPU; blocking on I/O until time 40494ms [Q D A X P W I U K S J H Y Q F B M C T Z]
time 39665ms: Process D started using the CPU for 30ms burst [Q A X P W I U K S J H Y Q F B M C T Z]
time 39695ms: Process D switching out of CPU; blocking on I/O until time 41176ms [Q A X P W I U K S J H Y Q F B M C T Z]
time 39697ms: Process A started using the CPU for 96ms burst [Q X P W I U K S J H Y Q F B M C T Z]
time 39793ms: Process A switching out of CPU; blocking on I/O until time 40794ms [Q X P W I U K S J H Y Q F B M C T Z]
time 39795ms: Process X started using the CPU for 116ms burst [Q P W I U K S J H Y Q F B M C T Z]
time 39911ms: Process X switching out of CPU; blocking on I/O until time 40032ms [Q P W I U K S J H Y Q F B M C T Z]
time 39913ms: Process P started using the CPU for 15ms burst [Q W I U K S J H Y Q F B M C T Z]
time 39928ms: Process P switching out of CPU; blocking on I/O until time 41039ms [Q W I U K S J H Y Q F B M C T Z]
time 39930ms: Process W started using the CPU for 209ms burst [Q I U K S J H Y Q F B M C T Z]
time 40032ms: Process X completed I/O; added to ready queue [Q I U K S J H Y Q F B M C T Z X]
time 40139ms: Process W switching out of CPU; blocking on I/O until time 40480ms [Q I U K S J H Y Q F B M C T Z X]
time 40141ms: Process I started using the CPU for 99ms burst [Q U K S J H Y Q F B M C T Z X]
time 40160ms: Process L completed I/O; added to ready queue [Q U K S J H Y Q F B M C T Z X L]
time 40240ms: Process I switching out of CPU; blocking on I/O until time 40921ms [Q U K S J H Y Q F B M C T Z X L]
time 40242ms: Process U started using the CPU for 161ms burst [Q K S J H Y Q F B M C T Z X L]
time 40403ms: Process U switching out of CPU; blocking on I/O until time 40764ms [Q K S J H Y Q F B M C T Z X L]
time 40405ms: Process K started using the CPU for 2ms burst [Q S J H Y Q F B M C T Z X L]
time 40407ms: Process K switching out of CPU; blocking on I/O until time 44988ms [Q S J H Y Q F B M C T Z X L]
time 40409ms: Process S started using the CPU for 37ms burst [Q J H Y Q F B M C T Z X L]
time 40446ms: Process S switching out of CPU; blocking on I/O until time 43497ms [Q J H Y Q F B M C T Z X L]
time 40448ms: Process J started using the CPU for 27ms burst [Q H Y Q F B M C T Z X L]
time 40475ms: Process J switching out of CPU; blocking on I/O until time 41306ms [Q H Y Q F B M C T Z X L]
time 40477ms: Process H started using the CPU for 87ms burst [Q Y Q F B M C T Z X L]
time 40480ms: Process W completed I/O; added to ready queue [Q Y Q F B M C T Z X L W]
time 40494ms: Process G completed I/O; added to ready queue [Q Y Q F B M C T Z X L W G]
time 40564ms: Process H switching out of CPU; blocking on I/O until time 41445ms [Q Y Q F B M C T Z X L W G]
time 40566ms: Process Y started using the CPU for 132ms burst [Q Q F B M C T Z X L W G]
time 40698ms: Process Y switching out of CPU; blocking on I/O until time 40725ms [Q Q F B M C T Z X L W G]
time 40700ms: Process Q started using the CPU for 33ms burst [Q F B M C T Z X L W G]
time 40725ms: Process Y completed I/O; added to ready queue [Q F B M C T Z X L W G Y]
time 40733ms: Process Q switching out of CPU; blocking on I/O until time 43684ms [Q F B M C T Z X L W G Y]
time 40735ms: Process F started using the CPU for 129ms burst [Q B M C T Z X L W G Y]
time 40764ms: Process U completed I/O; added to ready queue [Q B M C T Z X L W G Y U]
time 40794ms: Process A completed I/O; added to ready queue [Q B M C T Z X L W G Y U A]
time 40864ms: Process F switching out of CPU; blocking on I/O until time 41895ms [Q B M C T Z X L W G Y U A]
time 40866ms: Process B started using the CPU for 197ms burst [Q M C T Z X L W G Y U A]
time 40921ms: Process I completed I/O; added to ready queue [Q M C T Z X L W G Y U A I]
time 40984ms: Process V completed I/O; added to ready queue [Q M C T Z X L W G Y U A I V]
time 41039ms: Process P completed I/O; added to ready queue [Q M C T Z X L W G Y U A I V P]
time 41063ms: Process B switching out of CPU; blocking on I/O until time 42374ms [Q M C T Z X L W G Y U A I V P]
time 41065ms: Process M started using the CPU for 128ms burst [Q C T Z X L W G Y U A I V P]
time 41176ms: Process D completed I/O; added to ready queue [Q C T Z X L W G Y U A I V P D]
time 41193ms: Process M switching out of CPU; blocking on I/O until time 41654ms [Q C T Z X L W G Y U A I V P D]
time 41195ms: Process C started using the CPU for 182ms burst [Q T Z X L W G Y U A I V P D]
time 41306ms: Process J completed I/O; added to ready queue [Q T Z X L W G Y U A I V P D J]
time 41377ms: Process C switching out of CPU; blocking on I/O until time 41508ms [Q T Z X L W G Y U A I V P D J]
time 41379ms: Process T started using the CPU for 112ms burst [Q Z X L W G Y U A I V P D J]
time 41445ms: Process H completed I/O; added to ready queue [Q Z X L W G Y U A I V P D J H]
time 41491ms: Process T switching out of CPU; blocking on I/O until time 41972ms [Q Z X L W G Y U A I V P D J H]
time 41493ms: Process Z started using the CPU for 24ms burst [Q X L W G Y U A I V P D J H]
time 41508ms: Process C completed I/O; added to ready queue [Q X L W G Y U A I V P D J H C]
time 41517ms: Process Z switching out of CPU; blocking on I/O until time 41684ms [Q X L W G Y U A I V P D J H C]
time 41519ms: Process X started using the CPU for 436ms burst [Q L W G Y U A I V P D J H C]
time 41654ms: Process M completed I/O; added to ready queue [Q L W G Y U A I V P D J H C M]
time 41684ms: Process Z completed I/O; added to ready queue [Q L W G Y U A I V P D J H C M Z]
time 41895ms: Process F completed I/O; added to ready queue [Q L W G Y U A I V P D J H C M Z F]
time 41955ms: Process X switching out of CPU; blocking on I/O until time 42033ms [Q L W G Y U A I V P D J H C M Z F]
time 41957ms: Process L started using the CPU for 29ms burst [Q W G Y U A I V P D J H C M Z F]
time 41972ms: Process T completed I/O; added to ready queue [Q W G Y U A I V P D J H C M Z F T]
time 41986ms: Process L switching out of CPU; blocking on I/O until time 42017ms [Q W G Y U A I V P D J H C M Z F T]
time 41988ms: Process W started using the CPU for 44ms burst [Q G Y U A I V P D J H C M Z F T]
time 42017ms: Process L completed I/O; added to ready queue [Q G Y U A I V P D J H C M Z F T L]
time 42032ms: Process W switching out of CPU; blocking on I/O until time 44893ms [Q G Y U A I V P D J H C M Z F T L]
time 42033ms: Process X completed I/O; added to ready queue [Q G Y U A I V P D J H C M Z F T L X]
time 42034ms: Process G started using the CPU for 214ms burst [Q Y U A I V P D J H C M Z F T L X]
time 42248ms: Process G switching out of CPU; blocking on I/O until time 42749ms [Q Y U A I V P D J H C M Z F T L X]
time 42250ms: Process Y started using the CPU for 348ms burst [Q U A I V P D J H C M Z F T L X]
time 42374ms: Process B completed I/O; added to ready queue [Q U A I V P D J H C M Z F T L X B]
time 42598ms: Process Y switching out of CPU; blocking on I/O until time 42707ms [Q U A I V P D J H C M Z F T L X B]
time 42600ms: Process U started using the CPU for 89ms burst [Q A I V P D J H C M Z F T L X B]
time 42689ms: Process U switching out of CPU; blocking on I/O until time 44420ms [Q A I V P D J H C M Z F T L X B]
time 42691ms: Process A started using the CPU for 24ms burst [Q I V P D J H C M Z F T L X B]
time 42707ms: Process Y completed I/O; added to ready queue [Q I V P D J H C M Z F T L X B Y]
time 42715ms: Process A switching out of CPU; blocking on I/O until time 44426ms [Q I V P D J H C M Z F T L X B Y]
time 42717ms: Process I started using the CPU for 71ms burst [Q V P D J H C M Z F T L X B Y]
time 42749ms: Process G completed I/O; added to ready queue [Q V P D J H C M Z F T L X B Y G]
time 42788ms: Process I switching out of CPU; blocking on I/O until time 42809ms [Q V P D J H C M Z F T L X B Y G]
time 42790ms: Process V started using the CPU for 4ms burst [Q P D J H C M Z F T L X B Y G]
time 42794ms: Process V switching out of CPU; blocking on I/O until time 43265ms [Q P D J H C M Z F T L X B Y G]
time 42796ms: Process P started using the CPU for 7ms burst [Q D J H C M Z F T L X B Y G]
time 42803ms: Process P switching out of CPU; blocking on I/O until time 44344ms [Q D J H C M Z F T L X B Y G]
time 42805ms: Process D started using the CPU for 164ms burst [Q J H C M Z F T L X B Y G]
time 42809ms: Process I completed I/O; added to ready queue [Q J H C M Z F T L X B Y G I]
time 42969ms: Process D switching out of CPU; blocking on I/O until time 43610ms [Q J H C M Z F T L X B Y G I]
time 42971ms: Process J started using the CPU for 118ms burst [Q H C M Z F T L X B Y G I]
time 43089ms: Process J switching out of CPU; blocking on I/O until time 43440ms [Q H C M Z F T L X B Y G I]
time 43091ms: Process H started using the CPU for 130ms burst [Q C M Z F T L X B Y G I]
time 43221ms: Process H switching out of CPU; blocking on I/O until time 43882ms [Q C M Z F T L X B Y G I]
time 43223ms: Process C started using the CPU for 60ms burst [Q M Z F T L X B Y G I]
time 43265ms: Process V completed I/O; added to ready queue [Q M Z F T L X B Y G I V]
time 43283ms: Process C switching out of CPU; blocking on I/O until time 43694ms [Q M Z F T L X B Y G I V]
time 43285ms: Process M started using the CPU for 27ms burst [Q Z F T L X B Y G I V]
time 43312ms: Process M switching out of CPU; blocking on I/O until time 43353ms [Q Z F T L X B Y G I V]
time 43314ms: Process Z started using the CPU for 760ms burst [Q F T L X B Y G I V]
time 43353ms: Process M completed I/O; added to ready queue [Q F T L X B Y G I V M]
time 43440ms: Process J completed I/O; added to ready queue [Q F T L X B Y G I V M J]
time 43497ms: Process S completed I/O; added to ready queue [Q F T L X B Y G I V M J S]
time 43610ms: Process D completed I/O; added to ready queue [Q F T L X B Y G I V M J S D]
time 43684ms: Process Q completed I/O; added to ready queue [Q F T L X B Y G I V M J S D Q]
time 43694ms: Process C completed I/O; added to ready queue [Q F T L X B Y G I V M J S D Q C]
time 43882ms: Process H completed I/O; added to ready queue [Q F T L X B Y G I V M J S D Q C H]
time 44074ms: Process Z switching out of CPU; blocking on I/O until time 44395ms [Q F T L X B Y G I V M J S D Q C H]
time 44076ms: Process F started using the CPU for 92ms burst [Q T L X B Y G I V M J S D Q C H]
time 44168ms: Process F switching out of CPU; blocking on I/O until time 44579ms [Q T L X B Y G I V M J S D Q C H]
time 44170ms: Process T started using the CPU for 31ms burst [Q L X B Y G I V M J S D Q C H]
time 44201ms: Process T switching out of CPU; blocking on I/O until time 44582ms [Q L X B Y G I V M J S D Q C H]
time 44203ms: Process L started using the CPU for 81ms burst [Q X B Y G I V M J S D Q C H]
time 44284ms: Process L switching out of CPU; blocking on I/O until time 45555ms [Q X B Y G I V M J S D Q C H]
time 44286ms: Process X started using the CPU for 640ms burst [Q B Y G I V M J S D Q C H]
time 44344ms: Process P completed I/O; added to ready queue [Q B Y G I V M J S D Q C H P]
time 44395ms: Process Z completed I/O; added to ready queue [Q B Y G I V M J S D Q C H P Z]
time 44420ms: Process U completed I/O; added to ready queue [Q B Y G I V M J S D Q C H P Z U]
time 44426ms: Process A completed I/O; added to ready queue [Q B Y G I V M J S D Q C H P Z U A]
time 44579ms: Process F completed I/O; added to ready queue [Q B Y G I V M J S D Q C H P Z U A F]
time 44582ms: Process T completed I/O; added to ready queue [Q B Y G I V M J S D Q C H P Z U A F T]
time 44893ms: Process W completed I/O; added to ready queue [Q B Y G I V M J S D Q C H P Z U A F T W]
time 44926ms: Process X switching out of CPU; blocking on I/O until time 45077ms [Q B Y G I V M J S D Q C H P Z U A F T W]
time 44928ms: Process B started using the CPU for 31ms burst [Q Y G I V M J S D Q C H P Z U A F T W]
time 44959ms: Process B switching out of CPU; blocking on I/O until time 47910ms [Q Y G I V M J S D Q C H P Z U A F T W]
time 44961ms: Process Y started using the CPU for 184ms burst [Q G I V M J S D Q C H P Z U A F T W]
time 44988ms: Process K completed I/O; added to ready queue [Q G I V M J S D Q C H P Z U A F T W K]
time 45077ms: Process X completed I/O; added to ready queue [Q G I V M J S D Q C H P Z U A F T W K X]
time 45145ms: Process Y switching out of CPU; blocking on I/O until time 45149ms [Q G I V M J S D Q C H P Z U A F T W K X]
time 45147ms: Process G started using the CPU for 62ms burst [Q I V M J S D Q C H P Z U A F T W K X]
time 45149ms: Process Y completed I/O; added to ready queue [Q I V M J S D Q C H P Z U A F T W K X Y]
time 45209ms: Process G switching out of CPU; blocking on I/O until time 45760ms [Q I V M J S D Q C H P Z U A F T W K X Y]
time 45211ms: Process I started using the CPU for 178ms burst [Q V M J S D Q C H P Z U A F T W K X Y]
time 45389ms: Process I switching out of CPU; blocking on I/O until time 46350ms [Q V M J S D Q C H P Z U A F T W K X Y]
time 45391ms: Process V started using the CPU for 166ms burst [Q M J S D Q C H P Z U A F T W K X Y]
time 45555ms: Process L completed I/O; added to ready queue [Q M J S D Q C H P Z U A F T W K X Y L]
